<?xml version="1.0" encoding="UTF-8"?><Posts><Post><PostId>21282307</PostId><Url>http://stackoverflow.com/questions/21282307</Url><Stack><Type>ConflictError</Type><Message>database conflict error (oid 0x01, class OFS.Application.Application, serial this txn started with 0x03a449da3a7b1e44 2014-01-22 11:38:13.706468, serial currently committed 0x03a449da3af74dee 2014-01-22 11:38:13.820164)</Message><Frame><File>/home/myUser/opt/Zope2-2.13.21/local/lib/python2.7/site-packages/Zope2-2.13.21-py2.7.egg/OFS/Application.py</File><Line>693</Line><Method>install_product</Method></Frame><Frame><File>/home/myUser/opt/Zope2-2.13.21/local/lib/python2.7/site-packages/transaction-1.1.1-py2.7.egg/transaction/_manager.py</File><Line>89</Line><Method>commit</Method></Frame><Frame><File>/home/myUser/opt/Zope2-2.13.21/local/lib/python2.7/site-packages/transaction-1.1.1-py2.7.egg/transaction/_transaction.py</File><Line>329</Line><Method>commit</Method></Frame><Frame><File>/home/myUser/opt/Zope2-2.13.21/local/lib/python2.7/site-packages/transaction-1.1.1-py2.7.egg/transaction/_transaction.py</File><Line>446</Line><Method>_commitResources</Method></Frame><Frame><File>/home/myUser/opt/Zope2-2.13.21/local/lib/python2.7/site-packages/ZODB3-3.10.5-py2.7-linux-x86_64.egg/ZODB/Connection.py</File><Line>781</Line><Method>tpc_vote</Method></Frame><Frame><File>/home/myUser/opt/Zope2-2.13.21/local/lib/python2.7/site-packages/ZODB3-3.10.5-py2.7-linux-x86_64.egg/ZEO/ClientStorage.py</File><Line>1098</Line><Method>tpc_vote</Method></Frame><Frame><File>/home/myUser/opt/Zope2-2.13.21/local/lib/python2.7/site-packages/ZODB3-3.10.5-py2.7-linux-x86_64.egg/ZEO/ClientStorage.py</File><Line>929</Line><Method>_check_serials</Method></Frame></Stack></Post></Posts>