<?xml version="1.0" encoding="UTF-8"?><Posts><Post><PostId>11440263</PostId><Url>http://stackoverflow.com/questions/11440263</Url><Stack><Type>ConnectionError</Type><Message>HTTPConnectionPool(host='api.stlouisfed.org', port=80): Max retries exceeded with     url: /fred/series?series_id=GNPCA</Message><Frame><File>pyshell#3</File><Line>1</Line><Method>module</Method></Frame><Frame><File>build\bdist.win32\egg\fred\api.py</File><Line>90</Line><Method>series</Method></Frame><Frame><File>build\bdist.win32\egg\fred\core.py</File><Line>100</Line><Method>series</Method></Frame><Frame><File>build\bdist.win32\egg\fred\core.py</File><Line>36</Line><Method>get</Method></Frame><Frame><File>C:\Python26\lib\site-packages\requests-0.13.2-py2.6.egg\requests\api.py</File><Line>54</Line><Method>get</Method></Frame><Frame><File>C:\Python26\lib\site-packages\requests-0.13.2-py2.6.egg\requests\safe_mode.py</File><Line>37</Line><Method>wrapped</Method></Frame><Frame><File>C:\Python26\lib\site-packages\requests-0.13.2-py2.6.egg\requests\api.py</File><Line>42</Line><Method>request</Method></Frame><Frame><File>C:\Python26\lib\site-packages\requests-0.13.2-py2.6.egg\requests\sessions.py</File><Line>230</Line><Method>request</Method></Frame><Frame><File>C:\Python26\lib\site-packages\requests-0.13.2-py2.6.egg\requests\models.py</File><Line>601</Line><Method>send</Method></Frame></Stack></Post><Post><PostId>12755896</PostId><Url>http://stackoverflow.com/questions/12755896</Url><Stack><Type>ConnectionError</Type><Message>Error 2 connecting to unix socket: 127.0.0.1. No such file or directory.</Message><Frame><File>/System/Library/Frameworks/Python.framework/Versions/2.7/lib/python2.7/wsgiref/handlers.py</File><Line>85</Line><Method>run</Method></Frame><Frame><File>/Library/Python/2.7/site-packages/django/contrib/staticfiles/handlers.py</File><Line>67</Line><Method>__call__</Method></Frame><Frame><File>/Library/Python/2.7/site-packages/django/core/handlers/wsgi.py</File><Line>241</Line><Method>__call__</Method></Frame><Frame><File>/Library/Python/2.7/site-packages/django/core/handlers/base.py</File><Line>179</Line><Method>get_response</Method></Frame><Frame><File>/Library/Python/2.7/site-packages/django/core/handlers/base.py</File><Line>111</Line><Method>get_response</Method></Frame><Frame><File>/Users/dlitwak/mozio/dotcloud/demo/search/views.py</File><Line>391</Line><Method>results</Method></Frame><Frame><File>/Users/dlitwak/mozio/dotcloud/demo/cache.py</File><Line>305</Line><Method>setDistanceAndDuration</Method></Frame><Frame><File>/Library/Python/2.7/site-packages/redis_cache/cache.py</File><Line>218</Line><Method>set</Method></Frame><Frame><File>/Library/Python/2.7/site-packages/redis_cache/cache.py</File><Line>199</Line><Method>_set</Method></Frame><Frame><File>/Library/Python/2.7/site-packages/redis/client.py</File><Line>1221</Line><Method>setex</Method></Frame><Frame><File>/Library/Python/2.7/site-packages/redis/client.py</File><Line>338</Line><Method>execute_command</Method></Frame><Frame><File>/Library/Python/2.7/site-packages/redis/connection.py</File><Line>287</Line><Method>send_command</Method></Frame><Frame><File>/Library/Python/2.7/site-packages/redis/connection.py</File><Line>269</Line><Method>send_packed_command</Method></Frame><Frame><File>/Library/Python/2.7/site-packages/redis/connection.py</File><Line>217</Line><Method>connect</Method></Frame></Stack></Post><Post><PostId>14812200</PostId><Url>http://stackoverflow.com/questions/14812200</Url><Stack><Type>ConnectionError</Type><Message>[Errno 11002] getaddrinfo failed</Message><Frame><File>C:\Users\Meirion\AppData\Local\Trigger Toolkit\build-tools\forge\async.py</File><Line>96</Line><Method>run</Method></Frame><Frame><File>C:\Users\Meirion\AppData\Local\Trigger Toolkit\trigger\api\api.py</File><Line>6</Line><Method>get</Method></Frame><Frame><File>C:\Users\Meirion\AppData\Local\Trigger Toolkit\build-tools\forge\remote.py</File><Line>265</Line><Method>_api_get</Method></Frame><Frame><File>C:\Users\Meirion\AppData\Local\Trigger Toolkit\build-tools\forge\remote.py</File><Line>221</Line><Method>__get_or_post</Method></Frame><Frame><File>C:\Users\Meirion\AppData\Local\Trigger Toolkit\build-tools\forge-dependencies\requests\sessions.py</File><Line>254</Line><Method>get</Method></Frame><Frame><File>C:\Users\Meirion\AppData\Local\Trigger Toolkit\build-tools\forge-dependencies\requests\sessions.py</File><Line>241</Line><Method>request</Method></Frame><Frame><File>C:\Users\Meirion\AppData\Local\Trigger Toolkit\build-tools\forge-dependencies\requests\models.py</File><Line>634</Line><Method>send</Method></Frame></Stack></Post><Post><PostId>14817181</PostId><Url>http://stackoverflow.com/questions/14817181</Url><Stack><Type>ConnectionError</Type><Message>Too many heartbeats missed</Message><Frame><File>/app/.heroku/python/lib/python2.7/site-packages/celery/utils/timer2.py</File><Line>97</Line><Method>apply_entry</Method></Frame><Frame><File>/app/.heroku/python/lib/python2.7/site-packages/celery/utils/timer2.py</File><Line>51</Line><Method>__call__</Method></Frame><Frame><File>/app/.heroku/python/lib/python2.7/site-packages/celery/utils/timer2.py</File><Line>153</Line><Method>_reschedules</Method></Frame><Frame><File>/app/.heroku/python/lib/python2.7/site-packages/kombu/connection.py</File><Line>265</Line><Method>heartbeat_check</Method></Frame><Frame><File>/app/.heroku/python/lib/python2.7/site-packages/kombu/transport/pyamqp.py</File><Line>134</Line><Method>heartbeat_check</Method></Frame><Frame><File>/app/.heroku/python/lib/python2.7/site-packages/amqp/connection.py</File><Line>837</Line><Method>heartbeat_tick</Method></Frame></Stack></Post><Post><PostId>18353891</PostId><Url>http://stackoverflow.com/questions/18353891</Url><Stack><Type>ConnectionError</Type><Message>HTTPConnectionPool(host='localhost', port=8080): Max retries exceeded with url: /MYAPP/V1.0/user/login (Caused by</Message><Frame><File>/home/rahul/git/myapp/webapp/views/utils.py</File><Line>31</Line><Method>decorated_view</Method></Frame><Frame><File>/home/rahul/git/myapp/webapp/views/public.py</File><Line>37</Line><Method>login</Method></Frame><Frame><File>/home/rahul/git/myapp/venv/local/lib/python2.7/site-packages/requests/api.py</File><Line>88</Line><Method>post</Method></Frame><Frame><File>/home/rahul/git/myapp/venv/local/lib/python2.7/site-packages/requests/api.py</File><Line>44</Line><Method>request</Method></Frame><Frame><File>/home/rahul/git/myapp/venv/local/lib/python2.7/site-packages/requests/sessions.py</File><Line>335</Line><Method>request</Method></Frame><Frame><File>/home/rahul/git/myapp/venv/local/lib/python2.7/site-packages/requests/sessions.py</File><Line>438</Line><Method>send</Method></Frame><Frame><File>/home/rahul/git/myapp/venv/local/lib/python2.7/site-packages/requests/adapters.py</File><Line>327</Line><Method>send</Method></Frame></Stack></Post><Post><PostId>19731852</PostId><Url>http://stackoverflow.com/questions/19731852</Url><Stack><Type>ConnectionError</Type><Message>Socket closed on remote end</Message><Frame><File>c:\Python27\Lib\threading.py</File><Line>551</Line><Method>__bootstrap_inner</Method></Frame><Frame><File>c:\Python27\Lib\threading.py</File><Line>504</Line><Method>run</Method></Frame><Frame><File>C:\Users\Administrator\Documents\my_proj\my_module.py</File><Line>69</Line><Method>_listen</Method></Frame><Frame><File>C:\Users\Administrator\virtual_environments\spyker\lib\site-packages\redis\client.py</File><Line>1555</Line><Method>listen</Method></Frame><Frame><File>C:\Users\Administrator\virtual_environments\spyker\lib\site-packages\redis\client.py</File><Line>1499</Line><Method>parse_response</Method></Frame><Frame><File>C:\Users\Administrator\virtual_environments\spyker\lib\site-packages\redis\connection.py</File><Line>306</Line><Method>read_response</Method></Frame><Frame><File>C:\Users\Administrator\virtual_environments\spyker\lib\site-packages\redis\connection.py</File><Line>106</Line><Method>read_response</Method></Frame></Stack></Post><Post><PostId>21015135</PostId><Url>http://stackoverflow.com/questions/21015135</Url><Stack><Type>ConnectionError</Type><Message>HTTPConnectionPool(host='127.0.0.1', port=9200): Max</Message><Frame><File>/srv/www/site.co.uk/env/local/lib/python2.7/site-packages/django/core/handlers/base.py</File><Line>115</Line><Method>get_response</Method></Frame><Frame><File>/srv/www/site.co.uk/env/local/lib/python2.7/site-packages/django/views/generic/base.py</File><Line>68</Line><Method>view</Method></Frame><Frame><File>/srv/www/site.co.uk/env/local/lib/python2.7/site-packages/django/views/generic/base.py</File><Line>86</Line><Method>dispatch</Method></Frame><Frame><File>/srv/www/site.co.uk/env/local/lib/python2.7/site-packages/django/views/generic/base.py</File><Line>153</Line><Method>get</Method></Frame><Frame><File>/srv/www/site.co.uk/clothes_comparison/clothes_comparison/views.py</File><Line>56</Line><Method>get_context_data</Method></Frame><Frame><File>/srv/www/site.co.uk/env/local/lib/python2.7/site-packages/pyelasticsearch/client.py</File><Line>96</Line><Method>decorate</Method></Frame><Frame><File>/srv/www/site.co.uk/env/local/lib/python2.7/site-packages/pyelasticsearch/client.py</File><Line>512</Line><Method>multi_get</Method></Frame><Frame><File>/srv/www/site.co.uk/env/local/lib/python2.7/site-packages/pyelasticsearch/client.py</File><Line>238</Line><Method>send_request</Method></Frame><Frame><File>/srv/www/site.co.uk/env/local/lib/python2.7/site-packages/requests/sessions.py</File><Line>347</Line><Method>get</Method></Frame><Frame><File>/srv/www/site.co.uk/env/local/lib/python2.7/site-packages/requests/sessions.py</File><Line>335</Line><Method>request</Method></Frame><Frame><File>/srv/www/site.co.uk/env/local/lib/python2.7/site-packages/requests/sessions.py</File><Line>438</Line><Method>send</Method></Frame><Frame><File>/srv/www/site.co.uk/env/local/lib/python2.7/site-packages/requests/adapters.py</File><Line>327</Line><Method>send</Method></Frame></Stack></Post><Post><PostId>23002367</PostId><Url>http://stackoverflow.com/questions/23002367</Url><Stack><Type>ConnectionError</Type><Message>HTTPConnectionPool(host='10.0.10.4', port=80): Max retries exceeded with url: / (Caused by</Message><Frame><File>/usr/lib64/python2.6/threading.py</File><Line>532</Line><Method>__bootstrap_inner</Method></Frame><Frame><File>./my.py</File><Line>47</Line><Method>run</Method></Frame><Frame><File>/usr/lib/python2.6/site-packages/requests-2.3.0-py2.6.egg/requests/sessions.py</File><Line>464</Line><Method>get</Method></Frame><Frame><File>/usr/lib/python2.6/site-packages/requests-2.3.0-py2.6.egg/requests/sessions.py</File><Line>452</Line><Method>request</Method></Frame><Frame><File>/usr/lib/python2.6/site-packages/requests-2.3.0-py2.6.egg/requests/sessions.py</File><Line>555</Line><Method>send</Method></Frame><Frame><File>/usr/lib/python2.6/site-packages/requests-2.3.0-py2.6.egg/requests/adapters.py</File><Line>375</Line><Method>send</Method></Frame></Stack></Post><Post><PostId>24614016</PostId><Url>http://stackoverflow.com/questions/24614016</Url><Stack><Type>ConnectionError</Type><Message>HTTPConnectionPool(host='127.0.0.1', port=4400): Max retries exceeded with url: / (Caused by</Message><Frame><File>/home/me/PycharmProjects/test/client.py</File><Line>16</Line><Method>f</Method></Frame><Frame><File>/usr/local/lib/python2.7/dist-packages/requests/api.py</File><Line>55</Line><Method>get</Method></Frame><Frame><File>/usr/local/lib/python2.7/dist-packages/requests/api.py</File><Line>44</Line><Method>request</Method></Frame><Frame><File>/usr/local/lib/python2.7/dist-packages/requests/sessions.py</File><Line>383</Line><Method>request</Method></Frame><Frame><File>/usr/local/lib/python2.7/dist-packages/requests/sessions.py</File><Line>486</Line><Method>send</Method></Frame><Frame><File>/usr/local/lib/python2.7/dist-packages/requests/adapters.py</File><Line>378</Line><Method>send</Method></Frame></Stack></Post><Post><PostId>24968169</PostId><Url>http://stackoverflow.com/questions/24968169</Url><Stack><Type>ConnectionError</Type><Message>HTTPSConnectionPool(host='graph.facebook.com', port=443): Max retries exceeded with url: /me?access_token=CAAUi8RJCRZAkBAPdHFKhckONnLwjOExZCeVXpW39GZAZBLdD5rTsukQqTPi9KP6neMDxtwdhZAQvmzCS92rxR0rIZCNlzenQ2jHiyANvToy6tOWrOh5ZAYFmJFYeYvbXGNc9fuPIa0hAUqGfPzFtZB0tepoxoO7bpt01izuTYBkmS9NJChXaX9iDZAQlDTDvtLTZBvLesjFtSfwp6RusbArRzH (Caused by</Message><Frame><File>/home/amir/claudius/lib/python2.7/site-packages/allauth/socialaccount/providers/facebook/views.py</File><Line>73</Line><Method>login_by_token</Method></Frame><Frame><File>/home/amir/claudius/lib/python2.7/site-packages/allauth/socialaccount/providers/facebook/views.py</File><Line>26</Line><Method>fb_complete_login</Method></Frame><Frame><File>/home/amir/claudius/lib/python2.7/site-packages/requests/api.py</File><Line>55</Line><Method>get</Method></Frame><Frame><File>/home/amir/claudius/lib/python2.7/site-packages/requests/api.py</File><Line>44</Line><Method>request</Method></Frame><Frame><File>/home/amir/claudius/lib/python2.7/site-packages/requests/sessions.py</File><Line>456</Line><Method>request</Method></Frame><Frame><File>/home/amir/claudius/lib/python2.7/site-packages/requests/sessions.py</File><Line>559</Line><Method>send</Method></Frame><Frame><File>/home/amir/claudius/lib/python2.7/site-packages/requests/adapters.py</File><Line>375</Line><Method>send</Method></Frame></Stack></Post><Post><PostId>25120696</PostId><Url>http://stackoverflow.com/questions/25120696</Url><Stack><Type>ConnectionError</Type><Message>Socket was disconnected</Message><Frame><File>/usr/local/lib/python2.7/dist-packages/celery/worker/consumer.py</File><Line>278</Line><Method>start</Method></Frame><Frame><File>/usr/local/lib/python2.7/dist-packages/celery/bootsteps.py</File><Line>123</Line><Method>start</Method></Frame><Frame><File>/usr/local/lib/python2.7/dist-packages/celery/worker/consumer.py</File><Line>796</Line><Method>start</Method></Frame><Frame><File>/usr/local/lib/python2.7/dist-packages/celery/worker/loops.py</File><Line>72</Line><Method>asynloop</Method></Frame><Frame><File>/usr/local/lib/python2.7/dist-packages/kombu/async/hub.py</File><Line>320</Line><Method>create_loop</Method></Frame><Frame><File>/usr/local/lib/python2.7/dist-packages/kombu/transport/base.py</File><Line>159</Line><Method>on_readable</Method></Frame><Frame><File>/usr/local/lib/python2.7/dist-packages/kombu/transport/base.py</File><Line>142</Line><Method>_read</Method></Frame></Stack></Post><Post><PostId>25203445</PostId><Url>http://stackoverflow.com/questions/25203445</Url><Stack><Type>ConnectionError</Type><Message>error 3 from memcached_get(:1:avatar_url_eui_80_2387): CONNECTION FAILURE, host: 127.0.0.1:11211 -</Message><Frame><File>/app/.heroku/python/lib/python2.7/site-packages/django/core/handlers/base.py</File><Line>114</Line><Method>get_response</Method></Frame><Frame><File>/app/.heroku/python/lib/python2.7/site-packages/django/contrib/auth/decorators.py</File><Line>22</Line><Method>_wrapped_view</Method></Frame><Frame><File>/app/.heroku/python/lib/python2.7/site-packages/avatar/views.py</File><Line>123</Line><Method>change</Method></Frame><Frame><File>/app/.heroku/python/lib/python2.7/site-packages/django/shortcuts/__init__.py</File><Line>53</Line><Method>render</Method></Frame><Frame><File>/app/.heroku/python/lib/python2.7/site-packages/django/template/loader.py</File><Line>169</Line><Method>render_to_string</Method></Frame><Frame><File>/app/.heroku/python/lib/python2.7/site-packages/django/template/base.py</File><Line>140</Line><Method>render</Method></Frame><Frame><File>/app/.heroku/python/lib/python2.7/site-packages/django/template/base.py</File><Line>134</Line><Method>_render</Method></Frame><Frame><File>/app/.heroku/python/lib/python2.7/site-packages/django/template/base.py</File><Line>840</Line><Method>render</Method></Frame><Frame><File>/app/.heroku/python/lib/python2.7/site-packages/django/template/debug.py</File><Line>78</Line><Method>render_node</Method></Frame><Frame><File>/app/.heroku/python/lib/python2.7/site-packages/django/template/loader_tags.py</File><Line>123</Line><Method>render</Method></Frame><Frame><File>/app/.heroku/python/lib/python2.7/site-packages/django/template/base.py</File><Line>134</Line><Method>_render</Method></Frame><Frame><File>/app/.heroku/python/lib/python2.7/site-packages/django/template/base.py</File><Line>840</Line><Method>render</Method></Frame><Frame><File>/app/.heroku/python/lib/python2.7/site-packages/django/template/debug.py</File><Line>78</Line><Method>render_node</Method></Frame><Frame><File>/app/.heroku/python/lib/python2.7/site-packages/django/template/loader_tags.py</File><Line>123</Line><Method>render</Method></Frame><Frame><File>/app/.heroku/python/lib/python2.7/site-packages/django/template/base.py</File><Line>134</Line><Method>_render</Method></Frame><Frame><File>/app/.heroku/python/lib/python2.7/site-packages/django/template/base.py</File><Line>840</Line><Method>render</Method></Frame><Frame><File>/app/.heroku/python/lib/python2.7/site-packages/django/template/debug.py</File><Line>78</Line><Method>render_node</Method></Frame><Frame><File>/app/.heroku/python/lib/python2.7/site-packages/django/template/loader_tags.py</File><Line>62</Line><Method>render</Method></Frame><Frame><File>/app/.heroku/python/lib/python2.7/site-packages/django/template/base.py</File><Line>840</Line><Method>render</Method></Frame><Frame><File>/app/.heroku/python/lib/python2.7/site-packages/django/template/debug.py</File><Line>78</Line><Method>render_node</Method></Frame><Frame><File>/app/.heroku/python/lib/python2.7/site-packages/django/template/base.py</File><Line>1125</Line><Method>render</Method></Frame><Frame><File>/app/.heroku/python/lib/python2.7/site-packages/avatar/templatetags/avatar_tags.py</File><Line>54</Line><Method>avatar</Method></Frame><Frame><File>/app/.heroku/python/lib/python2.7/site-packages/avatar/util.py</File><Line>72</Line><Method>cached_func</Method></Frame><Frame><File>/app/.heroku/python/lib/python2.7/site-packages/django/core/cache/backends/memcached.py</File><Line>75</Line><Method>get</Method></Frame></Stack></Post><Post><PostId>25250132</PostId><Url>http://stackoverflow.com/questions/25250132</Url><Stack><Type>ConnectionError</Type><Message>HTTPSConnectionPool(host='api.github.com', port=443): Max retries exceeded with url: /user (Caused by</Message><Frame><File>pyshell#32</File><Line>1</Line><Method>module</Method></Frame><Frame><File>C:\Python27\lib\site-packages\requests-2.3.0-py2.7.egg\requests\api.py</File><Line>55</Line><Method>get</Method></Frame><Frame><File>C:\Python27\lib\site-packages\requests-2.3.0-py2.7.egg\requests\api.py</File><Line>44</Line><Method>request</Method></Frame><Frame><File>C:\Python27\lib\site-packages\requests-2.3.0-py2.7.egg\requests\sessions.py</File><Line>456</Line><Method>request</Method></Frame><Frame><File>C:\Python27\lib\site-packages\requests-2.3.0-py2.7.egg\requests\sessions.py</File><Line>559</Line><Method>send</Method></Frame><Frame><File>C:\Python27\lib\site-packages\requests-2.3.0-py2.7.egg\requests\adapters.py</File><Line>375</Line><Method>send</Method></Frame></Stack></Post><Post><PostId>25471828</PostId><Url>http://stackoverflow.com/questions/25471828</Url><Stack><Type>ConnectionError</Type><Message>ConnectionError(('Connection aborted.', error(61, 'Connection refused'))) caused by: ProtocolError(('Connection aborted.', error(61, 'Connection refused')))</Message><Frame><File>/Library/Frameworks/Python.framework/Versions/2.7/lib/python2.7/site-packages/haystack/management/commands/update_index.py</File><Line>221</Line><Method>handle_label</Method></Frame><Frame><File>/Library/Frameworks/Python.framework/Versions/2.7/lib/python2.7/site-packages/haystack/management/commands/update_index.py</File><Line>266</Line><Method>update_backend</Method></Frame><Frame><File>/Library/Frameworks/Python.framework/Versions/2.7/lib/python2.7/site-packages/haystack/management/commands/update_index.py</File><Line>89</Line><Method>do_update</Method></Frame><Frame><File>/Library/Frameworks/Python.framework/Versions/2.7/lib/python2.7/site-packages/haystack/backends/elasticsearch_backend.py</File><Line>184</Line><Method>update</Method></Frame><Frame><File>/Library/Frameworks/Python.framework/Versions/2.7/lib/python2.7/site-packages/elasticsearch/helpers/__init__.py</File><Line>145</Line><Method>bulk</Method></Frame><Frame><File>/Library/Frameworks/Python.framework/Versions/2.7/lib/python2.7/site-packages/elasticsearch/helpers/__init__.py</File><Line>104</Line><Method>streaming_bulk</Method></Frame><Frame><File>/Library/Frameworks/Python.framework/Versions/2.7/lib/python2.7/site-packages/elasticsearch/client/utils.py</File><Line>68</Line><Method>_wrapped</Method></Frame><Frame><File>/Library/Frameworks/Python.framework/Versions/2.7/lib/python2.7/site-packages/elasticsearch/client/__init__.py</File><Line>646</Line><Method>bulk</Method></Frame><Frame><File>/Library/Frameworks/Python.framework/Versions/2.7/lib/python2.7/site-packages/elasticsearch/transport.py</File><Line>284</Line><Method>perform_request</Method></Frame><Frame><File>/Library/Frameworks/Python.framework/Versions/2.7/lib/python2.7/site-packages/elasticsearch/connection/http_urllib3.py</File><Line>51</Line><Method>perform_request</Method></Frame></Stack></Post></Posts>