<?xml version="1.0" encoding="UTF-8"?><Posts><Post><PostId>3774747</PostId><Url>http://stackoverflow.com/questions/3774747</Url><Stack><Type>DatabaseError</Type><Message>no such table: medley_heiselfoo_heiselfoo</Message><Frame><File>/Users/chris/Code/heiselfoo/ve/lib/python2.6/site-packages/heiselfoo/tests.py</File><Line>10</Line><Method>test_truth</Method></Frame><Frame><File>/Users/chris/Code/heiselfoo/ve/lib/python2.6/site-packages/django/db/models/base.py</File><Line>434</Line><Method>save</Method></Frame><Frame><File>/Users/chris/Code/heiselfoo/ve/lib/python2.6/site-packages/django/db/models/base.py</File><Line>527</Line><Method>save_base</Method></Frame><Frame><File>/Users/chris/Code/heiselfoo/ve/lib/python2.6/site-packages/django/db/models/manager.py</File><Line>195</Line><Method>_insert</Method></Frame><Frame><File>/Users/chris/Code/heiselfoo/ve/lib/python2.6/site-packages/django/db/models/query.py</File><Line>1479</Line><Method>insert_query</Method></Frame><Frame><File>/Users/chris/Code/heiselfoo/ve/lib/python2.6/site-packages/django/db/models/sql/compiler.py</File><Line>783</Line><Method>execute_sql</Method></Frame><Frame><File>/Users/chris/Code/heiselfoo/ve/lib/python2.6/site-packages/django/db/models/sql/compiler.py</File><Line>727</Line><Method>execute_sql</Method></Frame><Frame><File>/Users/chris/Code/heiselfoo/ve/lib/python2.6/site-packages/django/db/backends/sqlite3/base.py</File><Line>200</Line><Method>execute</Method></Frame></Stack></Post><Post><PostId>4361443</PostId><Url>http://stackoverflow.com/questions/4361443</Url><Stack><Type>DatabaseError</Type><Message>Unexpected keyword arguments: next_count, prefetch_count, offset</Message><Frame><File>/base/data/home/apps/ezcrd2/10.346707310382875890/common-apps/django/core/handlers/base.py</File><Line>101</Line><Method>get_response</Method></Frame><Frame><File>/base/data/home/apps/ezcrd2/10.346707310382875890/django_oauth_twitter/views.py</File><Line>159</Line><Method>callback</Method></Frame><Frame><File>/base/data/home/apps/ezcrd2/10.346707310382875890/django_oauth_twitter/views.py</File><Line>239</Line><Method>_authenticate</Method></Frame><Frame><File>/base/data/home/apps/ezcrd2/10.346707310382875890/common-apps/django/db/models/manager.py</File><Line>132</Line><Method>get</Method></Frame><Frame><File>/base/data/home/apps/ezcrd2/10.346707310382875890/common-apps/django/db/models/query.py</File><Line>334</Line><Method>get</Method></Frame><Frame><File>/base/data/home/apps/ezcrd2/10.346707310382875890/common-apps/django/db/models/query.py</File><Line>79</Line><Method>__len__</Method></Frame><Frame><File>/base/data/home/apps/ezcrd2/10.346707310382875890/common-apps/django/db/models/query.py</File><Line>267</Line><Method>iterator</Method></Frame><Frame><File>/base/data/home/apps/ezcrd2/10.346707310382875890/common-apps/djangoappengine/db/compiler.py</File><Line>96</Line><Method>results_iter</Method></Frame><Frame><File>/base/python_runtime/python_lib/versions/1/google/appengine/api/datastore.py</File><Line>1304</Line><Method>Run</Method></Frame><Frame><File>/base/python_runtime/python_lib/versions/1/google/appengine/api/datastore.py</File><Line>169</Line><Method>_GetConfigFromKwargs</Method></Frame></Stack></Post><Post><PostId>5161173</PostId><Url>http://stackoverflow.com/questions/5161173</Url><Stack><Type>DatabaseError</Type><Message>(1146, "Table 'test_mcif_django.customer' doesn't exist")</Message><Frame><File>/home/jason/projects/mcifdjango/mcif/tests/customer_upsert_test.py</File><Line>9</Line><Method>test_upsert</Method></Frame><Frame><File>/home/jason/projects/mcifdjango/mcif/models/mcif_model.py</File><Line>11</Line><Method>upsert</Method></Frame><Frame><File>/usr/lib/pymodules/python2.6/django/db/backends/mysql/base.py</File><Line>86</Line><Method>execute</Method></Frame><Frame><File>/usr/lib/pymodules/python2.6/MySQLdb/cursors.py</File><Line>166</Line><Method>execute</Method></Frame><Frame><File>/usr/lib/pymodules/python2.6/MySQLdb/connections.py</File><Line>35</Line><Method>defaulterrorhandler</Method></Frame></Stack></Post><Post><PostId>5172612</PostId><Url>http://stackoverflow.com/questions/5172612</Url><Stack><Type>DatabaseError</Type><Message>Lookup type 'month' isn't supported</Message><Frame><File>F:\Its_mine19\Programming\Java\pineapplemon\src\django\core\handlers\base.py</File><Line>111</Line><Method>get_response</Method></Frame><Frame><File>F:\Its_mine19\Programming\Java\pineapplemon\src\django\contrib\admin\options.py</File><Line>308</Line><Method>wrapper</Method></Frame><Frame><File>F:\Its_mine19\Programming\Java\pineapplemon\src\django\utils\decorators.py</File><Line>93</Line><Method>_wrapped_view</Method></Frame><Frame><File>F:\Its_mine19\Programming\Java\pineapplemon\src\django\views\decorators\cache.py</File><Line>79</Line><Method>_wrapped_view_func</Method></Frame><Frame><File>F:\Its_mine19\Programming\Java\pineapplemon\src\django\contrib\admin\sites.py</File><Line>190</Line><Method>inner</Method></Frame><Frame><File>F:\Its_mine19\Programming\Java\pineapplemon\src\django\utils\decorators.py</File><Line>28</Line><Method>_wrapper</Method></Frame><Frame><File>F:\Its_mine19\Programming\Java\pineapplemon\src\django\utils\decorators.py</File><Line>93</Line><Method>_wrapped_view</Method></Frame><Frame><File>F:\Its_mine19\Programming\Java\pineapplemon\src\django\utils\decorators.py</File><Line>24</Line><Method>bound_func</Method></Frame><Frame><File>F:\Its_mine19\Programming\Java\pineapplemon\src\django\db\transaction.py</File><Line>282</Line><Method>inner</Method></Frame><Frame><File>F:\Its_mine19\Programming\Java\pineapplemon\src\django\contrib\admin\options.py</File><Line>852</Line><Method>add_view</Method></Frame><Frame><File>F:\Its_mine19\Programming\Java\pineapplemon\src\django\forms\forms.py</File><Line>121</Line><Method>is_valid</Method></Frame><Frame><File>F:\Its_mine19\Programming\Java\pineapplemon\src\django\forms\forms.py</File><Line>112</Line><Method>_get_errors</Method></Frame><Frame><File>F:\Its_mine19\Programming\Java\pineapplemon\src\django\forms\forms.py</File><Line>269</Line><Method>full_clean</Method></Frame><Frame><File>F:\Its_mine19\Programming\Java\pineapplemon\src\django\forms\models.py</File><Line>338</Line><Method>_post_clean</Method></Frame><Frame><File>F:\Its_mine19\Programming\Java\pineapplemon\src\django\forms\models.py</File><Line>347</Line><Method>validate_unique</Method></Frame><Frame><File>F:\Its_mine19\Programming\Java\pineapplemon\src\django\db\models\base.py</File><Line>669</Line><Method>validate_unique</Method></Frame><Frame><File>F:\Its_mine19\Programming\Java\pineapplemon\src\django\db\models\base.py</File><Line>791</Line><Method>_perform_date_checks</Method></Frame><Frame><File>F:\Its_mine19\Programming\Java\pineapplemon\src\django\db\models\query.py</File><Line>498</Line><Method>exists</Method></Frame><Frame><File>F:\Its_mine19\Programming\Java\pineapplemon\src\django\db\models\sql\query.py</File><Line>428</Line><Method>has_results</Method></Frame><Frame><File>F:\Its_mine19\Programming\Java\pineapplemon\src\djangotoolbox\db\basecompiler.py</File><Line>222</Line><Method>has_results</Method></Frame><Frame><File>F:\Its_mine19\Programming\Java\pineapplemon\src\djangotoolbox\db\basecompiler.py</File><Line>269</Line><Method>get_count</Method></Frame><Frame><File>F:\Its_mine19\Programming\Java\pineapplemon\src\djangotoolbox\db\basecompiler.py</File><Line>275</Line><Method>build_query</Method></Frame><Frame><File>F:\Its_mine19\Programming\Java\pineapplemon\src\djangotoolbox\db\basecompiler.py</File><Line>72</Line><Method>add_filters</Method></Frame><Frame><File>F:\Its_mine19\Programming\Java\pineapplemon\src\djangotoolbox\db\basecompiler.py</File><Line>76</Line><Method>add_filters</Method></Frame><Frame><File>F:\Its_mine19\Programming\Java\pineapplemon\src\djangoappengine\db\compiler.py</File><Line>57</Line><Method>_func</Method></Frame><Frame><File>F:\Its_mine19\Programming\Java\pineapplemon\src\djangoappengine\db\compiler.py</File><Line>211</Line><Method>add_filter</Method></Frame></Stack></Post><Post><PostId>5970377</PostId><Url>http://stackoverflow.com/questions/5970377</Url><Stack><Type>DatabaseError</Type><Message>no such table: visualize_analysis</Message><Frame><File>import_scripts/tests.py</File><Line>20</Line><Method>test_analysis_creation</Method></Frame><Frame><File>/home/dan/programmingProjects/topical_guide/import_scripts/analysis_import.py</File><Line>117</Line><Method>create_analysis</Method></Frame><Frame><File>/usr/local/lib/python2.7/dist-packages/Django-1.3-py2.7.egg/django/db/models/manager.py</File><Line>132</Line><Method>get</Method></Frame><Frame><File>/usr/local/lib/python2.7/dist-packages/Django-1.3-py2.7.egg/django/db/models/query.py</File><Line>344</Line><Method>get</Method></Frame><Frame><File>/usr/local/lib/python2.7/dist-packages/Django-1.3-py2.7.egg/django/db/models/query.py</File><Line>82</Line><Method>__len__</Method></Frame><Frame><File>/usr/local/lib/python2.7/dist-packages/Django-1.3-py2.7.egg/django/db/models/query.py</File><Line>273</Line><Method>iterator</Method></Frame><Frame><File>/usr/local/lib/python2.7/dist-packages/Django-1.3-py2.7.egg/django/db/models/sql/compiler.py</File><Line>680</Line><Method>results_iter</Method></Frame><Frame><File>/usr/local/lib/python2.7/dist-packages/Django-1.3-py2.7.egg/django/db/models/sql/compiler.py</File><Line>735</Line><Method>execute_sql</Method></Frame><Frame><File>/usr/local/lib/python2.7/dist-packages/Django-1.3-py2.7.egg/django/db/backends/util.py</File><Line>34</Line><Method>execute</Method></Frame><Frame><File>/usr/local/lib/python2.7/dist-packages/Django-1.3-py2.7.egg/django/db/backends/sqlite3/base.py</File><Line>234</Line><Method>execute</Method></Frame></Stack></Post><Post><PostId>6078930</PostId><Url>http://stackoverflow.com/questions/6078930</Url><Stack><Type>DatabaseError</Type><Message>no such table: autest_daemon</Message><Frame><File>/usr/lib/python2.6/threading.py</File><Line>532</Line><Method>__bootstrap_inner</Method></Frame><Frame><File>/usr/lib/python2.6/threading.py</File><Line>484</Line><Method>run</Method></Frame><Frame><File>/home/bhayes/lockss-code/hare/lockss-django/autest/tests.py</File><Line>247</Line><Method>printer</Method></Frame><Frame><File>/usr/lib/pymodules/python2.6/django/db/models/manager.py</File><Line>120</Line><Method>count</Method></Frame><Frame><File>/usr/lib/pymodules/python2.6/django/db/models/query.py</File><Line>326</Line><Method>count</Method></Frame><Frame><File>/usr/lib/pymodules/python2.6/django/db/models/sql/query.py</File><Line>394</Line><Method>get_count</Method></Frame><Frame><File>/usr/lib/pymodules/python2.6/django/db/models/sql/query.py</File><Line>366</Line><Method>get_aggregation</Method></Frame><Frame><File>/usr/lib/pymodules/python2.6/django/db/models/sql/compiler.py</File><Line>727</Line><Method>execute_sql</Method></Frame><Frame><File>/usr/lib/pymodules/python2.6/django/db/backends/sqlite3/base.py</File><Line>200</Line><Method>execute</Method></Frame></Stack></Post><Post><PostId>6444251</PostId><Url>http://stackoverflow.com/questions/6444251</Url><Stack><Type>DatabaseError</Type><Message>ORA-12705: Cannot access NLS data files or invalid environment specified</Message><Frame><File>pyshell#3</File><Line>1</Line><Method>module</Method></Frame><Frame><File>C:\oracleTest.py</File><Line>2</Line><Method>module</Method></Frame></Stack></Post><Post><PostId>6444251</PostId><Url>http://stackoverflow.com/questions/6444251</Url><Stack><Type>DatabaseError</Type><Message>ORA-12705: Cannot access NLS data files or invalid environment specified</Message><Frame><File>pyshell#3</File><Line>1</Line><Method>module</Method></Frame><Frame><File>C:\oracleTest.py</File><Line>2</Line><Method>module</Method></Frame></Stack></Post><Post><PostId>6959702</PostId><Url>http://stackoverflow.com/questions/6959702</Url><Stack><Type>DatabaseError</Type><Message>no such table: celery_taskmeta</Message><Frame><File>/Users/erichutchinson/python-env/slate/lib/python2.7/site-packages/celery/worker/job.py</File><Line>107</Line><Method>execute_safe</Method></Frame><Frame><File>/Users/erichutchinson/python-env/slate/lib/python2.7/site-packages/celery/worker/job.py</File><Line>125</Line><Method>execute</Method></Frame><Frame><File>/Users/erichutchinson/python-env/slate/lib/python2.7/site-packages/celery/execute/trace.py</File><Line>79</Line><Method>execute</Method></Frame><Frame><File>/Users/erichutchinson/python-env/slate/lib/python2.7/site-packages/celery/execute/trace.py</File><Line>93</Line><Method>_trace</Method></Frame><Frame><File>/Users/erichutchinson/python-env/slate/lib/python2.7/site-packages/celery/worker/job.py</File><Line>140</Line><Method>handle_success</Method></Frame><Frame><File>/Users/erichutchinson/python-env/slate/lib/python2.7/site-packages/celery/backends/base.py</File><Line>54</Line><Method>mark_as_done</Method></Frame><Frame><File>/Users/erichutchinson/python-env/slate/lib/python2.7/site-packages/celery/backends/base.py</File><Line>194</Line><Method>store_result</Method></Frame><Frame><File>/Users/erichutchinson/python-env/slate/lib/python2.7/site-packages/djcelery/backends/database.py</File><Line>20</Line><Method>_store_result</Method></Frame><Frame><File>/Users/erichutchinson/python-env/slate/lib/python2.7/site-packages/djcelery/managers.py</File><Line>36</Line><Method>_inner</Method></Frame><Frame><File>/Users/erichutchinson/python-env/slate/lib/python2.7/site-packages/djcelery/managers.py</File><Line>154</Line><Method>store_result</Method></Frame><Frame><File>/Users/erichutchinson/python-env/slate/lib/python2.7/site-packages/djcelery/managers.py</File><Line>78</Line><Method>update_or_create</Method></Frame><Frame><File>/Users/erichutchinson/python-env/slate/lib/python2.7/site-packages/djcelery/managers.py</File><Line>62</Line><Method>update_or_create</Method></Frame><Frame><File>/Users/erichutchinson/python-env/slate/lib/python2.7/site-packages/django/db/models/query.py</File><Line>378</Line><Method>get_or_create</Method></Frame><Frame><File>/Users/erichutchinson/python-env/slate/lib/python2.7/site-packages/django/db/models/query.py</File><Line>344</Line><Method>get</Method></Frame><Frame><File>/Users/erichutchinson/python-env/slate/lib/python2.7/site-packages/django/db/models/query.py</File><Line>82</Line><Method>__len__</Method></Frame><Frame><File>/Users/erichutchinson/python-env/slate/lib/python2.7/site-packages/django/db/models/query.py</File><Line>273</Line><Method>iterator</Method></Frame><Frame><File>/Users/erichutchinson/python-env/slate/lib/python2.7/site-packages/django/db/models/sql/compiler.py</File><Line>680</Line><Method>results_iter</Method></Frame><Frame><File>/Users/erichutchinson/python-env/slate/lib/python2.7/site-packages/django/db/models/sql/compiler.py</File><Line>735</Line><Method>execute_sql</Method></Frame><Frame><File>/Users/erichutchinson/python-env/slate/lib/python2.7/site- packages/django/db/backends/util.py</File><Line>34</Line><Method>execute</Method></Frame><Frame><File>/Users/erichutchinson/python-env/slate/lib/python2.7/site- packages/django/db/backends/sqlite3/base.py</File><Line>234</Line><Method>execute</Method></Frame></Stack></Post><Post><PostId>7192675</PostId><Url>http://stackoverflow.com/questions/7192675</Url><Stack><Type>DatabaseError</Type><Message>no such table: core_client</Message><Frame><File>.../django/core/management/commands/loaddata.py</File><Line>174</Line><Method>handle</Method></Frame><Frame><File>.../django/core/serializers/base.py</File><Line>165</Line><Method>save</Method></Frame><Frame><File>.../django/db/models/base.py</File><Line>522</Line><Method>save_base</Method></Frame><Frame><File>.../django/db/models/query.py</File><Line>496</Line><Method>exists</Method></Frame><Frame><File>.../django/db/models/sql/query.py</File><Line>424</Line><Method>has_results</Method></Frame><Frame><File>.../django/db/models/sql/compiler.py</File><Line>735</Line><Method>execute_sql</Method></Frame><Frame><File>.../django/db/backends/util.py</File><Line>34</Line><Method>execute</Method></Frame><Frame><File>.../django/db/backends/sqlite3/base.py</File><Line>234</Line><Method>execute</Method></Frame></Stack></Post><Post><PostId>7914533</PostId><Url>http://stackoverflow.com/questions/7914533</Url><Stack><Type>DatabaseError</Type><Message>invalid byte sequence for encoding "UTF8": 0x97</Message><Frame><File>C:\PIDevelopment\workspace37_pydev\pyh23\py23\service\auth\tests.py</File><Line>64</Line><Method>test_001_registerUserInfo</Method></Frame><Frame><File>C:\Python25\lib\site-packages\django\db\models\base.py</File><Line>458</Line><Method>save</Method></Frame><Frame><File>C:\Python25\lib\site-packages\django\db\models\base.py</File><Line>551</Line><Method>save_base</Method></Frame><Frame><File>C:\Python25\Lib\site-packages\django\db\models\manager.py</File><Line>195</Line><Method>_insert</Method></Frame><Frame><File>C:\Python25\lib\site-packages\django\db\models\query.py</File><Line>1524</Line><Method>insert_query</Method></Frame><Frame><File>C:\Python25\lib\site-packages\django\db\models\sql\compiler.py</File><Line>788</Line><Method>execute_sql</Method></Frame><Frame><File>C:\Python25\lib\site-packages\django\db\models\sql\compiler.py</File><Line>732</Line><Method>execute_sql</Method></Frame><Frame><File>C:\Python25\lib\site-packages\django\db\backends\util.py</File><Line>15</Line><Method>execute</Method></Frame><Frame><File>C:\Python25\lib\site-packages\django\db\backends\postgresql_psycopg2\base.py</File><Line>44</Line><Method>execute</Method></Frame></Stack></Post><Post><PostId>8082045</PostId><Url>http://stackoverflow.com/questions/8082045</Url><Stack><Type>DatabaseError</Type><Message>SAVEPOINT can only be used in transaction blocks</Message><Frame><File>/Users/kepioo/Documents/code/virtualenvs/myproject/proj/../proj/apps/project/tests/integration_tests.py</File><Line>88</Line><Method>test_update_project_files</Method></Frame><Frame><File>/Users/kepioo/Documents/code/virtualenvs/myproject/lib/python2.6/site-packages/django_webtest/__init__.py</File><Line>71</Line><Method>get</Method></Frame><Frame><File>/Users/kepioo/Documents/code/virtualenvs/myproject/lib/python2.6/site-packages/webtest/app.py</File><Line>756</Line><Method>get</Method></Frame><Frame><File>/Users/kepioo/Documents/code/virtualenvs/myproject/lib/python2.6/site-packages/django_webtest/__init__.py</File><Line>42</Line><Method>do_request</Method></Frame><Frame><File>/Users/kepioo/Documents/code/virtualenvs/myproject/lib/python2.6/site-packages/webtest/app.py</File><Line>1000</Line><Method>do_request</Method></Frame><Frame><File>/Users/kepioo/Documents/code/virtualenvs/myproject/lib/python2.6/site-packages/webob/request.py</File><Line>1145</Line><Method>get_response</Method></Frame><Frame><File>/Users/kepioo/Documents/code/virtualenvs/myproject/lib/python2.6/site-packages/webob/request.py</File><Line>1118</Line><Method>call_application</Method></Frame><Frame><File>/Users/kepioo/Documents/code/virtualenvs/myproject/lib/python2.6/site-packages/webtest/lint.py</File><Line>173</Line><Method>lint_app</Method></Frame><Frame><File>/Users/kepioo/Documents/code/virtualenvs/myproject/lib/python2.6/site-packages/django_webtest/middleware.py</File><Line>77</Line><Method>__call__</Method></Frame><Frame><File>/Users/kepioo/Documents/code/virtualenvs/myproject/lib/python2.6/site-packages/django/contrib/staticfiles/handlers.py</File><Line>68</Line><Method>__call__</Method></Frame><Frame><File>/Users/kepioo/Documents/code/virtualenvs/myproject/lib/python2.6/site-packages/django/core/handlers/wsgi.py</File><Line>272</Line><Method>__call__</Method></Frame><Frame><File>/Users/kepioo/Documents/code/virtualenvs/myproject/lib/python2.6/site-packages/django/core/handlers/base.py</File><Line>169</Line><Method>get_response</Method></Frame><Frame><File>/Users/kepioo/Documents/code/virtualenvs/myproject/lib/python2.6/site-packages/django/core/handlers/base.py</File><Line>89</Line><Method>get_response</Method></Frame><Frame><File>/Users/kepioo/Documents/code/virtualenvs/myproject/lib/python2.6/site-packages/django_webtest/middleware.py</File><Line>49</Line><Method>process_request</Method></Frame><Frame><File>/Users/kepioo/Documents/code/virtualenvs/myproject/lib/python2.6/site-packages/django/contrib/auth/__init__.py</File><Line>80</Line><Method>login</Method></Frame><Frame><File>/Users/kepioo/Documents/code/virtualenvs/myproject/lib/python2.6/site-packages/django/contrib/sessions/backends/base.py</File><Line>271</Line><Method>cycle_key</Method></Frame><Frame><File>/Users/kepioo/Documents/code/virtualenvs/myproject/lib/python2.6/site-packages/django/contrib/sessions/backends/db.py</File><Line>40</Line><Method>create</Method></Frame><Frame><File>/Users/kepioo/Documents/code/virtualenvs/myproject/lib/python2.6/site-packages/django/contrib/sessions/backends/db.py</File><Line>61</Line><Method>save</Method></Frame><Frame><File>/Users/kepioo/Documents/code/virtualenvs/myproject/lib/python2.6/site-packages/django/db/transaction.py</File><Line>162</Line><Method>savepoint</Method></Frame><Frame><File>/Users/kepioo/Documents/code/virtualenvs/myproject/lib/python2.6/site-packages/django/db/backends/__init__.py</File><Line>223</Line><Method>savepoint</Method></Frame><Frame><File>/Users/kepioo/Documents/code/virtualenvs/myproject/lib/python2.6/site-packages/django/db/backends/__init__.py</File><Line>70</Line><Method>_savepoint</Method></Frame><Frame><File>/Users/kepioo/Documents/code/virtualenvs/myproject/lib/python2.6/site-packages/django/db/backends/postgresql_psycopg2/base.py</File><Line>44</Line><Method>execute</Method></Frame></Stack></Post><Post><PostId>10813983</PostId><Url>http://stackoverflow.com/questions/10813983</Url><Stack><Type>DatabaseError</Type><Message>(1146, "Table 'thumbnail_kvstore' doesn't exist")</Message><Frame><File>/usr/lib/python2.6/site-packages/sorl_thumbnail-11.12-py2.6.egg/sorl/thumbnail/templatetags/thumbnail.py</File><Line>45</Line><Method>render</Method></Frame><Frame><File>/usr/lib/python2.6/site-packages/sorl_thumbnail-11.12-py2.6.egg/sorl/thumbnail/templatetags/thumbnail.py</File><Line>97</Line><Method>_render</Method></Frame><Frame><File>/usr/lib/python2.6/site-packages/sorl_thumbnail-11.12-py2.6.egg/sorl/thumbnail/base.py</File><Line>50</Line><Method>get_thumbnail</Method></Frame><Frame><File>/usr/lib/python2.6/site-packages/sorl_thumbnail-11.12-py2.6.egg/sorl/thumbnail/kvstores/base.py</File><Line>25</Line><Method>get</Method></Frame><Frame><File>/usr/lib/python2.6/site-packages/sorl_thumbnail-11.12-py2.6.egg/sorl/thumbnail/kvstores/base.py</File><Line>123</Line><Method>_get</Method></Frame><Frame><File>/usr/lib/python2.6/site-packages/sorl_thumbnail-11.12-py2.6.egg/sorl/thumbnail/kvstores/cached_db_kvstore.py</File><Line>26</Line><Method>_get_raw</Method></Frame><Frame><File>/usr/lib/python2.6/site-packages/django/db/models/manager.py</File><Line>132</Line><Method>get</Method></Frame><Frame><File>/usr/lib/python2.6/site-packages/django/db/models/query.py</File><Line>344</Line><Method>get</Method></Frame><Frame><File>/usr/lib/python2.6/site-packages/django/db/models/query.py</File><Line>82</Line><Method>__len__</Method></Frame><Frame><File>/usr/lib/python2.6/site-packages/django/db/models/query.py</File><Line>273</Line><Method>iterator</Method></Frame><Frame><File>/usr/lib/python2.6/site-packages/django/db/models/sql/compiler.py</File><Line>680</Line><Method>results_iter</Method></Frame><Frame><File>/usr/lib/python2.6/site-packages/django/db/models/sql/compiler.py</File><Line>735</Line><Method>execute_sql</Method></Frame><Frame><File>/usr/lib/python2.6/site-packages/django/db/backends/util.py</File><Line>34</Line><Method>execute</Method></Frame><Frame><File>/usr/lib/python2.6/site-packages/django/db/backends/mysql/base.py</File><Line>86</Line><Method>execute</Method></Frame><Frame><File>/usr/lib64/python2.6/site-packages/MySQLdb/cursors.py</File><Line>174</Line><Method>execute</Method></Frame><Frame><File>/usr/lib64/python2.6/site-packages/MySQLdb/connections.py</File><Line>36</Line><Method>defaulterrorhandler</Method></Frame></Stack></Post><Post><PostId>11214099</PostId><Url>http://stackoverflow.com/questions/11214099</Url><Stack><Type>DatabaseError</Type><Message>no such table: app_m</Message><Frame><File>/usr/lib/python2.6/threading.py</File><Line>532</Line><Method>__bootstrap_inner</Method></Frame><Frame><File>/usr/lib/python2.6/threading.py</File><Line>484</Line><Method>run</Method></Frame><Frame><File>/home/jacobsen/testdjango/app/tests.py</File><Line>10</Line><Method>insert</Method></Frame><Frame><File>/home/jacobsen/dj14/lib/python2.6/site-packages/Django-1.4-py2.6.egg/django/db/models/base.py</File><Line>463</Line><Method>save</Method></Frame><Frame><File>/home/jacobsen/dj14/lib/python2.6/site-packages/Django-1.4-py2.6.egg/django/db/models/base.py</File><Line>551</Line><Method>save_base</Method></Frame><Frame><File>/home/jacobsen/dj14/lib/python2.6/site-packages/Django-1.4-py2.6.egg/django/db/models/manager.py</File><Line>203</Line><Method>_insert</Method></Frame><Frame><File>/home/jacobsen/dj14/lib/python2.6/site-packages/Django-1.4-py2.6.egg/django/db/models/query.py</File><Line>1576</Line><Method>insert_query</Method></Frame><Frame><File>/home/jacobsen/dj14/lib/python2.6/site-packages/Django-1.4-py2.6.egg/django/db/models/sql/compiler.py</File><Line>910</Line><Method>execute_sql</Method></Frame><Frame><File>/home/jacobsen/dj14/lib/python2.6/site-packages/Django-1.4-py2.6.egg/django/db/backends/sqlite3/base.py</File><Line>337</Line><Method>execute</Method></Frame></Stack></Post><Post><PostId>12841734</PostId><Url>http://stackoverflow.com/questions/12841734</Url><Stack><Type>DatabaseError</Type><Message>file is encrypted or is not a database</Message><Frame><File>C:\Users\Nat\Desktop\MessageExtract.py</File><Line>12</Line><Method>module</Method></Frame></Stack></Post><Post><PostId>13979029</PostId><Url>http://stackoverflow.com/questions/13979029</Url><Stack><Type>DatabaseError</Type><Message>Could not load myapp2.table2(pk=1): relation "myapp2_table2" does not exist</Message><Frame><File>... project folder .../venv/lib/python2.7/site-packages/django/core/management/commands/loaddata.py</File><Line>196</Line><Method>handle</Method></Frame><Frame><File>... project folder .../venv/lib/python2.7/site-packages/django/core/serializers/base.py</File><Line>165</Line><Method>save</Method></Frame><Frame><File>... project folder .../venv/lib/python2.7/site-packages/django/db/models/base.py</File><Line>524</Line><Method>save_base</Method></Frame><Frame><File>... project folder .../venv/lib/python2.7/site-packages/django/db/models/query.py</File><Line>565</Line><Method>exists</Method></Frame><Frame><File>... project folder .../venv/lib/python2.7/site-packages/django/db/models/sql/query.py</File><Line>441</Line><Method>has_results</Method></Frame><Frame><File>... project folder .../venv/lib/python2.7/site-packages/django/db/models/sql/compiler.py</File><Line>818</Line><Method>execute_sql</Method></Frame><Frame><File>... project folder .../venv/lib/python2.7/site-packages/django/db/backends/postgresql_psycopg2/base.py</File><Line>52</Line><Method>execute</Method></Frame></Stack></Post><Post><PostId>15797894</PostId><Url>http://stackoverflow.com/questions/15797894</Url><Stack><Type>DatabaseError</Type><Message>ORA-01460: unimplemented or unreasonable conversion requested</Message><Frame><File>C:/Program Files/App_Logic/..\apps\views.py</File><Line>400</Line><Method>regularize_TAG</Method></Frame></Stack></Post><Post><PostId>16044754</PostId><Url>http://stackoverflow.com/questions/16044754</Url><Stack><Type>DatabaseError</Type><Message>operator does not exist: integer = text LINE 1: ... INNER JOIN "django_comments" ON ("pi ns_pin"."id" = "django_...</Message><Frame><File>/app/.heroku/src/django-tastypie/tastypie/resources.py</File><Line>202</Line><Method>wrapper</Method></Frame><Frame><File>/app/.heroku/src/django-tastypie/tastypie/resources.py</File><Line>441</Line><Method>dispatch_list</Method></Frame><Frame><File>/app/.heroku/src/django-tastypie/tastypie/resources.py</File><Line>473</Line><Method>dispatch</Method></Frame><Frame><File>/app/.heroku/src/django-tastypie/tastypie/resources.py</File><Line>1244</Line><Method>get_list</Method></Frame><Frame><File>/app/.heroku/src/django-tastypie/tastypie/paginator.py</File><Line>186</Line><Method>page</Method></Frame><Frame><File>/app/.heroku/src/django-tastypie/tastypie/paginator.py</File><Line>118</Line><Method>get_count</Method></Frame><Frame><File>/app/.heroku/python/lib/python2.7/site-packages/django/db/models/query.py</File><Line>351</Line><Method>count</Method></Frame><Frame><File>/app/.heroku/python/lib/python2.7/site-packages/django/db/models/sql/query.py</File><Line>418</Line><Method>get_count</Method></Frame><Frame><File>/app/.heroku/python/lib/python2.7/site-packages/django/db/models/sql/query.py</File><Line>384</Line><Method>get_aggregation</Method></Frame><Frame><File>/app/.heroku/python/lib/python2.7/site-packages/django/db/models/sql/compiler.py</File><Line>818</Line><Method>execute_sql</Method></Frame><Frame><File>/app/.heroku/python/lib/python2.7/site-packages/django/db/backends/postgresql_psycopg2/base.py</File><Line>52</Line><Method>execute</Method></Frame></Stack></Post><Post><PostId>16392288</PostId><Url>http://stackoverflow.com/questions/16392288</Url><Stack><Type>DatabaseError</Type><Message>ORA-01036: illegal variable name/number</Message><Frame><File>D:\work\venkat\QGIS\Tools\GlobalErrorMarker\globalerrormarker.py</File><Line>272</Line><Method>btnDownloadError_Clicked</Method></Frame></Stack></Post><Post><PostId>16650585</PostId><Url>http://stackoverflow.com/questions/16650585</Url><Stack><Type>DatabaseError</Type><Message>database is locked</Message><Frame><File>/opt/cloudera/parcels/CDH-4.2.1-1.cdh4.2.1.p0.5/share/hue/build/env/lib/python2.6/site-packages/eventlet-0.9.14-py2.6.egg/eventlet/wsgi.py</File><Line>336</Line><Method>handle_one_response</Method></Frame><Frame><File>/opt/cloudera/parcels/CDH-4.2.1-1.cdh4.2.1.p0.5/share/hue/build/env/lib/python2.6/site-packages/Django-1.2.3-py2.6.egg/django/core/handlers/wsgi.py</File><Line>245</Line><Method>__call__</Method></Frame><Frame><File>/opt/cloudera/parcels/CDH-4.2.1-1.cdh4.2.1.p0.5/share/hue/build/env/lib/python2.6/site-packages/Django-1.2.3-py2.6.egg/django/contrib/sessions/middleware.py</File><Line>36</Line><Method>process_response</Method></Frame><Frame><File>/opt/cloudera/parcels/CDH-4.2.1-1.cdh4.2.1.p0.5/share/hue/build/env/lib/python2.6/site-packages/Django-1.2.3-py2.6.egg/django/contrib/sessions/backends/db.py</File><Line>63</Line><Method>save</Method></Frame><Frame><File>/opt/cloudera/parcels/CDH-4.2.1-1.cdh4.2.1.p0.5/share/hue/build/env/lib/python2.6/site-packages/Django-1.2.3-py2.6.egg/django/db/models/base.py</File><Line>434</Line><Method>save</Method></Frame><Frame><File>/opt/cloudera/parcels/CDH-4.2.1-1.cdh4.2.1.p0.5/share/hue/build/env/lib/python2.6/site-packages/Django-1.2.3-py2.6.egg/django/db/models/base.py</File><Line>500</Line><Method>save_base</Method></Frame><Frame><File>/opt/cloudera/parcels/CDH-4.2.1-1.cdh4.2.1.p0.5/share/hue/build/env/lib/python2.6/site-packages/Django-1.2.3-py2.6.egg/django/db/models/query.py</File><Line>491</Line><Method>_update</Method></Frame><Frame><File>/opt/cloudera/parcels/CDH-4.2.1-1.cdh4.2.1.p0.5/share/hue/build/env/lib/python2.6/site-packages/Django-1.2.3-py2.6.egg/django/db/models/sql/compiler.py</File><Line>861</Line><Method>execute_sql</Method></Frame><Frame><File>/opt/cloudera/parcels/CDH-4.2.1-1.cdh4.2.1.p0.5/share/hue/build/env/lib/python2.6/site-packages/Django-1.2.3-py2.6.egg/django/db/models/sql/compiler.py</File><Line>727</Line><Method>execute_sql</Method></Frame><Frame><File>/opt/cloudera/parcels/CDH-4.2.1-1.cdh4.2.1.p0.5/share/hue/build/env/lib/python2.6/site-packages/Django-1.2.3-py2.6.egg/django/db/backends/sqlite3/base.py</File><Line>200</Line><Method>execute</Method></Frame></Stack></Post><Post><PostId>16716200</PostId><Url>http://stackoverflow.com/questions/16716200</Url><Stack><Type>DatabaseError</Type><Message>no such table: orders_orderline</Message><Frame><File>/var/www/phaethon/virtualenvs/my_random_website/lib/python2.6/site-packages/django/core/handlers/base.py</File><Line>111</Line><Method>get_response</Method></Frame><Frame><File>/var/www/phaethon/virtualenvs/my_random_website/lib/python2.6/site-packages/django/contrib/admin/options.py</File><Line>366</Line><Method>wrapper</Method></Frame><Frame><File>/var/www/phaethon/virtualenvs/my_random_website/lib/python2.6/site-packages/django/utils/decorators.py</File><Line>91</Line><Method>_wrapped_view</Method></Frame><Frame><File>/var/www/phaethon/virtualenvs/my_random_website/lib/python2.6/site-packages/django/views/decorators/cache.py</File><Line>89</Line><Method>_wrapped_view_func</Method></Frame><Frame><File>/var/www/phaethon/virtualenvs/my_random_website/lib/python2.6/site-packages/django/contrib/admin/sites.py</File><Line>196</Line><Method>inner</Method></Frame><Frame><File>/var/www/phaethon/virtualenvs/my_random_website/lib/python2.6/site-packages/django/utils/decorators.py</File><Line>25</Line><Method>_wrapper</Method></Frame><Frame><File>/var/www/phaethon/virtualenvs/my_random_website/lib/python2.6/site-packages/django/utils/decorators.py</File><Line>91</Line><Method>_wrapped_view</Method></Frame><Frame><File>/var/www/phaethon/virtualenvs/my_random_website/lib/python2.6/site-packages/django/utils/decorators.py</File><Line>21</Line><Method>bound_func</Method></Frame><Frame><File>/var/www/phaethon/virtualenvs/my_random_website/lib/python2.6/site-packages/django/db/transaction.py</File><Line>224</Line><Method>inner</Method></Frame><Frame><File>/var/www/phaethon/virtualenvs/my_random_website/lib/python2.6/site-packages/django/contrib/admin/options.py</File><Line>1274</Line><Method>delete_view</Method></Frame><Frame><File>/var/www/phaethon/virtualenvs/my_random_website/lib/python2.6/site-packages/django/contrib/admin/util.py</File><Line>104</Line><Method>get_deleted_objects</Method></Frame><Frame><File>/var/www/phaethon/virtualenvs/my_random_website/lib/python2.6/site-packages/django/contrib/admin/util.py</File><Line>155</Line><Method>collect</Method></Frame><Frame><File>/var/www/phaethon/virtualenvs/my_random_website/lib/python2.6/site-packages/django/db/models/deletion.py</File><Line>175</Line><Method>collect</Method></Frame><Frame><File>/var/www/phaethon/virtualenvs/my_random_website/lib/python2.6/site-packages/django/db/models/query.py</File><Line>130</Line><Method>__nonzero__</Method></Frame><Frame><File>/var/www/phaethon/virtualenvs/my_random_website/lib/python2.6/site-packages/django/db/models/query.py</File><Line>118</Line><Method>_result_iter</Method></Frame><Frame><File>/var/www/phaethon/virtualenvs/my_random_website/lib/python2.6/site-packages/django/db/models/query.py</File><Line>892</Line><Method>_fill_cache</Method></Frame><Frame><File>/var/www/phaethon/virtualenvs/my_random_website/lib/python2.6/site-packages/django/db/models/query.py</File><Line>291</Line><Method>iterator</Method></Frame><Frame><File>/var/www/phaethon/virtualenvs/my_random_website/lib/python2.6/site-packages/django/db/models/sql/compiler.py</File><Line>763</Line><Method>results_iter</Method></Frame><Frame><File>/var/www/phaethon/virtualenvs/my_random_website/lib/python2.6/site-packages/django/db/models/sql/compiler.py</File><Line>818</Line><Method>execute_sql</Method></Frame><Frame><File>/var/www/phaethon/virtualenvs/my_random_website/lib/python2.6/site-packages/django/db/backends/sqlite3/base.py</File><Line>344</Line><Method>execute</Method></Frame></Stack></Post><Post><PostId>18601604</PostId><Url>http://stackoverflow.com/questions/18601604</Url><Stack><Type>DatabaseError</Type><Message>column "person_id" specified more than once</Message><Frame><File>/usr/lib/python2.7/site-packages/django/core/management/base.py</File><Line>222</Line><Method>run_from_argv</Method></Frame><Frame><File>/usr/lib/python2.7/site-packages/django/core/management/commands/test.py</File><Line>72</Line><Method>execute</Method></Frame><Frame><File>/usr/lib/python2.7/site-packages/django/core/management/base.py</File><Line>255</Line><Method>execute</Method></Frame><Frame><File>/usr/lib/python2.7/site-packages/django/core/management/commands/test.py</File><Line>89</Line><Method>handle</Method></Frame><Frame><File>/usr/lib/python2.7/site-packages/django/test/simple.py</File><Line>367</Line><Method>run_tests</Method></Frame><Frame><File>/usr/lib/python2.7/site-packages/django/test/simple.py</File><Line>315</Line><Method>setup_databases</Method></Frame><Frame><File>/usr/lib/python2.7/site-packages/django/db/backends/creation.py</File><Line>293</Line><Method>create_test_db</Method></Frame><Frame><File>/usr/lib/python2.7/site-packages/django/core/management/__init__.py</File><Line>161</Line><Method>call_command</Method></Frame><Frame><File>/usr/lib/python2.7/site-packages/django/core/management/base.py</File><Line>255</Line><Method>execute</Method></Frame><Frame><File>/usr/lib/python2.7/site-packages/django/core/management/base.py</File><Line>385</Line><Method>handle</Method></Frame><Frame><File>/usr/lib/python2.7/site-packages/django/core/management/commands/syncdb.py</File><Line>102</Line><Method>handle_noargs</Method></Frame><Frame><File>/usr/lib/python2.7/site-packages/django/db/backends/postgresql_psycopg2/base.py</File><Line>58</Line><Method>execute</Method></Frame><Frame><File>/usr/lib/python2.7/site-packages/django/db/backends/postgresql_psycopg2/base.py</File><Line>54</Line><Method>execute</Method></Frame></Stack></Post><Post><PostId>18876652</PostId><Url>http://stackoverflow.com/questions/18876652</Url><Stack><Type>DatabaseError</Type><Message>OTHER({'info': 'index generation failed', 'desc': 'Internal (implementation specific) error'},)</Message><Frame><File>/export/home/somedir/lib/somedir/db/ldapcmd.py</File><Line>308</Line><Method>add</Method></Frame><Frame><File>/usr/local/lib/python2.7/site-packages/python_ldap-2.3.9-py2.7-linux-x86_64.egg/ldap/ldapobject.py</File><Line>186</Line><Method>add_s</Method></Frame><Frame><File>/usr/local/lib/python2.7/site-packages/python_ldap-2.3.9-py2.7-linux-x86_64.egg/ldap/ldapobject.py</File><Line>428</Line><Method>result</Method></Frame><Frame><File>/usr/local/lib/python2.7/site-packages/python_ldap-2.3.9-py2.7-linux-x86_64.egg/ldap/ldapobject.py</File><Line>432</Line><Method>result2</Method></Frame><Frame><File>/usr/local/lib/python2.7/site-packages/python_ldap-2.3.9-py2.7-linux-x86_64.egg/ldap/ldapobject.py</File><Line>438</Line><Method>result3</Method></Frame><Frame><File>/usr/local/lib/python2.7/site-packages/python_ldap-2.3.9-py2.7-linux-x86_64.egg/ldap/ldapobject.py</File><Line>96</Line><Method>_ldap_call</Method></Frame><Frame><File>../bin/somescript</File><Line>707</Line><Method>module</Method></Frame><Frame><File>/export/home/somedir/lib/somedir/db/ldapcmd.py</File><Line>313</Line><Method>add</Method></Frame></Stack></Post><Post><PostId>18876652</PostId><Url>http://stackoverflow.com/questions/18876652</Url><Stack><Type>DatabaseError</Type><Message>OTHER({'info': 'index generation failed', 'desc': 'Internal (implementation specific) error'},)</Message><Frame><File>/export/home/somedir/lib/somedir/db/ldapcmd.py</File><Line>308</Line><Method>add</Method></Frame><Frame><File>/usr/local/lib/python2.7/site-packages/python_ldap-2.3.9-py2.7-linux-x86_64.egg/ldap/ldapobject.py</File><Line>186</Line><Method>add_s</Method></Frame><Frame><File>/usr/local/lib/python2.7/site-packages/python_ldap-2.3.9-py2.7-linux-x86_64.egg/ldap/ldapobject.py</File><Line>428</Line><Method>result</Method></Frame><Frame><File>/usr/local/lib/python2.7/site-packages/python_ldap-2.3.9-py2.7-linux-x86_64.egg/ldap/ldapobject.py</File><Line>432</Line><Method>result2</Method></Frame><Frame><File>/usr/local/lib/python2.7/site-packages/python_ldap-2.3.9-py2.7-linux-x86_64.egg/ldap/ldapobject.py</File><Line>438</Line><Method>result3</Method></Frame><Frame><File>/usr/local/lib/python2.7/site-packages/python_ldap-2.3.9-py2.7-linux-x86_64.egg/ldap/ldapobject.py</File><Line>96</Line><Method>_ldap_call</Method></Frame><Frame><File>../bin/somescript</File><Line>707</Line><Method>module</Method></Frame><Frame><File>/export/home/somedir/lib/somedir/db/ldapcmd.py</File><Line>313</Line><Method>add</Method></Frame></Stack></Post><Post><PostId>19222373</PostId><Url>http://stackoverflow.com/questions/19222373</Url><Stack><Type>DatabaseError</Type><Message>Could not load contenttypes.ContentType(pk=29): permission denied for relation django_content_type</Message><Frame><File>/home/vagrant/devenv/local/lib/python2.7/site-packages/django/core/management/commands/loaddata.py</File><Line>196</Line><Method>handle</Method></Frame><Frame><File>/home/vagrant/devenv/local/lib/python2.7/site-packages/django/core/serializers/base.py</File><Line>165</Line><Method>save</Method></Frame><Frame><File>/home/vagrant/devenv/local/lib/python2.7/site-packages/django/db/models/base.py</File><Line>524</Line><Method>save_base</Method></Frame><Frame><File>/home/vagrant/devenv/local/lib/python2.7/site-packages/django/db/models/query.py</File><Line>565</Line><Method>exists</Method></Frame><Frame><File>/home/vagrant/devenv/local/lib/python2.7/site-packages/django/db/models/sql/query.py</File><Line>441</Line><Method>has_results</Method></Frame><Frame><File>/home/vagrant/devenv/local/lib/python2.7/site-packages/django/db/models/sql/compiler.py</File><Line>818</Line><Method>execute_sql</Method></Frame><Frame><File>/home/vagrant/devenv/local/lib/python2.7/site-packages/django/db/backends/util.py</File><Line>40</Line><Method>execute</Method></Frame><Frame><File>/home/vagrant/devenv/local/lib/python2.7/site-packages/django/db/backends/postgresql_psycopg2/base.py</File><Line>52</Line><Method>execute</Method></Frame></Stack></Post><Post><PostId>19276830</PostId><Url>http://stackoverflow.com/questions/19276830</Url><Stack><Type>DatabaseError</Type><Message>no such table: accounts_siuser</Message><Frame><File>/Users/chaz/dev/projects/si/apps/accounts/tests/test_admin.py</File><Line>17</Line><Method>setUp</Method></Frame><Frame><File>/Users/chaz/dev/envs/startupinst/lib/python2.7/site-packages/factory/base.py</File><Line>452</Line><Method>create</Method></Frame><Frame><File>/Users/chaz/dev/envs/startupinst/lib/python2.7/site-packages/factory/base.py</File><Line>316</Line><Method>attributes</Method></Frame><Frame><File>/Users/chaz/dev/envs/startupinst/lib/python2.7/site-packages/factory/containers.py</File><Line>263</Line><Method>build</Method></Frame><Frame><File>/Users/chaz/dev/envs/startupinst/lib/python2.7/site-packages/factory/base.py</File><Line>287</Line><Method>_generate_next_sequence</Method></Frame><Frame><File>/Users/chaz/dev/envs/startupinst/lib/python2.7/site-packages/factory/django.py</File><Line>71</Line><Method>_setup_next_sequence</Method></Frame><Frame><File>/Users/chaz/dev/envs/startupinst/lib/python2.7/site-packages/django/db/models/query.py</File><Line>231</Line><Method>__getitem__</Method></Frame><Frame><File>/Users/chaz/dev/envs/startupinst/lib/python2.7/site-packages/django/db/models/query.py</File><Line>108</Line><Method>__len__</Method></Frame><Frame><File>/Users/chaz/dev/envs/startupinst/lib/python2.7/site-packages/django/db/models/query.py</File><Line>1140</Line><Method>iterator</Method></Frame><Frame><File>/Users/chaz/dev/envs/startupinst/lib/python2.7/site-packages/django/db/models/sql/compiler.py</File><Line>775</Line><Method>results_iter</Method></Frame><Frame><File>/Users/chaz/dev/envs/startupinst/lib/python2.7/site-packages/django/db/models/sql/compiler.py</File><Line>840</Line><Method>execute_sql</Method></Frame><Frame><File>/Users/chaz/dev/envs/startupinst/lib/python2.7/site-packages/django/db/backends/sqlite3/base.py</File><Line>366</Line><Method>execute</Method></Frame><Frame><File>/Users/chaz/dev/envs/startupinst/lib/python2.7/site-packages/django/db/backends/sqlite3/base.py</File><Line>362</Line><Method>execute</Method></Frame></Stack></Post><Post><PostId>19580364</PostId><Url>http://stackoverflow.com/questions/19580364</Url><Stack><Type>DatabaseError</Type><Message>(1054, "Unknown column 'polls_poll.question' in 'field list'")</Message><Frame><File>/Users/MyClean/anaconda/lib/python2.7/site-packages/django/core/handlers/base.py</File><Line>115</Line><Method>get_response</Method></Frame><Frame><File>/Users/MyClean/anaconda/lib/python2.7/site-packages/django/contrib/admin/options.py</File><Line>372</Line><Method>wrapper</Method></Frame><Frame><File>/Users/MyClean/anaconda/lib/python2.7/site-packages/django/utils/decorators.py</File><Line>91</Line><Method>_wrapped_view</Method></Frame><Frame><File>/Users/MyClean/anaconda/lib/python2.7/site-packages/django/views/decorators/cache.py</File><Line>89</Line><Method>_wrapped_view_func</Method></Frame><Frame><File>/Users/MyClean/anaconda/lib/python2.7/site-packages/django/contrib/admin/sites.py</File><Line>202</Line><Method>inner</Method></Frame><Frame><File>/Users/MyClean/anaconda/lib/python2.7/site-packages/django/utils/decorators.py</File><Line>25</Line><Method>_wrapper</Method></Frame><Frame><File>/Users/MyClean/anaconda/lib/python2.7/site-packages/django/utils/decorators.py</File><Line>91</Line><Method>_wrapped_view</Method></Frame><Frame><File>/Users/MyClean/anaconda/lib/python2.7/site-packages/django/utils/decorators.py</File><Line>21</Line><Method>bound_func</Method></Frame><Frame><File>/Users/MyClean/anaconda/lib/python2.7/site-packages/django/contrib/admin/options.py</File><Line>1285</Line><Method>changelist_view</Method></Frame><Frame><File>/Users/MyClean/anaconda/lib/python2.7/site-packages/django/db/models/query.py</File><Line>106</Line><Method>__len__</Method></Frame><Frame><File>/Users/MyClean/anaconda/lib/python2.7/site-packages/django/db/models/query.py</File><Line>317</Line><Method>iterator</Method></Frame><Frame><File>/Users/MyClean/anaconda/lib/python2.7/site-packages/django/db/models/sql/compiler.py</File><Line>775</Line><Method>results_iter</Method></Frame><Frame><File>/Users/MyClean/anaconda/lib/python2.7/site-packages/django/db/models/sql/compiler.py</File><Line>840</Line><Method>execute_sql</Method></Frame><Frame><File>/Users/MyClean/anaconda/lib/python2.7/site-packages/django/db/backends/util.py</File><Line>41</Line><Method>execute</Method></Frame><Frame><File>/Users/MyClean/anaconda/lib/python2.7/site-packages/django/db/backends/mysql/base.py</File><Line>128</Line><Method>execute</Method></Frame><Frame><File>/Users/MyClean/anaconda/lib/python2.7/site-packages/django/db/backends/mysql/base.py</File><Line>120</Line><Method>execute</Method></Frame><Frame><File>/Users/MyClean/anaconda/lib/python2.7/site-packages/MySQLdb/cursors.py</File><Line>201</Line><Method>execute</Method></Frame><Frame><File>/Users/MyClean/anaconda/lib/python2.7/site-packages/MySQLdb/connections.py</File><Line>36</Line><Method>defaulterrorhandler</Method></Frame></Stack></Post><Post><PostId>19958587</PostId><Url>http://stackoverflow.com/questions/19958587</Url><Stack><Type>DatabaseError</Type><Message>no such table: core_industry</Message><Frame><File>/home/igniteflow/Projects/foo/src/lib/nose/loader.py</File><Line>413</Line><Method>loadTestsFromName</Method></Frame><Frame><File>/home/igniteflow/Projects/foo/src/lib/nose/importer.py</File><Line>47</Line><Method>importFromPath</Method></Frame><Frame><File>/home/igniteflow/Projects/foo/src/lib/nose/importer.py</File><Line>94</Line><Method>importFromDir</Method></Frame><Frame><File>/home/igniteflow/Projects/foo/src/app/cms/tests/__init__.py</File><Line>5</Line><Method>module</Method></Frame><Frame><File>/home/igniteflow/Projects/foo/src/app/cms/tests/bulk_export.py</File><Line>8</Line><Method>module</Method></Frame><Frame><File>/home/igniteflow/Projects/foo/src/app/cms/input_parsers.py</File><Line>10</Line><Method>module</Method></Frame><Frame><File>/home/igniteflow/Projects/foo/src/app/cms/bulkimport.py</File><Line>683</Line><Method>module</Method></Frame><Frame><File>/home/igniteflow/Projects/foo/src/app/cms/bulkimport.py</File><Line>709</Line><Method>BaseContentBulkUploadForm</Method></Frame><Frame><File>/home/igniteflow/Projects/foo/src/app/cms/bulkimport.py</File><Line>674</Line><Method>m2m_column_help_text</Method></Frame><Frame><File>/home/igniteflow/Projects/foo/src/lib/django/db/models/query.py</File><Line>123</Line><Method>_result_iter</Method></Frame><Frame><File>/home/igniteflow/Projects/foo/src/lib/django/db/models/query.py</File><Line>927</Line><Method>_fill_cache</Method></Frame><Frame><File>/home/igniteflow/Projects/foo/src/lib/django/db/models/query.py</File><Line>1129</Line><Method>iterator</Method></Frame><Frame><File>/home/igniteflow/Projects/foo/src/lib/django/db/models/sql/compiler.py</File><Line>775</Line><Method>results_iter</Method></Frame><Frame><File>/home/igniteflow/Projects/foo/src/lib/django/db/models/sql/compiler.py</File><Line>840</Line><Method>execute_sql</Method></Frame><Frame><File>/home/igniteflow/Projects/foo/src/lib/django/db/backends/util.py</File><Line>41</Line><Method>execute</Method></Frame><Frame><File>/home/igniteflow/Projects/foo/src/lib/django/db/backends/sqlite3/base.py</File><Line>366</Line><Method>execute</Method></Frame><Frame><File>/home/igniteflow/Projects/foo/src/lib/django/db/backends/sqlite3/base.py</File><Line>362</Line><Method>execute</Method></Frame></Stack></Post><Post><PostId>19970809</PostId><Url>http://stackoverflow.com/questions/19970809</Url><Stack><Type>DatabaseError</Type><Message>(DatabaseError) ORA-01036: illegal variable name/number</Message><Frame><File>pyshell#4</File><Line>1</Line><Method>module</Method></Frame><Frame><File>build\bdist.win32\egg\sqlalchemy\orm\query.py</File><Line>2275</Line><Method>first</Method></Frame><Frame><File>build\bdist.win32\egg\sqlalchemy\orm\query.py</File><Line>2142</Line><Method>__getitem__</Method></Frame><Frame><File>build\bdist.win32\egg\sqlalchemy\orm\query.py</File><Line>2346</Line><Method>__iter__</Method></Frame><Frame><File>build\bdist.win32\egg\sqlalchemy\orm\query.py</File><Line>2361</Line><Method>_execute_and_instances</Method></Frame><Frame><File>build\bdist.win32\egg\sqlalchemy\engine\base.py</File><Line>664</Line><Method>execute</Method></Frame><Frame><File>build\bdist.win32\egg\sqlalchemy\sql\elements.py</File><Line>272</Line><Method>_execute_on_connection</Method></Frame><Frame><File>build\bdist.win32\egg\sqlalchemy\engine\base.py</File><Line>761</Line><Method>_execute_clauseelement</Method></Frame><Frame><File>build\bdist.win32\egg\sqlalchemy\engine\base.py</File><Line>874</Line><Method>_execute_context</Method></Frame><Frame><File>build\bdist.win32\egg\sqlalchemy\engine\base.py</File><Line>1023</Line><Method>_handle_dbapi_exception</Method></Frame><Frame><File>build\bdist.win32\egg\sqlalchemy\util\compat.py</File><Line>185</Line><Method>raise_from_cause</Method></Frame><Frame><File>build\bdist.win32\egg\sqlalchemy\engine\base.py</File><Line>867</Line><Method>_execute_context</Method></Frame><Frame><File>build\bdist.win32\egg\sqlalchemy\engine\default.py</File><Line>376</Line><Method>do_execute</Method></Frame></Stack></Post><Post><PostId>20865881</PostId><Url>http://stackoverflow.com/questions/20865881</Url><Stack><Type>DatabaseError</Type><Message>Ordering can't span tables on non-relational backends (content_type__app_label).</Message><Frame><File>/home/madmin/workspace/milkyway/apiserver/startup.py</File><Line>57</Line><Method>startup</Method></Frame><Frame><File>/usr/local/lib/python2.7/dist-packages/django/core/management/__init__.py</File><Line>161</Line><Method>call_command</Method></Frame><Frame><File>/usr/local/lib/python2.7/dist-packages/django/core/management/base.py</File><Line>255</Line><Method>execute</Method></Frame><Frame><File>/usr/local/lib/python2.7/dist-packages/django/core/management/base.py</File><Line>385</Line><Method>handle</Method></Frame><Frame><File>/usr/local/lib/python2.7/dist-packages/django/core/management/commands/syncdb.py</File><Line>109</Line><Method>handle_noargs</Method></Frame><Frame><File>/usr/local/lib/python2.7/dist-packages/django/core/management/sql.py</File><Line>195</Line><Method>emit_post_sync_signal</Method></Frame><Frame><File>/usr/local/lib/python2.7/dist-packages/django/dispatch/dispatcher.py</File><Line>170</Line><Method>send</Method></Frame><Frame><File>/usr/local/lib/python2.7/dist-packages/django/contrib/auth/management/__init__.py</File><Line>88</Line><Method>create_permissions</Method></Frame><Frame><File>/usr/local/lib/python2.7/dist-packages/django/db/models/query.py</File><Line>139</Line><Method>_result_iter</Method></Frame><Frame><File>/usr/local/lib/python2.7/dist-packages/django/db/models/query.py</File><Line>941</Line><Method>_fill_cache</Method></Frame><Frame><File>/usr/local/lib/python2.7/dist-packages/django/db/models/query.py</File><Line>1143</Line><Method>iterator</Method></Frame><Frame><File>/usr/local/lib/python2.7/dist-packages/djangotoolbox/db/basecompiler.py</File><Line>375</Line><Method>results_iter</Method></Frame><Frame><File>/usr/local/lib/python2.7/dist-packages/djangotoolbox/db/basecompiler.py</File><Line>482</Line><Method>build_query</Method></Frame><Frame><File>/usr/local/lib/python2.7/dist-packages/djangotoolbox/db/basecompiler.py</File><Line>543</Line><Method>_get_ordering</Method></Frame></Stack></Post><Post><PostId>21839106</PostId><Url>http://stackoverflow.com/questions/21839106</Url><Stack><Type>DatabaseError</Type><Message>(1366, "Incorrect string value: '\\xE2\\x9C\\x93 \\xE2\\x9C...' for column 'description' at row 1")</Message><Frame><File>/Users/admin/Developer/project/pro/blogs/tests.py</File><Line>64</Line><Method>test_post_blog</Method></Frame><Frame><File>build/bdist.macosx-10.9-intel/egg/MySQLdb/cursors.py</File><Line>201</Line><Method>execute</Method></Frame><Frame><File>build/bdist.macosx-10.9-intel/egg/MySQLdb/connections.py</File><Line>36</Line><Method>defaulterrorhandler</Method></Frame></Stack></Post><Post><PostId>23558082</PostId><Url>http://stackoverflow.com/questions/23558082</Url><Stack><Type>DatabaseError</Type><Message>(1146, "Table 'nddweb.auth_user' doesn't exist")</Message><Frame><File>/Applications/GoogleAppEngineLauncher.app/Contents/Resources/GoogleAppEngine-default.bundle/Contents/Resources/google_appengine/lib/django-1.5/django/core/handlers/base.py</File><Line>115</Line><Method>get_response</Method></Frame><Frame><File>/Users/nextdoordoctor/git/NDDWeb/NDDWeb/src/welcome/views.py</File><Line>19</Line><Method>index</Method></Frame><Frame><File>/Applications/GoogleAppEngineLauncher.app/Contents/Resources/GoogleAppEngine-default.bundle/Contents/Resources/google_appengine/lib/django-1.5/django/contrib/auth/__init__.py</File><Line>60</Line><Method>authenticate</Method></Frame><Frame><File>/Applications/GoogleAppEngineLauncher.app/Contents/Resources/GoogleAppEngine-default.bundle/Contents/Resources/google_appengine/lib/django-1.5/django/contrib/auth/backends.py</File><Line>16</Line><Method>authenticate</Method></Frame><Frame><File>/Applications/GoogleAppEngineLauncher.app/Contents/Resources/GoogleAppEngine-default.bundle/Contents/Resources/google_appengine/lib/django-1.5/django/contrib/auth/models.py</File><Line>168</Line><Method>get_by_natural_key</Method></Frame><Frame><File>/Applications/GoogleAppEngineLauncher.app/Contents/Resources/GoogleAppEngine-default.bundle/Contents/Resources/google_appengine/lib/django-1.5/django/db/models/manager.py</File><Line>143</Line><Method>get</Method></Frame><Frame><File>/Applications/GoogleAppEngineLauncher.app/Contents/Resources/GoogleAppEngine-default.bundle/Contents/Resources/google_appengine/lib/django-1.5/django/db/models/query.py</File><Line>398</Line><Method>get</Method></Frame><Frame><File>/Applications/GoogleAppEngineLauncher.app/Contents/Resources/GoogleAppEngine-default.bundle/Contents/Resources/google_appengine/lib/django-1.5/django/db/models/query.py</File><Line>106</Line><Method>__len__</Method></Frame><Frame><File>/Applications/GoogleAppEngineLauncher.app/Contents/Resources/GoogleAppEngine-default.bundle/Contents/Resources/google_appengine/lib/django-1.5/django/db/models/query.py</File><Line>317</Line><Method>iterator</Method></Frame><Frame><File>/Applications/GoogleAppEngineLauncher.app/Contents/Resources/GoogleAppEngine-default.bundle/Contents/Resources/google_appengine/lib/django-1.5/django/db/models/sql/compiler.py</File><Line>775</Line><Method>results_iter</Method></Frame><Frame><File>/Applications/GoogleAppEngineLauncher.app/Contents/Resources/GoogleAppEngine-default.bundle/Contents/Resources/google_appengine/lib/django-1.5/django/db/models/sql/compiler.py</File><Line>840</Line><Method>execute_sql</Method></Frame><Frame><File>/Applications/GoogleAppEngineLauncher.app/Contents/Resources/GoogleAppEngine-default.bundle/Contents/Resources/google_appengine/lib/django-1.5/django/db/backends/util.py</File><Line>41</Line><Method>execute</Method></Frame><Frame><File>/Applications/GoogleAppEngineLauncher.app/Contents/Resources/GoogleAppEngine-default.bundle/Contents/Resources/google_appengine/lib/django-1.5/django/db/backends/mysql/base.py</File><Line>130</Line><Method>execute</Method></Frame><Frame><File>/Applications/GoogleAppEngineLauncher.app/Contents/Resources/GoogleAppEngine-default.bundle/Contents/Resources/google_appengine/lib/django-1.5/django/db/backends/mysql/base.py</File><Line>120</Line><Method>execute</Method></Frame><Frame><File>/Library/Frameworks/Python.framework/Versions/2.7/lib/python2.7/site-packages/MySQL_python-1.2.4b4-py2.7-macosx-10.6-intel.egg/MySQLdb/cursors.py</File><Line>202</Line><Method>execute</Method></Frame><Frame><File>/Library/Frameworks/Python.framework/Versions/2.7/lib/python2.7/site-packages/MySQL_python-1.2.4b4-py2.7-macosx-10.6-intel.egg/MySQLdb/connections.py</File><Line>36</Line><Method>defaulterrorhandler</Method></Frame></Stack></Post><Post><PostId>23598384</PostId><Url>http://stackoverflow.com/questions/23598384</Url><Stack><Type>DatabaseError</Type><Message>could not load library "/usr/lib/postgresql/9.3/lib/postgis-2.1.so": /usr/lib/liblwgeom-2.1.2.so: undefined symbol: GEOSDelaunayTriangulation</Message><Frame><File>/home/bug/virtualenvs/menuchefs/local/lib/python2.7/site-packages/django/core/handlers/base.py</File><Line>115</Line><Method>get_response</Method></Frame><Frame><File>/home/bug/projects/menuchef/menuchef/core/views.py</File><Line>985</Line><Method>get_menus_categorized</Method></Frame><Frame><File>/home/bug/virtualenvs/menuchefs/local/lib/python2.7/site-packages/django/db/models/fields/related.py</File><Line>384</Line><Method>__get__</Method></Frame><Frame><File>/home/bug/virtualenvs/menuchefs/local/lib/python2.7/site-packages/django/db/models/query.py</File><Line>382</Line><Method>get</Method></Frame><Frame><File>/home/bug/virtualenvs/menuchefs/local/lib/python2.7/site-packages/django/db/models/query.py</File><Line>90</Line><Method>__len__</Method></Frame><Frame><File>/home/bug/virtualenvs/menuchefs/local/lib/python2.7/site-packages/django/db/models/query.py</File><Line>301</Line><Method>iterator</Method></Frame><Frame><File>/home/bug/virtualenvs/menuchefs/local/lib/python2.7/site-packages/django/db/models/sql/compiler.py</File><Line>775</Line><Method>results_iter</Method></Frame><Frame><File>/home/bug/virtualenvs/menuchefs/local/lib/python2.7/site-packages/django/db/models/sql/compiler.py</File><Line>840</Line><Method>execute_sql</Method></Frame><Frame><File>/home/bug/virtualenvs/menuchefs/local/lib/python2.7/site-packages/django/db/backends/util.py</File><Line>41</Line><Method>execute</Method></Frame><Frame><File>/home/bug/virtualenvs/menuchefs/local/lib/python2.7/site-packages/django/db/backends/postgresql_psycopg2/base.py</File><Line>58</Line><Method>execute</Method></Frame><Frame><File>/home/bug/virtualenvs/menuchefs/local/lib/python2.7/site-packages/django/db/backends/postgresql_psycopg2/base.py</File><Line>54</Line><Method>execute</Method></Frame></Stack></Post><Post><PostId>24870065</PostId><Url>http://stackoverflow.com/questions/24870065</Url><Stack><Type>DatabaseError</Type><Message>(1064, "You have an error in your SQL syntax; check the manual that corresponds to your MySQL server version for the right syntax to use near '0.6.15-2ubuntu9.7'' LIKE CONCAT(''%'',version,''%''))' at line 1")</Message><Frame><File>/home/sapegin/vulndb_mercurial/vulndb/HANA/PYTHON/Python/lib/python2.6/site-packages/django/core/handlers/base.py</File><Line>111</Line><Method>get_response</Method></Frame><Frame><File>/home/sapegin/vulndb_mercurial/vulndb/vulndb/vulnerabilities/views.py</File><Line>1650</Line><Method>inventory</Method></Frame><Frame><File>/home/sapegin/vulndb_mercurial/vulndb/HANA/PYTHON/Python/lib/python2.6/site-packages/django/db/models/query.py</File><Line>351</Line><Method>count</Method></Frame><Frame><File>/home/sapegin/vulndb_mercurial/vulndb/HANA/PYTHON/Python/lib/python2.6/site-packages/django/db/models/sql/query.py</File><Line>418</Line><Method>get_count</Method></Frame><Frame><File>/home/sapegin/vulndb_mercurial/vulndb/HANA/PYTHON/Python/lib/python2.6/site-packages/django/db/models/sql/query.py</File><Line>384</Line><Method>get_aggregation</Method></Frame><Frame><File>/home/sapegin/vulndb_mercurial/vulndb/HANA/PYTHON/Python/lib/python2.6/site-packages/django/db/models/sql/compiler.py</File><Line>818</Line><Method>execute_sql</Method></Frame><Frame><File>/home/sapegin/vulndb_mercurial/vulndb/HANA/PYTHON/Python/lib/python2.6/site-packages/django/db/backends/util.py</File><Line>40</Line><Method>execute</Method></Frame><Frame><File>/home/sapegin/vulndb_mercurial/vulndb/HANA/PYTHON/Python/lib/python2.6/site-packages/django/db/backends/mysql/base.py</File><Line>119</Line><Method>execute</Method></Frame><Frame><File>/home/sapegin/vulndb_mercurial/vulndb/HANA/PYTHON/Python/lib/python2.6/site-packages/MySQL_python-1.2.4-py2.6-linux-x86_64.egg/MySQLdb/cursors.py</File><Line>201</Line><Method>execute</Method></Frame><Frame><File>/home/sapegin/vulndb_mercurial/vulndb/HANA/PYTHON/Python/lib/python2.6/site-packages/MySQL_python-1.2.4-py2.6-linux-x86_64.egg/MySQLdb/connections.py</File><Line>36</Line><Method>defaulterrorhandler</Method></Frame></Stack></Post></Posts>