<?xml version="1.0" encoding="UTF-8"?><Posts><Post><PostId>1314445</PostId><Url>http://stackoverflow.com/questions/1314445</Url><Stack><Type>Error</Type><Message>('IM002', '[IM002] [Microsoft]</Message><Frame><File>pyshell#41</File><Line>1</Line><Method>module</Method></Frame></Stack></Post><Post><PostId>2358642</PostId><Url>http://stackoverflow.com/questions/2358642</Url><Stack><Type>Error</Type><Message>Error parsing rlog output. Expected RCS file /export/home/cvs/repository/src/java/com/foo/bar/Attic/GlossaryPageBean.java,v, found /export/home/cvs/repositorysrc/java/com/foo/bar/Attic/HomePageBean.java,v</Message><Frame><File>/opt/bin/viewvc-1.0.5/lib/viewvc.py</File><Line>3766</Line><Method>main</Method></Frame><Frame><File>/opt/bin/viewvc-1.0.5/lib/viewvc.py</File><Line>394</Line><Method>run_viewvc</Method></Frame><Frame><File>/opt/bin/viewvc-1.0.5/lib/viewvc.py</File><Line>1565</Line><Method>view_directory</Method></Frame><Frame><File>/opt/bin/viewvc-1.0.5/lib/vclib/bincvs/__init__.py</File><Line>195</Line><Method>dirlogs</Method></Frame><Frame><File>/opt/bin/viewvc-1.0.5/lib/vclib/bincvs/__init__.py</File><Line>917</Line><Method>_get_logs</Method></Frame></Stack></Post><Post><PostId>2689071</PostId><Url>http://stackoverflow.com/questions/2689071</Url><Stack><Type>Error</Type><Message>unsupported locale setting</Message><Frame><File>/usr/lib/python2.6/SocketServer.py</File><Line>558</Line><Method>process_request_thread</Method></Frame><Frame><File>/usr/lib/python2.6/SocketServer.py</File><Line>320</Line><Method>finish_request</Method></Frame><Frame><File>/usr/lib/python2.6/SocketServer.py</File><Line>615</Line><Method>__init__</Method></Frame><Frame><File>/usr/lib/python2.6/BaseHTTPServer.py</File><Line>329</Line><Method>handle</Method></Frame><Frame><File>/usr/lib/python2.6/site-packages/Trac-0.11.7-py2.6.egg/trac/web/wsgi.py</File><Line>194</Line><Method>handle_one_request</Method></Frame><Frame><File>/usr/lib/python2.6/site-packages/Trac-0.11.7-py2.6.egg/trac/web/wsgi.py</File><Line>94</Line><Method>run</Method></Frame><Frame><File>/usr/lib/python2.6/site-packages/Trac-0.11.7-py2.6.egg/trac/web/standalone.py</File><Line>100</Line><Method>__call__</Method></Frame><Frame><File>/usr/lib/python2.6/site-packages/Trac-0.11.7-py2.6.egg/trac/web/main.py</File><Line>346</Line><Method>dispatch_request</Method></Frame><Frame><File>/usr/lib/python2.6/locale.py</File><Line>513</Line><Method>setlocale</Method></Frame></Stack></Post><Post><PostId>3363571</PostId><Url>http://stackoverflow.com/questions/3363571</Url><Stack><Type>Error</Type><Message>[('SSL routines', 'SSL23_GET_CLIENT_HELLO', 'http request')]</Message><Frame><File>/home/eigenein/Projects/Python/Pylons/lib/python2.6/site-packages/Paste-1.7.4-py2.6.egg/paste/httpserver.py</File><Line>1068</Line><Method>process_request_in_thread</Method></Frame><Frame><File>/usr/lib/python2.6/SocketServer.py</File><Line>320</Line><Method>finish_request</Method></Frame><Frame><File>/usr/lib/python2.6/SocketServer.py</File><Line>615</Line><Method>__init__</Method></Frame><Frame><File>/home/eigenein/Projects/Python/Pylons/lib/python2.6/site-packages/Paste-1.7.4-py2.6.egg/paste/httpserver.py</File><Line>442</Line><Method>handle</Method></Frame><Frame><File>/usr/lib/python2.6/BaseHTTPServer.py</File><Line>329</Line><Method>handle</Method></Frame><Frame><File>/home/eigenein/Projects/Python/Pylons/lib/python2.6/site-packages/Paste-1.7.4-py2.6.egg/paste/httpserver.py</File><Line>431</Line><Method>handle_one_request</Method></Frame><Frame><File>/usr/lib/python2.6/socket.py</File><Line>406</Line><Method>readline</Method></Frame></Stack></Post><Post><PostId>4395122</PostId><Url>http://stackoverflow.com/questions/4395122</Url><Stack><Type>Error</Type><Message>('08001', '[08001] [Microsoft]</Message><Frame><File>E:\Mass Emailer\massEmailer.py</File><Line>56</Line><Method>module</Method></Frame></Stack></Post><Post><PostId>5880741</PostId><Url>http://stackoverflow.com/questions/5880741</Url><Stack><Type>Error</Type><Message>Property user is corrupt in the datastore:</Message><Frame><File>/base/python_runtime/python_lib/versions/1/google/appengine/ext/webapp/__init__.py</File><Line>698</Line><Method>__call__</Method></Frame><Frame><File>/base/data/home/apps/classifiedsmarket/dev.350122009565563926/i18n.py</File><Line>266</Line><Method>get</Method></Frame><Frame><File>/base/python_runtime/python_lib/versions/1/google/appengine/ext/db/__init__.py</File><Line>2025</Line><Method>fetch</Method></Frame><Frame><File>/base/python_runtime/python_lib/versions/1/google/appengine/api/datastore.py</File><Line>1504</Line><Method>Get</Method></Frame><Frame><File>/base/python_runtime/python_lib/versions/1/google/appengine/datastore/datastore_query.py</File><Line>2220</Line><Method>next_batch</Method></Frame><Frame><File>/base/python_runtime/python_lib/versions/1/google/appengine/api/apiproxy_stub_map.py</File><Line>592</Line><Method>get_result</Method></Frame><Frame><File>/base/python_runtime/python_lib/versions/1/google/appengine/datastore/datastore_query.py</File><Line>1998</Line><Method>__query_result_hook</Method></Frame><Frame><File>/base/python_runtime/python_lib/versions/1/google/appengine/datastore/datastore_query.py</File><Line>2031</Line><Method>_process_results</Method></Frame><Frame><File>/base/python_runtime/python_lib/versions/1/google/appengine/datastore/datastore_rpc.py</File><Line>127</Line><Method>pb_to_query_result</Method></Frame><Frame><File>/base/python_runtime/python_lib/versions/1/google/appengine/api/datastore.py</File><Line>242</Line><Method>pb_to_entity</Method></Frame><Frame><File>/base/python_runtime/python_lib/versions/1/google/appengine/api/datastore.py</File><Line>962</Line><Method>_FromPb</Method></Frame></Stack></Post><Post><PostId>8571799</PostId><Url>http://stackoverflow.com/questions/8571799</Url><Stack><Type>Error</Type><Message>`tk_chooseDirectory` and `tk_chooseDirectory` are the same file</Message><Frame><File>C:\Python27\lib\lib-tk\Tkinter.py</File><Line>1410</Line><Method>__call__</Method></Frame><Frame><File>C:\Documents and Settings\Bharath Gupta\Desktop\task.py</File><Line>38</Line><Method>start</Method></Frame><Frame><File>C:\Python27\lib\shutil.py</File><Line>116</Line><Method>copy</Method></Frame><Frame><File>C:\Python27\lib\shutil.py</File><Line>68</Line><Method>copyfile</Method></Frame></Stack></Post><Post><PostId>8732172</PostId><Url>http://stackoverflow.com/questions/8732172</Url><Stack><Type>Error</Type><Message>The page has been destroyed and can no longer be used.</Message><Frame><File>resource://jid0-wdemwzahwzh3bsw0kkxlcjg9e7k-at-jetpack-api-utils-lib/content/worker.js</File><Line>405</Line><Method>postMessage</Method></Frame></Stack></Post><Post><PostId>11473737</PostId><Url>http://stackoverflow.com/questions/11473737</Url><Stack><Type>Error</Type><Message>('01000', "[01000] [Microsoft]</Message><Frame><File>C:\Python27\exampes\xxx.py</File><Line>8</Line><Method>module</Method></Frame></Stack></Post><Post><PostId>12358557</PostId><Url>http://stackoverflow.com/questions/12358557</Url><Stack><Type>Error</Type><Message>API error 4 (datastore_v3: NEED_INDEX): no matching index found.</Message><Frame><File>/home/me/google_appengine/google/appengine/tools/adaptive_thread_pool.py</File><Line>176</Line><Method>WorkOnItems</Method></Frame><Frame><File>/home/me/google_appengine/google/appengine/tools/bulkloader.py</File><Line>764</Line><Method>PerformWork</Method></Frame><Frame><File>/home/me/google_appengine/google/appengine/tools/bulkloader.py</File><Line>1170</Line><Method>_TransferItem</Method></Frame><Frame><File>/home/me/google_appengine/google/appengine/tools/bulkloader.py</File><Line>1471</Line><Method>GetEntities</Method></Frame><Frame><File>/home/me/google_appengine/google/appengine/tools/bulkloader.py</File><Line>1442</Line><Method>_QueryForPbs</Method></Frame></Stack></Post><Post><PostId>12413761</PostId><Url>http://stackoverflow.com/questions/12413761</Url><Stack><Type>Error</Type><Message>('07001', '[07001] [MySQL]</Message><Frame><File>C:/Users/vchauhan/Desktop/test_for_write.py</File><Line>111</Line><Method>module</Method></Frame></Stack></Post><Post><PostId>12800101</PostId><Url>http://stackoverflow.com/questions/12800101</Url><Stack><Type>Error</Type><Message>('IM002', '[IM002] [Microsoft]</Message><Frame><File>D:\ThirdTask\connecttwo.py</File><Line>39</Line><Method>module</Method></Frame></Stack></Post><Post><PostId>13208688</PostId><Url>http://stackoverflow.com/questions/13208688</Url><Stack><Type>Error</Type><Message>('IM002', '[IM002] [Microsoft]</Message><Frame><File>D:\ThirdTask\connecttwo.py</File><Line>39</Line><Method>module</Method></Frame></Stack></Post><Post><PostId>14587952</PostId><Url>http://stackoverflow.com/questions/14587952</Url><Stack><Type>Error</Type><Message>Incorrect padding</Message><Frame><File>E:\Programs\Python\lib\site-packages\django\core\handlers\base.py</File><Line>116</Line><Method>get_response</Method></Frame><Frame><File>E:\RSYearWork\ServerRS\Views\TestForAjaxView.py</File><Line>27</Line><Method>addAjax</Method></Frame><Frame><File>E:\Programs\Python\lib\base64.py</File><Line>321</Line><Method>decodestring</Method></Frame></Stack></Post><Post><PostId>14972345</PostId><Url>http://stackoverflow.com/questions/14972345</Url><Stack><Type>Error</Type><Message>[('X509 V3 routines', 'V2I_AUTHORITY_KEYID', 'unable to get issuer keyid'), ('X509 V3 routines', 'X509V3_EXT_nconf', 'error in extension')]</Message><Frame><File>C:\Documents and Settings\Administrator\Desktop\Certificate\certi.py</File><Line>21</Line><Method>module</Method></Frame></Stack></Post><Post><PostId>15777919</PostId><Url>http://stackoverflow.com/questions/15777919</Url><Stack><Type>Error</Type><Message>line contains NULL byte</Message><Frame><File>/Users/aleksnavratil/Desktop/sandbox.py</File><Line>23</Line><Method>module</Method></Frame><Frame><File>/Library/Frameworks/Python.framework/Versions/7.3/lib/python2.7/site-packages/numpy/lib/npyio.py</File><Line>805</Line><Method>loadtxt</Method></Frame><Frame><File>/Volumes/AVN2109/Raw Data/CETR_Plotter.py</File><Line>40</Line><Method>module</Method></Frame><Frame><File>/Library/Frameworks/Python.framework/Versions/7.3/lib/python2.7/site-        packages/matplotlib/mlab.py</File><Line>2181</Line><Method>csv2rec</Method></Frame><Frame><File>/Library/Frameworks/Python.framework/Versions/7.3/lib/python2.7/site-    packages/matplotlib/mlab.py</File><Line>2176</Line><Method>process_skiprows</Method></Frame></Stack></Post><Post><PostId>15777919</PostId><Url>http://stackoverflow.com/questions/15777919</Url><Stack><Type>Error</Type><Message>line contains NULL byte</Message><Frame><File>/Users/aleksnavratil/Desktop/sandbox.py</File><Line>23</Line><Method>module</Method></Frame><Frame><File>/Library/Frameworks/Python.framework/Versions/7.3/lib/python2.7/site-packages/numpy/lib/npyio.py</File><Line>805</Line><Method>loadtxt</Method></Frame><Frame><File>/Volumes/AVN2109/Raw Data/CETR_Plotter.py</File><Line>40</Line><Method>module</Method></Frame><Frame><File>/Library/Frameworks/Python.framework/Versions/7.3/lib/python2.7/site-        packages/matplotlib/mlab.py</File><Line>2181</Line><Method>csv2rec</Method></Frame><Frame><File>/Library/Frameworks/Python.framework/Versions/7.3/lib/python2.7/site-    packages/matplotlib/mlab.py</File><Line>2176</Line><Method>process_skiprows</Method></Frame></Stack></Post><Post><PostId>15943708</PostId><Url>http://stackoverflow.com/questions/15943708</Url><Stack><Type>Error</Type><Message>The page is currently hidden and can no longer be used until it is visible again.</Message><Frame><File>resource://onebutton-at-user043-dot-com/addon-sdk/lib/sdk/panel.js</File><Line>273</Line><Method>_onHide</Method></Frame><Frame><File>resource://onebutton-at-user043-dot-com/addon-sdk/lib/sdk/deprecated/events.js</File><Line>123</Line><Method>_emit</Method></Frame><Frame><File>resource://onebutton-at-user043-dot-com/addon-sdk/lib/sdk/deprecated/events.js</File><Line>153</Line><Method>_emitOnObject</Method></Frame><Frame><File>resource://onebutton-at-user043-dot-com/ubp-install/lib/main.js</File><Line>232</Line><Method>type: 'Application_reload'</Method></Frame><Frame><File>resource://onebutton-at-user043-dot-com/addon-sdk/lib/sdk/content/worker.js</File><Line>369</Line><Method>emit: function () self._emitEventToContent(Array.slice(arguments))</Method></Frame><Frame><File>resource://onebutton-at-user043-dot-com/addon-sdk/lib/sdk/content/worker.js</File><Line>404</Line><Method>_emitEventToContent</Method></Frame></Stack></Post><Post><PostId>16203252</PostId><Url>http://stackoverflow.com/questions/16203252</Url><Stack><Type>Error</Type><Message>R a n d o m   m e s s a g e</Message><Frame><File>pyshell#2</File><Line>1</Line><Method>module</Method></Frame><Frame><File>pyshell#3</File><Line>1</Line><Method>module</Method></Frame><Frame><File>pyshell#4</File><Line>1</Line><Method>module</Method></Frame></Stack></Post><Post><PostId>16203252</PostId><Url>http://stackoverflow.com/questions/16203252</Url><Stack><Type>Error</Type><Message>R a n d o m   m e s s a g e</Message><Frame><File>pyshell#2</File><Line>1</Line><Method>module</Method></Frame><Frame><File>pyshell#3</File><Line>1</Line><Method>module</Method></Frame><Frame><File>pyshell#4</File><Line>1</Line><Method>module</Method></Frame></Stack></Post><Post><PostId>16203252</PostId><Url>http://stackoverflow.com/questions/16203252</Url><Stack><Type>Error</Type><Message>R a n d o m   m e s s a g e</Message><Frame><File>pyshell#2</File><Line>1</Line><Method>module</Method></Frame><Frame><File>pyshell#3</File><Line>1</Line><Method>module</Method></Frame><Frame><File>pyshell#4</File><Line>1</Line><Method>module</Method></Frame></Stack></Post><Post><PostId>16547881</PostId><Url>http://stackoverflow.com/questions/16547881</Url><Stack><Type>Error</Type><Message>('HY000', "[HY000] [Microsoft]</Message><Frame><File>C:/pyodbc_access2007_example.py</File><Line>28</Line><Method>module</Method></Frame><Frame><File>C:/pyodbc_access2007_example.py</File><Line>17</Line><Method>odbc</Method></Frame></Stack></Post><Post><PostId>17435912</PostId><Url>http://stackoverflow.com/questions/17435912</Url><Stack><Type>Error</Type><Message>line contains NULL byte</Message><Frame><File>C:\filepath\conversiontest.py</File><Line>16</Line><Method>module</Method></Frame><Frame><File>C:\Python27\lib\csv.py</File><Line>103</Line><Method>next</Method></Frame><Frame><File>C:\Python27\lib\csv.py</File><Line>90</Line><Method>fieldnames</Method></Frame></Stack></Post><Post><PostId>18411683</PostId><Url>http://stackoverflow.com/questions/18411683</Url><Stack><Type>Error</Type><Message>('28000', "[28000] [Microsoft]</Message><Frame><File>C:\Users\ my username \Documents\sql_connect_test1.py</File><Line>27</Line><Method>module</Method></Frame></Stack></Post><Post><PostId>21752735</PostId><Url>http://stackoverflow.com/questions/21752735</Url><Stack><Type>Error</Type><Message>session 0 not found</Message><Frame><File>/usr/local/src/sparky/platforms/linux-2.6.9/python-2.4.2/lib/python2.4/threading.py</File><Line>442</Line><Method>__bootstrap</Method></Frame><Frame><File>/usr/local/src/sparky/platforms/linux-2.6.9/python-2.4.2/lib/python2.4/threading.py</File><Line>605</Line><Method>run</Method></Frame><Frame><File>/path/to/my/own/code/MyClass.py</File><Line>64</Line><Method>doPeriodically</Method></Frame></Stack></Post><Post><PostId>22199747</PostId><Url>http://stackoverflow.com/questions/22199747</Url><Stack><Type>Error</Type><Message>field larger than field limit (131072)</Message><Frame><File>/home//grpus/dg.py</File><Line>8</Line><Method>module</Method></Frame><Frame><File>/home/grpus/dg.py</File><Line>7</Line><Method>module</Method></Frame></Stack></Post><Post><PostId>22199747</PostId><Url>http://stackoverflow.com/questions/22199747</Url><Stack><Type>Error</Type><Message>field larger than field limit (131072)</Message><Frame><File>/home//grpus/dg.py</File><Line>8</Line><Method>module</Method></Frame><Frame><File>/home/grpus/dg.py</File><Line>7</Line><Method>module</Method></Frame></Stack></Post><Post><PostId>22292646</PostId><Url>http://stackoverflow.com/questions/22292646</Url><Stack><Type>Error</Type><Message>('HYC00', '[HYC00] [Microsoft]</Message><Frame><File>C:/Python33/data2.py</File><Line>15</Line><Method>module</Method></Frame></Stack></Post><Post><PostId>22807473</PostId><Url>http://stackoverflow.com/questions/22807473</Url><Stack><Type>Error</Type><Message>sequence expected</Message><Frame><File>C:/Users/Heinz/Desktop/python_test/distMatrix_test.py</File><Line>54</Line><Method>module</Method></Frame></Stack></Post></Posts>