<?xml version="1.0" encoding="UTF-8"?><Posts><Post><PostId>2616262</PostId><Url>http://stackoverflow.com/questions/2616262</Url><Stack><Type>gaierror</Type><Message>[Errno -2] Name or service not known</Message><Frame><File>./tsttraceback.py</File><Line>47</Line><Method>module</Method></Frame><Frame><File>./tsttraceback.py</File><Line>40</Line><Method>f1</Method></Frame><Frame><File>./tsttraceback.py</File><Line>41</Line><Method>f2</Method></Frame><Frame><File>./tsttraceback.py</File><Line>45</Line><Method>f3</Method></Frame></Stack></Post><Post><PostId>3149350</PostId><Url>http://stackoverflow.com/questions/3149350</Url><Stack><Type>gaierror</Type><Message>(11001, 'getaddrinfo failed')</Message><Frame><File>C:\Documents and Settings\Desktop\New Text Document.py</File><Line>24</Line><Method>?</Method></Frame><Frame><File>C:\Python24\lib\smtplib.py</File><Line>241</Line><Method>__init__</Method></Frame><Frame><File>C:\Python24\lib\smtplib.py</File><Line>289</Line><Method>connect</Method></Frame></Stack></Post><Post><PostId>4090753</PostId><Url>http://stackoverflow.com/questions/4090753</Url><Stack><Type>gaierror</Type><Message>[Errno 8] nodename nor servname provided, or not known</Message><Frame><File>/Users/gferguson/python/pythonbrew/build/Python-2.6.6/Lib/test/test_socket.py</File><Line>483</Line><Method>testSockName</Method></Frame></Stack></Post><Post><PostId>4126023</PostId><Url>http://stackoverflow.com/questions/4126023</Url><Stack><Type>gaierror</Type><Message>[Errno 11004] getaddrinfo failed</Message><Frame><File>C:\Python26\lib\lib-tk\Tkinter.py</File><Line>1410</Line><Method>__call__</Method></Frame><Frame><File>C:\Users\Rabia\Desktop\gethostinfo.py</File><Line>18</Line><Method>Info</Method></Frame></Stack></Post><Post><PostId>5666680</PostId><Url>http://stackoverflow.com/questions/5666680</Url><Stack><Type>gaierror</Type><Message>[Errno 11001] getaddrinfo failed</Message><Frame><File>pyshell#27</File><Line>1</Line><Method>module</Method></Frame><Frame><File>C:\Python27\lib\nntplib.py</File><Line>112</Line><Method>__init__</Method></Frame><Frame><File>C:\Python27\lib\socket.py</File><Line>553</Line><Method>create_connection</Method></Frame></Stack></Post><Post><PostId>6422907</PostId><Url>http://stackoverflow.com/questions/6422907</Url><Stack><Type>gaierror</Type><Message>[Errno 11001] getaddrinfo failed</Message><Frame><File>pyshell#18</File><Line>1</Line><Method>module</Method></Frame></Stack></Post><Post><PostId>8059942</PostId><Url>http://stackoverflow.com/questions/8059942</Url><Stack><Type>gaierror</Type><Message>[Errno 11004] getaddrinfo failed</Message><Frame><File>C:\resolve.py</File><Line>8</Line><Method>module</Method></Frame></Stack></Post><Post><PostId>9846953</PostId><Url>http://stackoverflow.com/questions/9846953</Url><Stack><Type>gaierror</Type><Message>[Errno 8] nodename nor servname provided, or not known</Message><Frame><File>/Applications/GoogleAppEngineLauncher.app/Contents/Resources/GoogleAppEngine-default.bundle/Contents/Resources/google_appengine/google/appengine/api/taskqueue/taskqueue_stub.py</File><Line>1846</Line><Method>ExecuteTask</Method></Frame><Frame><File>/System/Library/Frameworks/Python.framework/Versions/2.6/lib/python2.6/httplib.py</File><Line>868</Line><Method>endheaders</Method></Frame><Frame><File>/System/Library/Frameworks/Python.framework/Versions/2.6/lib/python2.6/httplib.py</File><Line>740</Line><Method>_send_output</Method></Frame><Frame><File>/System/Library/Frameworks/Python.framework/Versions/2.6/lib/python2.6/httplib.py</File><Line>699</Line><Method>send</Method></Frame><Frame><File>/System/Library/Frameworks/Python.framework/Versions/2.6/lib/python2.6/httplib.py</File><Line>683</Line><Method>connect</Method></Frame><Frame><File>/System/Library/Frameworks/Python.framework/Versions/2.6/lib/python2.6/socket.py</File><Line>498</Line><Method>create_connection</Method></Frame></Stack></Post><Post><PostId>11435437</PostId><Url>http://stackoverflow.com/questions/11435437</Url><Stack><Type>gaierror</Type><Message>[Errno -2] Name or service not known</Message><Frame><File>/usr/local/Plone/buildout-cache/eggs/Plone-4.0.4-py2.6.egg/Products/CMFPlone/patches/sendmail.py</File><Line>9</Line><Method>_catch</Method></Frame><Frame><File>/usr/local/Plone/buildout-cache/eggs/zope.sendmail-3.5.2-py2.6.egg/zope/sendmail/mailer.py</File><Line>46</Line><Method>send</Method></Frame><Frame><File>/usr/local/Plone/Python-2.6/lib/python2.6/smtplib.py</File><Line>239</Line><Method>__init__</Method></Frame><Frame><File>/usr/local/Plone/Python-2.6/lib/python2.6/smtplib.py</File><Line>295</Line><Method>connect</Method></Frame><Frame><File>/usr/local/Plone/Python-2.6/lib/python2.6/smtplib.py</File><Line>273</Line><Method>_get_socket</Method></Frame><Frame><File>/usr/local/Plone/Python-2.6/lib/python2.6/socket.py</File><Line>547</Line><Method>create_connection</Method></Frame><Frame><File>/usr/local/Plone/buildout-cache/eggs/Plone-4.0.4-py2.6.egg/Products/CMFPlone/patches/sendmail.py</File><Line>9</Line><Method>_catch</Method></Frame><Frame><File>/usr/local/Plone/buildout-cache/eggs/zope.sendmail-3.5.2-py2.6.egg/zope/sendmail/mailer.py</File><Line>46</Line><Method>send</Method></Frame><Frame><File>/usr/local/Plone/Python-2.6/lib/python2.6/smtplib.py</File><Line>239</Line><Method>__init__</Method></Frame><Frame><File>/usr/local/Plone/Python-2.6/lib/python2.6/smtplib.py</File><Line>295</Line><Method>connect</Method></Frame><Frame><File>/usr/local/Plone/Python-2.6/lib/python2.6/smtplib.py</File><Line>273</Line><Method>_get_socket</Method></Frame><Frame><File>/usr/local/Plone/Python-2.6/lib/python2.6/socket.py</File><Line>547</Line><Method>create_connection</Method></Frame><Frame><File>/usr/local/Plone/buildout-cache/eggs/Plone-4.0.4-py2.6.egg/Products/CMFPlone/patches/sendmail.py</File><Line>9</Line><Method>_catch</Method></Frame><Frame><File>/usr/local/Plone/buildout-cache/eggs/zope.sendmail-3.5.2-py2.6.egg/zope/sendmail/mailer.py</File><Line>46</Line><Method>send</Method></Frame><Frame><File>/usr/local/Plone/Python-2.6/lib/python2.6/smtplib.py</File><Line>239</Line><Method>__init__</Method></Frame><Frame><File>/usr/local/Plone/Python-2.6/lib/python2.6/smtplib.py</File><Line>295</Line><Method>connect</Method></Frame><Frame><File>/usr/local/Plone/Python-2.6/lib/python2.6/smtplib.py</File><Line>273</Line><Method>_get_socket</Method></Frame><Frame><File>/usr/local/Plone/Python-2.6/lib/python2.6/socket.py</File><Line>547</Line><Method>create_connection</Method></Frame><Frame><File>/usr/local/Plone/buildout-cache/eggs/Plone-4.0.4-py2.6.egg/Products/CMFPlone/patches/sendmail.py</File><Line>9</Line><Method>_catch</Method></Frame><Frame><File>/usr/local/Plone/buildout-cache/eggs/zope.sendmail-3.5.2-py2.6.egg/zope/sendmail/mailer.py</File><Line>46</Line><Method>send</Method></Frame><Frame><File>/usr/local/Plone/Python-2.6/lib/python2.6/smtplib.py</File><Line>239</Line><Method>__init__</Method></Frame><Frame><File>/usr/local/Plone/Python-2.6/lib/python2.6/smtplib.py</File><Line>295</Line><Method>connect</Method></Frame><Frame><File>/usr/local/Plone/Python-2.6/lib/python2.6/smtplib.py</File><Line>273</Line><Method>_get_socket</Method></Frame><Frame><File>/usr/local/Plone/Python-2.6/lib/python2.6/socket.py</File><Line>547</Line><Method>create_connection</Method></Frame></Stack></Post><Post><PostId>11435437</PostId><Url>http://stackoverflow.com/questions/11435437</Url><Stack><Type>gaierror</Type><Message>[Errno -2] Name or service not known</Message><Frame><File>/usr/local/Plone/buildout-cache/eggs/Plone-4.0.4-py2.6.egg/Products/CMFPlone/patches/sendmail.py</File><Line>9</Line><Method>_catch</Method></Frame><Frame><File>/usr/local/Plone/buildout-cache/eggs/zope.sendmail-3.5.2-py2.6.egg/zope/sendmail/mailer.py</File><Line>46</Line><Method>send</Method></Frame><Frame><File>/usr/local/Plone/Python-2.6/lib/python2.6/smtplib.py</File><Line>239</Line><Method>__init__</Method></Frame><Frame><File>/usr/local/Plone/Python-2.6/lib/python2.6/smtplib.py</File><Line>295</Line><Method>connect</Method></Frame><Frame><File>/usr/local/Plone/Python-2.6/lib/python2.6/smtplib.py</File><Line>273</Line><Method>_get_socket</Method></Frame><Frame><File>/usr/local/Plone/Python-2.6/lib/python2.6/socket.py</File><Line>547</Line><Method>create_connection</Method></Frame><Frame><File>/usr/local/Plone/buildout-cache/eggs/Plone-4.0.4-py2.6.egg/Products/CMFPlone/patches/sendmail.py</File><Line>9</Line><Method>_catch</Method></Frame><Frame><File>/usr/local/Plone/buildout-cache/eggs/zope.sendmail-3.5.2-py2.6.egg/zope/sendmail/mailer.py</File><Line>46</Line><Method>send</Method></Frame><Frame><File>/usr/local/Plone/Python-2.6/lib/python2.6/smtplib.py</File><Line>239</Line><Method>__init__</Method></Frame><Frame><File>/usr/local/Plone/Python-2.6/lib/python2.6/smtplib.py</File><Line>295</Line><Method>connect</Method></Frame><Frame><File>/usr/local/Plone/Python-2.6/lib/python2.6/smtplib.py</File><Line>273</Line><Method>_get_socket</Method></Frame><Frame><File>/usr/local/Plone/Python-2.6/lib/python2.6/socket.py</File><Line>547</Line><Method>create_connection</Method></Frame><Frame><File>/usr/local/Plone/buildout-cache/eggs/Plone-4.0.4-py2.6.egg/Products/CMFPlone/patches/sendmail.py</File><Line>9</Line><Method>_catch</Method></Frame><Frame><File>/usr/local/Plone/buildout-cache/eggs/zope.sendmail-3.5.2-py2.6.egg/zope/sendmail/mailer.py</File><Line>46</Line><Method>send</Method></Frame><Frame><File>/usr/local/Plone/Python-2.6/lib/python2.6/smtplib.py</File><Line>239</Line><Method>__init__</Method></Frame><Frame><File>/usr/local/Plone/Python-2.6/lib/python2.6/smtplib.py</File><Line>295</Line><Method>connect</Method></Frame><Frame><File>/usr/local/Plone/Python-2.6/lib/python2.6/smtplib.py</File><Line>273</Line><Method>_get_socket</Method></Frame><Frame><File>/usr/local/Plone/Python-2.6/lib/python2.6/socket.py</File><Line>547</Line><Method>create_connection</Method></Frame><Frame><File>/usr/local/Plone/buildout-cache/eggs/Plone-4.0.4-py2.6.egg/Products/CMFPlone/patches/sendmail.py</File><Line>9</Line><Method>_catch</Method></Frame><Frame><File>/usr/local/Plone/buildout-cache/eggs/zope.sendmail-3.5.2-py2.6.egg/zope/sendmail/mailer.py</File><Line>46</Line><Method>send</Method></Frame><Frame><File>/usr/local/Plone/Python-2.6/lib/python2.6/smtplib.py</File><Line>239</Line><Method>__init__</Method></Frame><Frame><File>/usr/local/Plone/Python-2.6/lib/python2.6/smtplib.py</File><Line>295</Line><Method>connect</Method></Frame><Frame><File>/usr/local/Plone/Python-2.6/lib/python2.6/smtplib.py</File><Line>273</Line><Method>_get_socket</Method></Frame><Frame><File>/usr/local/Plone/Python-2.6/lib/python2.6/socket.py</File><Line>547</Line><Method>create_connection</Method></Frame></Stack></Post><Post><PostId>11435437</PostId><Url>http://stackoverflow.com/questions/11435437</Url><Stack><Type>gaierror</Type><Message>[Errno -2] Name or service not known</Message><Frame><File>/usr/local/Plone/buildout-cache/eggs/Plone-4.0.4-py2.6.egg/Products/CMFPlone/patches/sendmail.py</File><Line>9</Line><Method>_catch</Method></Frame><Frame><File>/usr/local/Plone/buildout-cache/eggs/zope.sendmail-3.5.2-py2.6.egg/zope/sendmail/mailer.py</File><Line>46</Line><Method>send</Method></Frame><Frame><File>/usr/local/Plone/Python-2.6/lib/python2.6/smtplib.py</File><Line>239</Line><Method>__init__</Method></Frame><Frame><File>/usr/local/Plone/Python-2.6/lib/python2.6/smtplib.py</File><Line>295</Line><Method>connect</Method></Frame><Frame><File>/usr/local/Plone/Python-2.6/lib/python2.6/smtplib.py</File><Line>273</Line><Method>_get_socket</Method></Frame><Frame><File>/usr/local/Plone/Python-2.6/lib/python2.6/socket.py</File><Line>547</Line><Method>create_connection</Method></Frame><Frame><File>/usr/local/Plone/buildout-cache/eggs/Plone-4.0.4-py2.6.egg/Products/CMFPlone/patches/sendmail.py</File><Line>9</Line><Method>_catch</Method></Frame><Frame><File>/usr/local/Plone/buildout-cache/eggs/zope.sendmail-3.5.2-py2.6.egg/zope/sendmail/mailer.py</File><Line>46</Line><Method>send</Method></Frame><Frame><File>/usr/local/Plone/Python-2.6/lib/python2.6/smtplib.py</File><Line>239</Line><Method>__init__</Method></Frame><Frame><File>/usr/local/Plone/Python-2.6/lib/python2.6/smtplib.py</File><Line>295</Line><Method>connect</Method></Frame><Frame><File>/usr/local/Plone/Python-2.6/lib/python2.6/smtplib.py</File><Line>273</Line><Method>_get_socket</Method></Frame><Frame><File>/usr/local/Plone/Python-2.6/lib/python2.6/socket.py</File><Line>547</Line><Method>create_connection</Method></Frame><Frame><File>/usr/local/Plone/buildout-cache/eggs/Plone-4.0.4-py2.6.egg/Products/CMFPlone/patches/sendmail.py</File><Line>9</Line><Method>_catch</Method></Frame><Frame><File>/usr/local/Plone/buildout-cache/eggs/zope.sendmail-3.5.2-py2.6.egg/zope/sendmail/mailer.py</File><Line>46</Line><Method>send</Method></Frame><Frame><File>/usr/local/Plone/Python-2.6/lib/python2.6/smtplib.py</File><Line>239</Line><Method>__init__</Method></Frame><Frame><File>/usr/local/Plone/Python-2.6/lib/python2.6/smtplib.py</File><Line>295</Line><Method>connect</Method></Frame><Frame><File>/usr/local/Plone/Python-2.6/lib/python2.6/smtplib.py</File><Line>273</Line><Method>_get_socket</Method></Frame><Frame><File>/usr/local/Plone/Python-2.6/lib/python2.6/socket.py</File><Line>547</Line><Method>create_connection</Method></Frame><Frame><File>/usr/local/Plone/buildout-cache/eggs/Plone-4.0.4-py2.6.egg/Products/CMFPlone/patches/sendmail.py</File><Line>9</Line><Method>_catch</Method></Frame><Frame><File>/usr/local/Plone/buildout-cache/eggs/zope.sendmail-3.5.2-py2.6.egg/zope/sendmail/mailer.py</File><Line>46</Line><Method>send</Method></Frame><Frame><File>/usr/local/Plone/Python-2.6/lib/python2.6/smtplib.py</File><Line>239</Line><Method>__init__</Method></Frame><Frame><File>/usr/local/Plone/Python-2.6/lib/python2.6/smtplib.py</File><Line>295</Line><Method>connect</Method></Frame><Frame><File>/usr/local/Plone/Python-2.6/lib/python2.6/smtplib.py</File><Line>273</Line><Method>_get_socket</Method></Frame><Frame><File>/usr/local/Plone/Python-2.6/lib/python2.6/socket.py</File><Line>547</Line><Method>create_connection</Method></Frame></Stack></Post><Post><PostId>11435437</PostId><Url>http://stackoverflow.com/questions/11435437</Url><Stack><Type>gaierror</Type><Message>[Errno -2] Name or service not known</Message><Frame><File>/usr/local/Plone/buildout-cache/eggs/Plone-4.0.4-py2.6.egg/Products/CMFPlone/patches/sendmail.py</File><Line>9</Line><Method>_catch</Method></Frame><Frame><File>/usr/local/Plone/buildout-cache/eggs/zope.sendmail-3.5.2-py2.6.egg/zope/sendmail/mailer.py</File><Line>46</Line><Method>send</Method></Frame><Frame><File>/usr/local/Plone/Python-2.6/lib/python2.6/smtplib.py</File><Line>239</Line><Method>__init__</Method></Frame><Frame><File>/usr/local/Plone/Python-2.6/lib/python2.6/smtplib.py</File><Line>295</Line><Method>connect</Method></Frame><Frame><File>/usr/local/Plone/Python-2.6/lib/python2.6/smtplib.py</File><Line>273</Line><Method>_get_socket</Method></Frame><Frame><File>/usr/local/Plone/Python-2.6/lib/python2.6/socket.py</File><Line>547</Line><Method>create_connection</Method></Frame><Frame><File>/usr/local/Plone/buildout-cache/eggs/Plone-4.0.4-py2.6.egg/Products/CMFPlone/patches/sendmail.py</File><Line>9</Line><Method>_catch</Method></Frame><Frame><File>/usr/local/Plone/buildout-cache/eggs/zope.sendmail-3.5.2-py2.6.egg/zope/sendmail/mailer.py</File><Line>46</Line><Method>send</Method></Frame><Frame><File>/usr/local/Plone/Python-2.6/lib/python2.6/smtplib.py</File><Line>239</Line><Method>__init__</Method></Frame><Frame><File>/usr/local/Plone/Python-2.6/lib/python2.6/smtplib.py</File><Line>295</Line><Method>connect</Method></Frame><Frame><File>/usr/local/Plone/Python-2.6/lib/python2.6/smtplib.py</File><Line>273</Line><Method>_get_socket</Method></Frame><Frame><File>/usr/local/Plone/Python-2.6/lib/python2.6/socket.py</File><Line>547</Line><Method>create_connection</Method></Frame><Frame><File>/usr/local/Plone/buildout-cache/eggs/Plone-4.0.4-py2.6.egg/Products/CMFPlone/patches/sendmail.py</File><Line>9</Line><Method>_catch</Method></Frame><Frame><File>/usr/local/Plone/buildout-cache/eggs/zope.sendmail-3.5.2-py2.6.egg/zope/sendmail/mailer.py</File><Line>46</Line><Method>send</Method></Frame><Frame><File>/usr/local/Plone/Python-2.6/lib/python2.6/smtplib.py</File><Line>239</Line><Method>__init__</Method></Frame><Frame><File>/usr/local/Plone/Python-2.6/lib/python2.6/smtplib.py</File><Line>295</Line><Method>connect</Method></Frame><Frame><File>/usr/local/Plone/Python-2.6/lib/python2.6/smtplib.py</File><Line>273</Line><Method>_get_socket</Method></Frame><Frame><File>/usr/local/Plone/Python-2.6/lib/python2.6/socket.py</File><Line>547</Line><Method>create_connection</Method></Frame><Frame><File>/usr/local/Plone/buildout-cache/eggs/Plone-4.0.4-py2.6.egg/Products/CMFPlone/patches/sendmail.py</File><Line>9</Line><Method>_catch</Method></Frame><Frame><File>/usr/local/Plone/buildout-cache/eggs/zope.sendmail-3.5.2-py2.6.egg/zope/sendmail/mailer.py</File><Line>46</Line><Method>send</Method></Frame><Frame><File>/usr/local/Plone/Python-2.6/lib/python2.6/smtplib.py</File><Line>239</Line><Method>__init__</Method></Frame><Frame><File>/usr/local/Plone/Python-2.6/lib/python2.6/smtplib.py</File><Line>295</Line><Method>connect</Method></Frame><Frame><File>/usr/local/Plone/Python-2.6/lib/python2.6/smtplib.py</File><Line>273</Line><Method>_get_socket</Method></Frame><Frame><File>/usr/local/Plone/Python-2.6/lib/python2.6/socket.py</File><Line>547</Line><Method>create_connection</Method></Frame></Stack></Post><Post><PostId>12541173</PostId><Url>http://stackoverflow.com/questions/12541173</Url><Stack><Type>gaierror</Type><Message>[Errno 10109] getaddrinfo failed</Message><Frame><File>pyshell#9</File><Line>1</Line><Method>module</Method></Frame><Frame><File>C:\Python27\lib\site-packages\paramiko\client.py</File><Line>282</Line><Method>connect</Method></Frame></Stack></Post><Post><PostId>13273067</PostId><Url>http://stackoverflow.com/questions/13273067</Url><Stack><Type>gaierror</Type><Message>[Errno 8] nodename nor servname provided, or not known</Message><Frame><File>/Applications/GoogleAppEngineLauncher.app/Contents/Resources/GoogleAppEngine-default.bundle/Contents/Resources/google_appengine/google/appengine/api/taskqueue/taskqueue_stub.py</File><Line>1884</Line><Method>ExecuteTask</Method></Frame><Frame><File>/System/Library/Frameworks/Python.framework/Versions/2.7/lib/python2.7/httplib.py</File><Line>937</Line><Method>endheaders</Method></Frame><Frame><File>/System/Library/Frameworks/Python.framework/Versions/2.7/lib/python2.7/httplib.py</File><Line>797</Line><Method>_send_output</Method></Frame><Frame><File>/System/Library/Frameworks/Python.framework/Versions/2.7/lib/python2.7/httplib.py</File><Line>759</Line><Method>send</Method></Frame><Frame><File>/System/Library/Frameworks/Python.framework/Versions/2.7/lib/python2.7/httplib.py</File><Line>740</Line><Method>connect</Method></Frame><Frame><File>/System/Library/Frameworks/Python.framework/Versions/2.7/lib/python2.7/socket.py</File><Line>553</Line><Method>create_connection</Method></Frame></Stack></Post><Post><PostId>13318304</PostId><Url>http://stackoverflow.com/questions/13318304</Url><Stack><Type>gaierror</Type><Message>[Errno 2] temporary failure in name resolution.</Message><Frame><File>/home/root/ntp_manager/ntp_manager.py</File><Line>34</Line><Method>getDate</Method></Frame><Frame><File>/usr/lib/python2.7/ntplib.py</File><Line>265</Line><Method>request</Method></Frame></Stack></Post><Post><PostId>14490212</PostId><Url>http://stackoverflow.com/questions/14490212</Url><Stack><Type>gaierror</Type><Message>[Errno 11003] getaddrinfo failed</Message><Frame><File>C:\Users\joe\Desktop\PHA\AndroidPhones\androidphonescript2.py</File><Line>5</Line><Method>module</Method></Frame><Frame><File>C:\Python27\lib\httplib2.py</File><Line>608</Line><Method>request</Method></Frame><Frame><File>C:\Python27\lib\httplib2.py</File><Line>449</Line><Method>_request</Method></Frame><Frame><File>C:\Python27\lib\httplib2.py</File><Line>427</Line><Method>_conn_request</Method></Frame><Frame><File>C:\Python27\lib\httplib.py</File><Line>1157</Line><Method>connect</Method></Frame><Frame><File>C:\Python27\lib\socket.py</File><Line>553</Line><Method>create_connection</Method></Frame></Stack></Post><Post><PostId>17182416</PostId><Url>http://stackoverflow.com/questions/17182416</Url><Stack><Type>gaierror</Type><Message>[Errno 11004] getaddrinfo failed</Message><Frame><File>directory</File><Line>4</Line><Method>module</Method></Frame><Frame><File>C:\Python27\lib\ftplib.py</File><Line>117</Line><Method>__init__</Method></Frame><Frame><File>C:\Python27\lib\ftplib.py</File><Line>132</Line><Method>connect</Method></Frame><Frame><File>C:\Python27\lib\socket.py</File><Line>553</Line><Method>create_connection</Method></Frame></Stack></Post><Post><PostId>17781916</PostId><Url>http://stackoverflow.com/questions/17781916</Url><Stack><Type>gaierror</Type><Message>[Errno 11004] getaddrinfo failed</Message><Frame><File>C:/Users/turtle/Desktop/OUTPUT/STACKOVERFLOW - ftplib.py</File><Line>4</Line><Method>module</Method></Frame><Frame><File>C:\Python27\lib\ftplib.py</File><Line>117</Line><Method>__init__</Method></Frame><Frame><File>C:\Python27\lib\ftplib.py</File><Line>132</Line><Method>connect</Method></Frame><Frame><File>C:\Python27\lib\socket.py</File><Line>553</Line><Method>create_connection</Method></Frame></Stack></Post><Post><PostId>18216923</PostId><Url>http://stackoverflow.com/questions/18216923</Url><Stack><Type>gaierror</Type><Message>[Errno 11004] getaddrinfo failed`</Message><Frame><File>pyshell#3</File><Line>1</Line><Method>module</Method></Frame><Frame><File>C:\Python27\lib\httplib.py</File><Line>973</Line><Method>request</Method></Frame><Frame><File>C:\Python27\lib\httplib.py</File><Line>1007</Line><Method>_send_request</Method></Frame><Frame><File>C:\Python27\lib\httplib.py</File><Line>969</Line><Method>endheaders</Method></Frame><Frame><File>C:\Python27\lib\httplib.py</File><Line>829</Line><Method>_send_output</Method></Frame><Frame><File>C:\Python27\lib\httplib.py</File><Line>791</Line><Method>send</Method></Frame><Frame><File>C:\Python27\lib\httplib.py</File><Line>772</Line><Method>connect</Method></Frame><Frame><File>C:\Python27\lib\socket.py</File><Line>553</Line><Method>create_connection</Method></Frame></Stack></Post><Post><PostId>21845699</PostId><Url>http://stackoverflow.com/questions/21845699</Url><Stack><Type>gaierror</Type><Message>[Errno 11004] getaddrinfo failed</Message><Frame><File>C:/Users/Owner/Desktop/TheMagicalCake</File><Line>47</Line><Method>module</Method></Frame><Frame><File>C:\Python27\lib\socket.py</File><Line>224</Line><Method>meth</Method></Frame></Stack></Post></Posts>