<?xml version="1.0" encoding="UTF-8"?><Posts><Post><PostId>17980466</PostId><Url>http://stackoverflow.com/questions/17980466</Url><Stack><Type>OAuthError</Type><Message>[1] An unknown error has occurred.</Message><Frame><File>pyshell#40</File><Line>1</Line><Method>module</Method></Frame><Frame><File>C:\Documents and Settings\visolank\Desktop\Python\programs\facepy\graph_api.py</File><Line>42</Line><Method>get</Method></Frame><Frame><File>C:\Documents and Settings\visolank\Desktop\Python\programs\facepy\graph_api.py</File><Line>251</Line><Method>_query</Method></Frame><Frame><File>C:\Documents and Settings\visolank\Desktop\Python\programs\facepy\graph_api.py</File><Line>251</Line><Method>_query</Method></Frame><Frame><File>C:\Documents and Settings\visolank\Desktop\Python\programs\facepy\graph_api.py</File><Line>251</Line><Method>_query</Method></Frame><Frame><File>C:\Documents and Settings\visolank\Desktop\Python\programs\facepy\graph_api.py</File><Line>248</Line><Method>_query</Method></Frame><Frame><File>C:\Documents and Settings\visolank\Desktop\Python\programs\facepy\graph_api.py</File><Line>210</Line><Method>load</Method></Frame><Frame><File>C:\Documents and Settings\visolank\Desktop\Python\programs\facepy\graph_api.py</File><Line>290</Line><Method>_parse</Method></Frame></Stack></Post></Posts>