<?xml version="1.0" encoding="UTF-8"?><Posts><Post><PostId>4713089</PostId><Url>http://stackoverflow.com/questions/4713089</Url><Stack><Type>RequestError</Type><Message>{'status': 401, 'body': '</Message><Frame><File>C:\Program Files (x86)\Google\google_appengine\google\appengine\ext\webapp\__init__.py</File><Line>515</Line><Method>__call__</Method></Frame><Frame><File>C:\Users\Joshua\appengineapps\jmm-timeline\main.py</File><Line>75</Line><Method>get</Method></Frame><Frame><File>C:\Users\Joshua\appengineapps\website\gdata\service.py</File><Line>1108</Line><Method>Get</Method></Frame></Stack></Post><Post><PostId>9542387</PostId><Url>http://stackoverflow.com/questions/9542387</Url><Stack><Type>RequestError</Type><Message>Server responded with: 400, Malformed Content-Type</Message><Frame><File>/Applications/GoogleAppEngineLauncher.app/Contents/Resources/GoogleAppEngine-default.bundle/Contents/Resources/google_appengine/google/appengine/ext/webapp/_webapp25.py</File><Line>703</Line><Method>__call__</Method></Frame><Frame><File>...trim... /main.py</File><Line>126</Line><Method>post</Method></Frame><Frame><File>...trim... /gdata/contacts/client.py</File><Line>288</Line><Method>change_photo</Method></Frame><Frame><File>...trim... /atom/client.py</File><Line>142</Line><Method>put</Method></Frame><Frame><File>...trim... /gdata/client.py</File><Line>319</Line><Method>request</Method></Frame></Stack></Post><Post><PostId>18032980</PostId><Url>http://stackoverflow.com/questions/18032980</Url><Stack><Type>RequestError</Type><Message>Server responded with: 500, Internal Error</Message><Frame><File>/base/data/home/runtimes/python/python_lib/versions/1/google/appengine/ext/webapp/_webapp25.py</File><Line>716</Line><Method>__call__</Method></Frame><Frame><File>/base/data/home/apps/s~goodocdrop-hrd/70.369239377977712685/handler.py</File><Line>533</Line><Method>post</Method></Frame><Frame><File>/base/data/home/apps/s~goodocdrop-hrd/70.369239377977712685/gdata/client.py</File><Line>1026</Line><Method>upload_file</Method></Frame><Frame><File>/base/data/home/apps/s~goodocdrop-hrd/70.369239377977712685/gdata/client.py</File><Line>944</Line><Method>_init_session</Method></Frame><Frame><File>/base/data/home/apps/s~goodocdrop-hrd/70.369239377977712685/gdata/client.py</File><Line>320</Line><Method>request</Method></Frame></Stack></Post><Post><PostId>20319873</PostId><Url>http://stackoverflow.com/questions/20319873</Url><Stack><Type>RequestError</Type><Message>Forge API call to module/admob/version went wrong: Expecting object: line 9 column 1 (char 174)</Message><Frame><File>/Users/kevzettler/Library/Trigger Toolkit/build-tools/forge/async.py</File><Line>106</Line><Method>run</Method></Frame><Frame><File>/Users/kevzettler/Library/Trigger Toolkit/trigger/api/api.py</File><Line>20</Line><Method>post_files</Method></Frame><Frame><File>/Users/kevzettler/Library/Trigger Toolkit/build-tools/forge/remote.py</File><Line>475</Line><Method>_api_post</Method></Frame><Frame><File>/Users/kevzettler/Library/Trigger Toolkit/build-tools/forge/remote.py</File><Line>121</Line><Method>_check_api_response_for_error</Method></Frame><Frame><File>/Users/kevzettler/Library/Trigger Toolkit/build-tools/forge/remote.py</File><Line>81</Line><Method>_raise_if_json_error</Method></Frame></Stack></Post><Post><PostId>21513458</PostId><Url>http://stackoverflow.com/questions/21513458</Url><Stack><Type>RequestError</Type><Message>Server responded with: 413,</Message><Frame><File>pyshell#112</File><Line>1</Line><Method>module</Method></Frame><Frame><File>path/filename.py</File><Line>12</Line><Method>PrintAllContacts</Method></Frame><Frame><File>C:\Python27\lib\gdata\contacts\client.py</File><Line>201</Line><Method>get_contacts</Method></Frame><Frame><File>C:\Python27\lib\gdata\client.py</File><Line>640</Line><Method>get_feed</Method></Frame><Frame><File>C:\Python27\lib\gdata\client.py</File><Line>319</Line><Method>request</Method></Frame></Stack></Post><Post><PostId>21779185</PostId><Url>http://stackoverflow.com/questions/21779185</Url><Stack><Type>RequestError</Type><Message>Server responded with: 500, Internal Error</Message><Frame><File>/home/nj/google_appengine/lib/webapp2-2.5.2/webapp2.py</File><Line>1535</Line><Method>__call__</Method></Frame><Frame><File>/home/nj/google_appengine/lib/webapp2-2.5.2/webapp2.py</File><Line>1529</Line><Method>__call__</Method></Frame><Frame><File>/home/nj/google_appengine/lib/webapp2-2.5.2/webapp2.py</File><Line>1278</Line><Method>default_dispatcher</Method></Frame><Frame><File>/home/nj/google_appengine/lib/webapp2-2.5.2/webapp2.py</File><Line>1102</Line><Method>__call__</Method></Frame><Frame><File>/home/nj/google_appengine/lib/webapp2-2.5.2/webapp2.py</File><Line>572</Line><Method>dispatch</Method></Frame><Frame><File>/home/nj/google_appengine/lib/webapp2-2.5.2/webapp2.py</File><Line>570</Line><Method>dispatch</Method></Frame><Frame><File>/home/nj/Appengine/sms/test_oauth.py</File><Line>56</Line><Method>get</Method></Frame><Frame><File>/home/nj/Appengine/sms/gdata/client.py</File><Line>640</Line><Method>get_feed</Method></Frame><Frame><File>/home/nj/Appengine/sms/gdata/client.py</File><Line>319</Line><Method>request</Method></Frame></Stack></Post></Posts>