<?xml version="1.0" encoding="UTF-8"?><Posts><Post><PostId>384926</PostId><Url>http://stackoverflow.com/questions/384926</Url><Stack><Type>SystemError</Type><Message>new style getargs format but argument is not a tuple</Message><Frame><File>...blablabla.../PIL/Image.py</File><Line>1185</Line><Method>putdata</Method></Frame></Stack></Post><Post><PostId>1355931</PostId><Url>http://stackoverflow.com/questions/1355931</Url><Stack><Type>SystemError</Type><Message>super(): no arguments</Message><Frame><File>stdin</File><Line>1</Line><Method>module</Method></Frame><Frame><File>stdin</File><Line>3</Line><Method>__new__</Method></Frame></Stack></Post><Post><PostId>2287966</PostId><Url>http://stackoverflow.com/questions/2287966</Url><Stack><Type>SystemError</Type><Message>Parent module 'PIL' not loaded</Message><Frame><File>C:\Program Files (x86)\Google\google_appengine\google\appengine\tools\dev_appserver.py</File><Line>3180</Line><Method>_HandleRequest</Method></Frame><Frame><File>C:\Program Files (x86)\Google\google_appengine\google\appengine\tools\dev_appserver.py</File><Line>3123</Line><Method>_Dispatch</Method></Frame><Frame><File>C:\Program Files (x86)\Google\google_appengine\google\appengine\tools\dev_appserver.py</File><Line>515</Line><Method>Dispatch</Method></Frame><Frame><File>C:\Program Files (x86)\Google\google_appengine\google\appengine\tools\dev_appserver.py</File><Line>2382</Line><Method>Dispatch</Method></Frame><Frame><File>C:\Program Files (x86)\Google\google_appengine\google\appengine\tools\dev_appserver.py</File><Line>2292</Line><Method>ExecuteCGI</Method></Frame><Frame><File>C:\Program Files (x86)\Google\google_appengine\google\appengine\tools\dev_appserver.py</File><Line>2188</Line><Method>ExecuteOrImportScript</Method></Frame><Frame><File>d:\imgsvc\imgsvc.py</File><Line>7</Line><Method>module</Method></Frame><Frame><File>C:\Program Files (x86)\Google\google_appengine\google\appengine\api\images\__init__.py</File><Line>625</Line><Method>resize</Method></Frame><Frame><File>C:\Program Files (x86)\Google\google_appengine\google\appengine\api\images\__init__.py</File><Line>513</Line><Method>execute_transforms</Method></Frame><Frame><File>C:\Program Files (x86)\Google\google_appengine\google\appengine\api\apiproxy_stub_map.py</File><Line>78</Line><Method>MakeSyncCall</Method></Frame><Frame><File>C:\Program Files (x86)\Google\google_appengine\google\appengine\api\apiproxy_stub_map.py</File><Line>278</Line><Method>MakeSyncCall</Method></Frame><Frame><File>C:\Program Files (x86)\Google\google_appengine\google\appengine\api\apiproxy_rpc.py</File><Line>149</Line><Method>_WaitImpl</Method></Frame><Frame><File>C:\Program Files (x86)\Google\google_appengine\google\appengine\api\apiproxy_stub.py</File><Line>80</Line><Method>MakeSyncCall</Method></Frame><Frame><File>C:\Program Files (x86)\Google\google_appengine\google\appengine\api\images\images_stub.py</File><Line>171</Line><Method>_Dynamic_Transform</Method></Frame><Frame><File>C:\Program Files (x86)\Google\google_appengine\google\appengine\api\images\images_stub.py</File><Line>193</Line><Method>_EncodeImage</Method></Frame><Frame><File>C:\Python25\lib\site-packages\PIL\Image.py</File><Line>1439</Line><Method>save</Method></Frame><Frame><File>C:\Python25\lib\site-packages\PIL\PngImagePlugin.py</File><Line>564</Line><Method>_save</Method></Frame></Stack></Post><Post><PostId>2943847</PostId><Url>http://stackoverflow.com/questions/2943847</Url><Stack><Type>SystemError</Type><Message>Parent module 'mainpack' not loaded, cannot perform relative import</Message><Frame><File>/usr/lib/python2.6/runpy.py</File><Line>122</Line><Method>_run_module_as_main</Method></Frame><Frame><File>/usr/lib/python2.6/runpy.py</File><Line>34</Line><Method>_run_code</Method></Frame><Frame><File>path/mainpack/__main__.py</File><Line>2</Line><Method>module</Method></Frame></Stack></Post><Post><PostId>3173702</PostId><Url>http://stackoverflow.com/questions/3173702</Url><Stack><Type>SystemError</Type><Message>Cannot compile 'Python.h'. Perhaps you need to install python-dev|python-devel.</Message><Frame><File>setup.py</File><Line>210</Line><Method>module</Method></Frame><Frame><File>setup.py</File><Line>203</Line><Method>setup_package</Method></Frame><Frame><File>/Users/Software/numpy/numpy/distutils/core.py</File><Line>186</Line><Method>setup</Method></Frame><Frame><File>/Library/Frameworks/Python.framework/Versions/2.6/lib/python2.6/distutils/core.py</File><Line>152</Line><Method>setup</Method></Frame><Frame><File>/Library/Frameworks/Python.framework/Versions/2.6/lib/python2.6/distutils/dist.py</File><Line>975</Line><Method>run_commands</Method></Frame><Frame><File>/Library/Frameworks/Python.framework/Versions/2.6/lib/python2.6/distutils/dist.py</File><Line>995</Line><Method>run_command</Method></Frame><Frame><File>/Users/Software/numpy/numpy/distutils/command/install.py</File><Line>55</Line><Method>run</Method></Frame><Frame><File>/Library/Frameworks/Python.framework/Versions/2.6/lib/python2.6/distutils/command/install.py</File><Line>577</Line><Method>run</Method></Frame><Frame><File>/Library/Frameworks/Python.framework/Versions/2.6/lib/python2.6/distutils/cmd.py</File><Line>333</Line><Method>run_command</Method></Frame><Frame><File>/Library/Frameworks/Python.framework/Versions/2.6/lib/python2.6/distutils/dist.py</File><Line>995</Line><Method>run_command</Method></Frame><Frame><File>/Users/Software/numpy/numpy/distutils/command/build.py</File><Line>37</Line><Method>run</Method></Frame><Frame><File>/Library/Frameworks/Python.framework/Versions/2.6/lib/python2.6/distutils/command/build.py</File><Line>134</Line><Method>run</Method></Frame><Frame><File>/Library/Frameworks/Python.framework/Versions/2.6/lib/python2.6/distutils/cmd.py</File><Line>333</Line><Method>run_command</Method></Frame><Frame><File>/Library/Frameworks/Python.framework/Versions/2.6/lib/python2.6/distutils/dist.py</File><Line>995</Line><Method>run_command</Method></Frame><Frame><File>/Users/Software/numpy/numpy/distutils/command/build_src.py</File><Line>152</Line><Method>run</Method></Frame><Frame><File>/Users/Software/numpy/numpy/distutils/command/build_src.py</File><Line>169</Line><Method>build_sources</Method></Frame><Frame><File>/Users/Software/numpy/numpy/distutils/command/build_src.py</File><Line>328</Line><Method>build_extension_sources</Method></Frame><Frame><File>/Users/Software/numpy/numpy/distutils/command/build_src.py</File><Line>385</Line><Method>generate_sources</Method></Frame><Frame><File>numpy/core/setup.py</File><Line>395</Line><Method>generate_config_h</Method></Frame><Frame><File>numpy/core/setup.py</File><Line>41</Line><Method>check_types</Method></Frame><Frame><File>numpy/core/setup.py</File><Line>260</Line><Method>check_types</Method></Frame></Stack></Post><Post><PostId>3553088</PostId><Url>http://stackoverflow.com/questions/3553088</Url><Stack><Type>SystemError</Type><Message>new style getargs format but argument is not a tuple</Message><Frame><File>C:\Users\Nave\Desktop\a1\a1_template.py</File><Line>31</Line><Method>module</Method></Frame><Frame><File>C:\Users\Nave\Desktop\a1\a1_template.py</File><Line>23</Line><Method>doLOLImage</Method></Frame></Stack></Post><Post><PostId>6712051</PostId><Url>http://stackoverflow.com/questions/6712051</Url><Stack><Type>SystemError</Type><Message>Object reference not set to an instance of an object.</Message><Frame><File>stdin</File><Line>1</Line><Method>module</Method></Frame><Frame><File>c:/path/to/code.py</File><Line>10</Line><Method>cross_intersections</Method></Frame></Stack></Post><Post><PostId>6784858</PostId><Url>http://stackoverflow.com/questions/6784858</Url><Stack><Type>SystemError</Type><Message>Bad call flags in PyCFunction_Call. METH_OLDARGS is no longer suppo</Message><Frame><File>testscript.py</File><Line>7</Line><Method>module</Method></Frame></Stack></Post><Post><PostId>7114475</PostId><Url>http://stackoverflow.com/questions/7114475</Url><Stack><Type>SystemError</Type><Message>Objects/stringobject.c:3518: bad argument to internal function</Message><Frame><File>./try.py</File><Line>12</Line><Method>?</Method></Frame><Frame><File>/usr/lib64/python2.4/commands.py</File><Line>44</Line><Method>getoutput</Method></Frame><Frame><File>/usr/lib64/python2.4/commands.py</File><Line>54</Line><Method>getstatusoutput</Method></Frame></Stack></Post><Post><PostId>9445587</PostId><Url>http://stackoverflow.com/questions/9445587</Url><Stack><Type>SystemError</Type><Message>('Failed', 'make')</Message><Frame><File>setup.py</File><Line>75</Line><Method>module</Method></Frame><Frame><File>/usr/lib/python2.6/distutils/command/build_ext.py</File><Line>13</Line><Method>module</Method></Frame><Frame><File>/home/student/geoserv_new/geoportal2/trunk/parts/buildout/site.py</File><Line>601</Line><Method>module</Method></Frame><Frame><File>/home/student/geoserv_new/geoportal2/trunk/parts/buildout/site.py</File><Line>583</Line><Method>main</Method></Frame><Frame><File>/home/student/geoserv_new/geoportal2/trunk/parts/buildout/site.py</File><Line>271</Line><Method>addusersitepackages</Method></Frame><Frame><File>/home/student/geoserv_new/geoportal2/trunk/parts/buildout/site.py</File><Line>246</Line><Method>getusersitepackages</Method></Frame><Frame><File>/home/student/geoserv_new/geoportal2/trunk/parts/buildout/site.py</File><Line>235</Line><Method>getuserbase</Method></Frame><Frame><File>/home/student/geoserv_new/geoportal2/trunk/eggs/zc.buildout-1.5.2-py2.7.egg/zc/buildout/buildout.py</File><Line>1805</Line><Method>main</Method></Frame><Frame><File>/home/student/geoserv_new/geoportal2/trunk/eggs/zc.buildout-1.5.2-py2.7.egg/zc/buildout/buildout.py</File><Line>584</Line><Method>install</Method></Frame><Frame><File>/home/student/geoserv_new/geoportal2/trunk/eggs/zc.buildout-1.5.2-py2.7.egg/zc/buildout/buildout.py</File><Line>1297</Line><Method>_call</Method></Frame><Frame><File>/home/student/geoserv_new/geoportal2/trunk/eggs/zc.recipe.cmmi-1.3.5-py2.7.egg/zc/recipe/cmmi/__init__.py</File><Line>113</Line><Method>install</Method></Frame><Frame><File>/home/student/geoserv_new/geoportal2/trunk/eggs/zc.recipe.cmmi-1.3.5-py2.7.egg/zc/recipe/cmmi/__init__.py</File><Line>196</Line><Method>build</Method></Frame><Frame><File>/home/student/geoserv_new/geoportal2/trunk/eggs/zc.recipe.cmmi-1.3.5-py2.7.egg/zc/recipe/cmmi/__init__.py</File><Line>222</Line><Method>cmmi</Method></Frame><Frame><File>/home/student/geoserv_new/geoportal2/trunk/eggs/zc.recipe.cmmi-1.3.5-py2.7.egg/zc/recipe/cmmi/__init__.py</File><Line>34</Line><Method>system</Method></Frame></Stack></Post><Post><PostId>9445587</PostId><Url>http://stackoverflow.com/questions/9445587</Url><Stack><Type>SystemError</Type><Message>('Failed', 'make')</Message><Frame><File>setup.py</File><Line>75</Line><Method>module</Method></Frame><Frame><File>/usr/lib/python2.6/distutils/command/build_ext.py</File><Line>13</Line><Method>module</Method></Frame><Frame><File>/home/student/geoserv_new/geoportal2/trunk/parts/buildout/site.py</File><Line>601</Line><Method>module</Method></Frame><Frame><File>/home/student/geoserv_new/geoportal2/trunk/parts/buildout/site.py</File><Line>583</Line><Method>main</Method></Frame><Frame><File>/home/student/geoserv_new/geoportal2/trunk/parts/buildout/site.py</File><Line>271</Line><Method>addusersitepackages</Method></Frame><Frame><File>/home/student/geoserv_new/geoportal2/trunk/parts/buildout/site.py</File><Line>246</Line><Method>getusersitepackages</Method></Frame><Frame><File>/home/student/geoserv_new/geoportal2/trunk/parts/buildout/site.py</File><Line>235</Line><Method>getuserbase</Method></Frame><Frame><File>/home/student/geoserv_new/geoportal2/trunk/eggs/zc.buildout-1.5.2-py2.7.egg/zc/buildout/buildout.py</File><Line>1805</Line><Method>main</Method></Frame><Frame><File>/home/student/geoserv_new/geoportal2/trunk/eggs/zc.buildout-1.5.2-py2.7.egg/zc/buildout/buildout.py</File><Line>584</Line><Method>install</Method></Frame><Frame><File>/home/student/geoserv_new/geoportal2/trunk/eggs/zc.buildout-1.5.2-py2.7.egg/zc/buildout/buildout.py</File><Line>1297</Line><Method>_call</Method></Frame><Frame><File>/home/student/geoserv_new/geoportal2/trunk/eggs/zc.recipe.cmmi-1.3.5-py2.7.egg/zc/recipe/cmmi/__init__.py</File><Line>113</Line><Method>install</Method></Frame><Frame><File>/home/student/geoserv_new/geoportal2/trunk/eggs/zc.recipe.cmmi-1.3.5-py2.7.egg/zc/recipe/cmmi/__init__.py</File><Line>196</Line><Method>build</Method></Frame><Frame><File>/home/student/geoserv_new/geoportal2/trunk/eggs/zc.recipe.cmmi-1.3.5-py2.7.egg/zc/recipe/cmmi/__init__.py</File><Line>222</Line><Method>cmmi</Method></Frame><Frame><File>/home/student/geoserv_new/geoportal2/trunk/eggs/zc.recipe.cmmi-1.3.5-py2.7.egg/zc/recipe/cmmi/__init__.py</File><Line>34</Line><Method>system</Method></Frame></Stack></Post><Post><PostId>9815659</PostId><Url>http://stackoverflow.com/questions/9815659</Url><Stack><Type>SystemError</Type><Message>('Failed', 'make')</Message><Frame><File>/home/joeblow/buildout-cache/eggs/zc.buildout-1.4.4-py2.6.egg/zc/buildout/buildout.py</File><Line>1683</Line><Method>main</Method></Frame><Frame><File>/home/joeblow/buildout-cache/eggs/zc.buildout-1.4.4-py2.6.egg/zc/buildout/buildout.py</File><Line>555</Line><Method>install</Method></Frame><Frame><File>/home/joeblow/buildout-cache/eggs/zc.buildout-1.4.4-py2.6.egg/zc/buildout/buildout.py</File><Line>1227</Line><Method>_call</Method></Frame><Frame><File>/home/joeblow/buildout-cache/eggs/z3c.recipe.staticlxml-0.7.2-py2.6.egg/z3c/recipe/staticlxml/__init__.py</File><Line>169</Line><Method>install</Method></Frame><Frame><File>/home/joeblow/buildout-cache/eggs/z3c.recipe.staticlxml-0.7.2-py2.6.egg/z3c/recipe/staticlxml/__init__.py</File><Line>129</Line><Method>build_libxml2</Method></Frame><Frame><File>/home/joeblow/buildout-cache/eggs/zc.recipe.cmmi-1.3.4-py2.6.egg/zc/recipe/cmmi/__init__.py</File><Line>99</Line><Method>install</Method></Frame><Frame><File>/home/joeblow/buildout-cache/eggs/zc.recipe.cmmi-1.3.4-py2.6.egg/zc/recipe/cmmi/__init__.py</File><Line>182</Line><Method>build</Method></Frame><Frame><File>/home/joeblow/buildout-cache/eggs/zc.recipe.cmmi-1.3.4-py2.6.egg/zc/recipe/cmmi/__init__.py</File><Line>208</Line><Method>cmmi</Method></Frame><Frame><File>/home/joeblow/buildout-cache/eggs/zc.recipe.cmmi-1.3.4-py2.6.egg/zc/recipe/cmmi/__init__.py</File><Line>31</Line><Method>system</Method></Frame></Stack></Post><Post><PostId>9919686</PostId><Url>http://stackoverflow.com/questions/9919686</Url><Stack><Type>SystemError</Type><Message>gstrs was called with invalid arguments</Message><Frame><File>pyshell#70</File><Line>1</Line><Method>module</Method></Frame><Frame><File>pyshell#55</File><Line>1</Line><Method>module</Method></Frame></Stack></Post><Post><PostId>9919686</PostId><Url>http://stackoverflow.com/questions/9919686</Url><Stack><Type>SystemError</Type><Message>gstrs was called with invalid arguments</Message><Frame><File>pyshell#70</File><Line>1</Line><Method>module</Method></Frame><Frame><File>pyshell#55</File><Line>1</Line><Method>module</Method></Frame></Stack></Post><Post><PostId>10557857</PostId><Url>http://stackoverflow.com/questions/10557857</Url><Stack><Type>SystemError</Type><Message>Cannot compile 'Python.h'. Perhaps you need to install python-dev|python-devel.</Message><Frame><File>setup.py</File><Line>214</Line><Method>module</Method></Frame><Frame><File>setup.py</File><Line>207</Line><Method>setup_package</Method></Frame><Frame><File>/Users/adammcnicol/Downloads/numpy-1.6.2rc1/build/py3k/numpy/distutils/core.py</File><Line>186</Line><Method>setup</Method></Frame><Frame><File>/Library/Frameworks/Python.framework/Versions/3.2/lib/python3.2/distutils/core.py</File><Line>148</Line><Method>setup</Method></Frame><Frame><File>/Library/Frameworks/Python.framework/Versions/3.2/lib/python3.2/distutils/dist.py</File><Line>917</Line><Method>run_commands</Method></Frame><Frame><File>/Library/Frameworks/Python.framework/Versions/3.2/lib/python3.2/distutils/dist.py</File><Line>936</Line><Method>run_command</Method></Frame><Frame><File>/Users/adammcnicol/Downloads/numpy-1.6.2rc1/build/py3k/numpy/distutils/command/build.py</File><Line>37</Line><Method>run</Method></Frame><Frame><File>/Library/Frameworks/Python.framework/Versions/3.2/lib/python3.2/distutils/command/build.py</File><Line>126</Line><Method>run</Method></Frame><Frame><File>/Library/Frameworks/Python.framework/Versions/3.2/lib/python3.2/distutils/cmd.py</File><Line>313</Line><Method>run_command</Method></Frame><Frame><File>/Library/Frameworks/Python.framework/Versions/3.2/lib/python3.2/distutils/dist.py</File><Line>936</Line><Method>run_command</Method></Frame><Frame><File>/Users/adammcnicol/Downloads/numpy-1.6.2rc1/build/py3k/numpy/distutils/command/build_src.py</File><Line>152</Line><Method>run</Method></Frame><Frame><File>/Users/adammcnicol/Downloads/numpy-1.6.2rc1/build/py3k/numpy/distutils/command/build_src.py</File><Line>169</Line><Method>build_sources</Method></Frame><Frame><File>/Users/adammcnicol/Downloads/numpy-1.6.2rc1/build/py3k/numpy/distutils/command/build_src.py</File><Line>328</Line><Method>build_extension_sources</Method></Frame><Frame><File>/Users/adammcnicol/Downloads/numpy-1.6.2rc1/build/py3k/numpy/distutils/command/build_src.py</File><Line>385</Line><Method>generate_sources</Method></Frame><Frame><File>numpy/core/setup.py</File><Line>410</Line><Method>generate_config_h</Method></Frame><Frame><File>numpy/core/setup.py</File><Line>41</Line><Method>check_types</Method></Frame><Frame><File>numpy/core/setup.py</File><Line>271</Line><Method>check_types</Method></Frame></Stack></Post><Post><PostId>12468835</PostId><Url>http://stackoverflow.com/questions/12468835</Url><Stack><Type>SystemError</Type><Message>dynamic module not initialized properly</Message><Frame><File>test.py</File><Line>3</Line><Method>module</Method></Frame></Stack></Post><Post><PostId>13023111</PostId><Url>http://stackoverflow.com/questions/13023111</Url><Stack><Type>SystemError</Type><Message>MySQLError("Can't connect to MySQL server on '127.0.0.1' (10061) (code 2003)"): error calling Python module function DbMySQLFE.connect</Message><Frame><File>C:\Program Files (x86)\MySQL\MySQL Workbench 5.2 CE\workbench\wizard_progress_page_widget.py</File><Line>65</Line><Method>run</Method></Frame><Frame><File>C:\Program Files (x86)\MySQL\MySQL Workbench 5.2 CE\modules\migration_source_selection.py</File><Line>450</Line><Method>task_test_target</Method></Frame><Frame><File>C:\Program Files (x86)\MySQL\MySQL Workbench 5.2 CE\workbench\wizard_progress_page_widget.py</File><Line>543</Line><Method>update_status</Method></Frame><Frame><File>C:\Program Files (x86)\MySQL\MySQL Workbench 5.2 CE\workbench\wizard_progress_page_widget.py</File><Line>80</Line><Method>run</Method></Frame></Stack></Post><Post><PostId>13023111</PostId><Url>http://stackoverflow.com/questions/13023111</Url><Stack><Type>SystemError</Type><Message>MySQLError("Can't connect to MySQL server on '127.0.0.1' (10061) (code 2003)"): error calling Python module function DbMySQLFE.connect</Message><Frame><File>C:\Program Files (x86)\MySQL\MySQL Workbench 5.2 CE\workbench\wizard_progress_page_widget.py</File><Line>65</Line><Method>run</Method></Frame><Frame><File>C:\Program Files (x86)\MySQL\MySQL Workbench 5.2 CE\modules\migration_source_selection.py</File><Line>450</Line><Method>task_test_target</Method></Frame><Frame><File>C:\Program Files (x86)\MySQL\MySQL Workbench 5.2 CE\workbench\wizard_progress_page_widget.py</File><Line>543</Line><Method>update_status</Method></Frame><Frame><File>C:\Program Files (x86)\MySQL\MySQL Workbench 5.2 CE\workbench\wizard_progress_page_widget.py</File><Line>80</Line><Method>run</Method></Frame></Stack></Post><Post><PostId>13403798</PostId><Url>http://stackoverflow.com/questions/13403798</Url><Stack><Type>SystemError</Type><Message>Cannot compile 'Python.h'. Perhaps you need to install python-dev|python-devel.</Message><Frame><File>setup.py</File><Line>214</Line><Method>module</Method></Frame><Frame><File>setup.py</File><Line>207</Line><Method>setup_package</Method></Frame><Frame><File>/Users/eric/Desktop/numpy-1.7.0b2/build/py3k/numpy/distutils/core.py</File><Line>186</Line><Method>setup</Method></Frame><Frame><File>/Library/Frameworks/Python.framework/Versions/3.2/lib/python3.2/distutils/core.py</File><Line>148</Line><Method>setup</Method></Frame><Frame><File>/Library/Frameworks/Python.framework/Versions/3.2/lib/python3.2/distutils/dist.py</File><Line>917</Line><Method>run_commands</Method></Frame><Frame><File>/Library/Frameworks/Python.framework/Versions/3.2/lib/python3.2/distutils/dist.py</File><Line>936</Line><Method>run_command</Method></Frame><Frame><File>/Users/eric/Desktop/numpy-1.7.0b2/build/py3k/numpy/distutils/command/build.py</File><Line>37</Line><Method>run</Method></Frame><Frame><File>/Library/Frameworks/Python.framework/Versions/3.2/lib/python3.2/distutils/command/build.py</File><Line>126</Line><Method>run</Method></Frame><Frame><File>/Library/Frameworks/Python.framework/Versions/3.2/lib/python3.2/distutils/cmd.py</File><Line>313</Line><Method>run_command</Method></Frame><Frame><File>/Library/Frameworks/Python.framework/Versions/3.2/lib/python3.2/distutils/dist.py</File><Line>936</Line><Method>run_command</Method></Frame><Frame><File>/Users/eric/Desktop/numpy-1.7.0b2/build/py3k/numpy/distutils/command/build_src.py</File><Line>152</Line><Method>run</Method></Frame><Frame><File>/Users/eric/Desktop/numpy-1.7.0b2/build/py3k/numpy/distutils/command/build_src.py</File><Line>169</Line><Method>build_sources</Method></Frame><Frame><File>/Users/eric/Desktop/numpy-1.7.0b2/build/py3k/numpy/distutils/command/build_src.py</File><Line>328</Line><Method>build_extension_sources</Method></Frame><Frame><File>/Users/eric/Desktop/numpy-1.7.0b2/build/py3k/numpy/distutils/command/build_src.py</File><Line>385</Line><Method>generate_sources</Method></Frame><Frame><File>numpy/core/setup.py</File><Line>410</Line><Method>generate_config_h</Method></Frame><Frame><File>numpy/core/setup.py</File><Line>41</Line><Method>check_types</Method></Frame><Frame><File>numpy/core/setup.py</File><Line>271</Line><Method>check_types</Method></Frame></Stack></Post><Post><PostId>14633695</PostId><Url>http://stackoverflow.com/questions/14633695</Url><Stack><Type>SystemError</Type><Message>dynamic module not initialized properly</Message><Frame><File>pyshell#2</File><Line>1</Line><Method>module</Method></Frame></Stack></Post><Post><PostId>15460706</PostId><Url>http://stackoverflow.com/questions/15460706</Url><Stack><Type>SystemError</Type><Message>NULL object passed to Py_BuildValue</Message><Frame><File>C:\Python27\lib\lib-tk\Tkinter.py</File><Line>1410</Line><Method>__call__</Method></Frame><Frame><File>C:\Python27\lib\lib-tk\Tkinter.py</File><Line>495</Line><Method>callit</Method></Frame><Frame><File>C:\...\cv2_cam_v8.py</File><Line>20</Line><Method>update_video</Method></Frame></Stack></Post><Post><PostId>15924353</PostId><Url>http://stackoverflow.com/questions/15924353</Url><Stack><Type>SystemError</Type><Message>NULL result without error in PyObject_Call</Message><Frame><File>start.py</File><Line>15</Line><Method>module</Method></Frame><Frame><File>/tmp/sandbox/gmarie/gmarie/marie/eventbot.py</File><Line>41</Line><Method>__init__</Method></Frame><Frame><File>/tmp/sandbox/gmarie/venv/lib/python2.7/site-packages/redish/client.py</File><Line>196</Line><Method>__getitem__</Method></Frame><Frame><File>/tmp/sandbox/gmarie/venv/lib/python2.7/site-packages/redis/client.py</File><Line>551</Line><Method>get</Method></Frame><Frame><File>/tmp/sandbox/gmarie/venv/lib/python2.7/site-packages/redis/client.py</File><Line>360</Line><Method>execute_command</Method></Frame><Frame><File>/tmp/sandbox/gmarie/venv/lib/python2.7/site-packages/redis/connection.py</File><Line>301</Line><Method>send_command</Method></Frame><Frame><File>/tmp/sandbox/gmarie/venv/lib/python2.7/site-packages/redis/connection.py</File><Line>283</Line><Method>send_packed_command</Method></Frame><Frame><File>/tmp/sandbox/gmarie/venv/lib/python2.7/site-packages/redis/connection.py</File><Line>228</Line><Method>connect</Method></Frame><Frame><File>/tmp/sandbox/gmarie/venv/lib/python2.7/site-packages/redis/connection.py</File><Line>240</Line><Method>_connect</Method></Frame><Frame><File>/tmp/sandbox/gmarie/venv/lib/python2.7/site-packages/gevent/socket.py</File><Line>376</Line><Method>connect</Method></Frame><Frame><File>/tmp/sandbox/gmarie/venv/lib/python2.7/site-packages/gevent/socket.py</File><Line>215</Line><Method>wait_readwrite</Method></Frame><Frame><File>/tmp/sandbox/gmarie/venv/lib/python2.7/site-packages/gevent/hub.py</File><Line>164</Line><Method>switch</Method></Frame></Stack></Post><Post><PostId>16071423</PostId><Url>http://stackoverflow.com/questions/16071423</Url><Stack><Type>SystemError</Type><Message>../Objects/stringobject.c:3899: bad argument to internal function</Message><Frame><File>prop_keys.py</File><Line>34</Line><Method>module</Method></Frame><Frame><File>/usr/lib/python2.7/dist-packages/scipy/io/matlab/mio.py</File><Line>175</Line><Method>loadmat</Method></Frame><Frame><File>/usr/lib/python2.7/dist-packages/scipy/io/matlab/mio5.py</File><Line>272</Line><Method>get_variables</Method></Frame><Frame><File>/usr/lib/python2.7/dist-packages/scipy/io/matlab/mio5.py</File><Line>224</Line><Method>read_var_header</Method></Frame></Stack></Post><Post><PostId>16073995</PostId><Url>http://stackoverflow.com/questions/16073995</Url><Stack><Type>SystemError</Type><Message>new style getargs format but argument is not a tuple</Message><Frame><File>mymodtest.py</File><Line>10</Line><Method>module</Method></Frame></Stack></Post><Post><PostId>16189784</PostId><Url>http://stackoverflow.com/questions/16189784</Url><Stack><Type>SystemError</Type><Message>ProgrammingError("('42P01', '[42P01] ERROR: no existe la relaci\xc3\xb3n \xc2\xabpublic.idtipodatos\xc2\xbb;\nError while executing the query (7) (SQLExecDirectW)')"): error calling Python module function DbPostgresqlRE.reverseEngineer</Message><Frame><File>/usr/share/mysql-workbench/libraries/workbench/wizard_progress_page_widget.py</File><Line>192</Line><Method>thread_work</Method></Frame><Frame><File>/usr/lib/mysql-workbench/modules/migration_schema_selection.py</File><Line>160</Line><Method>task_reveng</Method></Frame><Frame><File>/usr/lib/mysql-workbench/modules/migration.py</File><Line>332</Line><Method>reverseEngineer</Method></Frame></Stack></Post><Post><PostId>16326793</PostId><Url>http://stackoverflow.com/questions/16326793</Url><Stack><Type>SystemError</Type><Message>Negative size passed to PyString_FromStringAndSize</Message><Frame><File>test_shelve.py</File><Line>27</Line><Method>module</Method></Frame><Frame><File>/System/Library/Frameworks/Python.framework/Versions/2.7/lib/python2.7/shelve.py</File><Line>101</Line><Method>keys</Method></Frame></Stack></Post><Post><PostId>16637765</PostId><Url>http://stackoverflow.com/questions/16637765</Url><Stack><Type>SystemError</Type><Message>../Objects/tupleobject.c:142: bad argument to internal function</Message><Frame><File>/var/www/site/environ/local/lib/python2.7/site-packages/django/core/handlers/wsgi.py</File><Line>240</Line><Method>__call__</Method></Frame></Stack></Post><Post><PostId>17313677</PostId><Url>http://stackoverflow.com/questions/17313677</Url><Stack><Type>SystemError</Type><Message>com_backpatch: offset too large</Message><Frame><File>C:\Python24\lib\lib-tk\Tkinter.py</File><Line>1345</Line><Method>__call__</Method></Frame><Frame><File>C:\Python24\lib\idlelib\ScriptBinding.py</File><Line>142</Line><Method>run_module_event</Method></Frame><Frame><File>C:\Python24\lib\idlelib\ScriptBinding.py</File><Line>101</Line><Method>checksyntax</Method></Frame></Stack></Post><Post><PostId>17902741</PostId><Url>http://stackoverflow.com/questions/17902741</Url><Stack><Type>SystemError</Type><Message>None</Message><Frame><File>/home/alienone/Programming/Python/OSINT/MANDIANTAPT/spitball.py</File><Line>63</Line><Method>main()</Method></Frame><Frame><File>/home/alienone/Programming/Python/OSINT/MANDIANTAPT/spitball.py</File><Line>59</Line><Method>main</Method></Frame><Frame><File>/home/alienone/.pythonbrew/pythons/Python-2.7.5/lib/python2.7/site-packages/py2neo/neo4j.py</File><Line>420</Line><Method>create</Method></Frame><Frame><File>/home/alienone/.pythonbrew/pythons/Python-2.7.5/lib/python2.7/site-packages/py2neo/neo4j.py</File><Line>2123</Line><Method>submit</Method></Frame><Frame><File>/home/alienone/.pythonbrew/pythons/Python-2.7.5/lib/python2.7/site-packages/py2neo/neo4j.py</File><Line>2092</Line><Method>em submit</Method></Frame><Frame><File>/home/alienone/.pythonbrew/pythons/Python-2.7.5/lib/python2.7/site-packages/py2neo/rest.py</File><Line>428</Line><Method>_send</Method></Frame><Frame><File>/home/alienone/.pythonbrew/pythons/Python-2.7.5/lib/python2.7/site-packages/py2neo/rest.py</File><Line>365</Line><Method>send</Method></Frame><Frame><File>/home/alienone/.pythonbrew/pythons/Python-2.7.5/lib/python2.7/site-packages/py2neo/rest.py</File><Line>279</Line><Method>strong init /strong</Method></Frame></Stack></Post><Post><PostId>18442572</PostId><Url>http://stackoverflow.com/questions/18442572</Url><Stack><Type>SystemError</Type><Message>Parent module 'astropy' not loaded, cannot perform relative import</Message><Frame><File>C:\Users\Omer\AppData\Local\Enthought\Canopy\User\lib\site-packages\astr       opy\logger.py</File><Line>222</Line><Method>_excepthook</Method></Frame><Frame><File>C:\Users\Omer\AppData\Local\Enthought\Canopy\App\appdata\canopy-1.0.3.12       62.win-x86_64\lib\logging__init__.py</File><Line>1166</Line><Method>error</Method></Frame><Frame><File>C:\Users\Omer\AppData\Local\Enthought\Canopy\App\appdata\canopy-1.0.3.12       62.win-x86_64\lib\logging__init__.py</File><Line>1258</Line><Method>_log</Method></Frame><Frame><File>C:\Users\Omer\AppData\Local\Enthought\Canopy\App\appdata\canopy-1.0.3.12       62.win-x86_64\lib\logging__init__.py</File><Line>1268</Line><Method>handle</Method></Frame><Frame><File>C:\Users\Omer\AppData\Local\Enthought\Canopy\App\appdata\canopy-1.0.3.12       62.win-x86_64\lib\logging__init__.py</File><Line>1308</Line><Method>callHandlers</Method></Frame><Frame><File>C:\Users\Omer\AppData\Local\Enthought\Canopy\App\appdata\canopy-1.0.3.12       62.win-x86_64\lib\logging__init__.py</File><Line>748</Line><Method>handle</Method></Frame><Frame><File>C:\Users\Omer\AppData\Local\Enthought\Canopy\User\lib\site-packages\astr       opy\logger.py</File><Line>339</Line><Method>_stream_formatter</Method></Frame><Frame><File>C:\Users\Omer\AppData\Local\Enthought\Canopy\User\lib\site-packages\astr       opy\utils\console.py</File><Line>230</Line><Method>color_print</Method></Frame><Frame><File>C:\Users\Omer\AppData\Local\Enthought\Canopy\User\lib\site-packages\astr       opy\config\configuration.py</File><Line>336</Line><Method>strong call /strong</Method></Frame><Frame><File>C:\Users\Omer\AppData\Local\Enthought\Canopy\User\lib\site-packages\astr       opy\config\configuration.py</File><Line>402</Line><Method>get_config</Method></Frame></Stack></Post><Post><PostId>18727530</PostId><Url>http://stackoverflow.com/questions/18727530</Url><Stack><Type>SystemError</Type><Message>/Users/sysadmin/build/v2.7.3/Objects/methodobject.c:120: bad argument to internal function</Message><Frame><File>../pink.py</File><Line>13</Line><Method>module</Method></Frame><Frame><File>imgproc.py</File><Line>51</Line><Method>imgproc.Image.__setitem__ (imgproc.c:2256)</Method></Frame></Stack></Post><Post><PostId>19844523</PostId><Url>http://stackoverflow.com/questions/19844523</Url><Stack><Type>SystemError</Type><Message>..\Objects\stringobject.c:3902: bad argument to internal function</Message><Frame><File>***</File><Line>16</Line><Method>module</Method></Frame></Stack></Post><Post><PostId>19891076</PostId><Url>http://stackoverflow.com/questions/19891076</Url><Stack><Type>SystemError</Type><Message>Parent module '' not loaded, cannot perform relative import</Message><Frame><File>6.py</File><Line>2</Line><Method>module</Method></Frame><Frame><File>6.py</File><Line>2</Line><Method>module</Method></Frame></Stack></Post><Post><PostId>19891076</PostId><Url>http://stackoverflow.com/questions/19891076</Url><Stack><Type>SystemError</Type><Message>Parent module '' not loaded, cannot perform relative import</Message><Frame><File>6.py</File><Line>2</Line><Method>module</Method></Frame><Frame><File>6.py</File><Line>2</Line><Method>module</Method></Frame></Stack></Post><Post><PostId>20437259</PostId><Url>http://stackoverflow.com/questions/20437259</Url><Stack><Type>SystemError</Type><Message>NULL result without error in PyObject_Call</Message><Frame><File>/System/Library/Frameworks/Python.framework/Versions/2.7/lib/python2.7/threading.py</File><Line>808</Line><Method>__bootstrap_inner</Method></Frame><Frame><File>/System/Library/Frameworks/Python.framework/Versions/2.7/lib/python2.7/threading.py</File><Line>761</Line><Method>run</Method></Frame><Frame><File>/System/Library/Frameworks/Python.framework/Versions/2.7/lib/python2.7/multiprocessing/pool.py</File><Line>342</Line><Method>_handle_tasks</Method></Frame></Stack></Post><Post><PostId>20482837</PostId><Url>http://stackoverflow.com/questions/20482837</Url><Stack><Type>SystemError</Type><Message>error return without exception set</Message><Frame><File>C:/Users/Dan/Desktop/a.py</File><Line>9</Line><Method>module</Method></Frame></Stack></Post><Post><PostId>20525086</PostId><Url>http://stackoverflow.com/questions/20525086</Url><Stack><Type>SystemError</Type><Message>Object reference not set to an instance of an object.</Message><Frame><File>test.py</File><Line>1</Line><Method>module</Method></Frame><Frame><File>test.py</File><Line>8</Line><Method>Test</Method></Frame></Stack></Post><Post><PostId>21172550</PostId><Url>http://stackoverflow.com/questions/21172550</Url><Stack><Type>SystemError</Type><Message>..\Objects\longobject.c:980: bad argument to internal function</Message><Frame><File>Parser.py</File><Line>1893</Line><Method>module</Method></Frame><Frame><File>Parser.py</File><Line>1864</Line><Method>main</Method></Frame><Frame><File>Parser.py</File><Line>1411</Line><Method>Parse</Method></Frame><Frame><File>Parser.py</File><Line>1554</Line><Method>ParseField</Method></Frame><Frame><File>C:\Users\dpitch40\Documents\Local Sandbox\main\BRANCHES\PARSER3\tools\integrated\Parser\DFiles\Result.py</File><Line>1503</Line><Method>CalcAggStat</Method></Frame></Stack></Post><Post><PostId>21325095</PostId><Url>http://stackoverflow.com/questions/21325095</Url><Stack><Type>SystemError</Type><Message>Cannot locate working compiler</Message><Frame><File>setup.py</File><Line>487</Line><Method>module</Method></Frame><Frame><File>/Library/Frameworks/Python.framework/Versions/2.7/lib/python2.7/distutils/core.py</File><Line>152</Line><Method>setup</Method></Frame><Frame><File>/Library/Frameworks/Python.framework/Versions/2.7/lib/python2.7/distutils/dist.py</File><Line>953</Line><Method>run_commands</Method></Frame><Frame><File>/Library/Frameworks/Python.framework/Versions/2.7/lib/python2.7/distutils/dist.py</File><Line>972</Line><Method>run_command</Method></Frame><Frame><File>/Library/Frameworks/Python.framework/Versions/2.7/lib/python2.7/distutils/command/install.py</File><Line>563</Line><Method>run</Method></Frame><Frame><File>/Library/Frameworks/Python.framework/Versions/2.7/lib/python2.7/distutils/cmd.py</File><Line>326</Line><Method>run_command</Method></Frame><Frame><File>/Library/Frameworks/Python.framework/Versions/2.7/lib/python2.7/distutils/dist.py</File><Line>972</Line><Method>run_command</Method></Frame><Frame><File>/Library/Frameworks/Python.framework/Versions/2.7/lib/python2.7/distutils/command/build.py</File><Line>127</Line><Method>run</Method></Frame><Frame><File>/Library/Frameworks/Python.framework/Versions/2.7/lib/python2.7/distutils/cmd.py</File><Line>326</Line><Method>run_command</Method></Frame><Frame><File>/Library/Frameworks/Python.framework/Versions/2.7/lib/python2.7/distutils/dist.py</File><Line>972</Line><Method>run_command</Method></Frame><Frame><File>/Library/Frameworks/Python.framework/Versions/2.7/lib/python2.7/distutils/command/build_ext.py</File><Line>307</Line><Method>run</Method></Frame><Frame><File>/Library/Frameworks/Python.framework/Versions/2.7/lib/python2.7/distutils/sysconfig.py</File><Line>170</Line><Method>customize_compiler</Method></Frame><Frame><File>/Library/Frameworks/Python.framework/Versions/2.7/lib/python2.7/_osx_support.py</File><Line>418</Line><Method>customize_compiler</Method></Frame><Frame><File>/Library/Frameworks/Python.framework/Versions/2.7/lib/python2.7/_osx_support.py</File><Line>191</Line><Method>_find_appropriate_compiler</Method></Frame></Stack></Post><Post><PostId>22180903</PostId><Url>http://stackoverflow.com/questions/22180903</Url><Stack><Type>SystemError</Type><Message>MemoryError(""): error calling Python module function DbMssqlRE.reverseEngineer</Message><Frame><File>/usr/share/mysql-workbench/libraries/workbench/wizard_progress_page_widget.py</File><Line>192</Line><Method>thread_work</Method></Frame><Frame><File>/usr/lib64/mysql-workbench/modules/migration_schema_selection.py</File><Line>160</Line><Method>task_reveng</Method></Frame><Frame><File>/usr/lib64/mysql-workbench/modules/migration.py</File><Line>353</Line><Method>reverseEngineer</Method></Frame></Stack></Post><Post><PostId>22205043</PostId><Url>http://stackoverflow.com/questions/22205043</Url><Stack><Type>SystemError</Type><Message>new style getargs format but argument is not a tuple</Message><Frame><File>proofer.py</File><Line>295</Line><Method>module</Method></Frame><Frame><File>proofer.py</File><Line>286</Line><Method>main</Method></Frame><Frame><File>proofer.py</File><Line>170</Line><Method>composite1</Method></Frame><Frame><File>/Library/Python/2.7/site-packages/PIL/Image.py</File><Line>1103</Line><Method>paste</Method></Frame></Stack></Post><Post><PostId>22656285</PostId><Url>http://stackoverflow.com/questions/22656285</Url><Stack><Type>SystemError</Type><Message>NULL result without error in PyObject_Call</Message><Frame><File>/usr/lib/python2.7/multiprocessing/queues.py</File><Line>266</Line><Method>_feed</Method></Frame></Stack></Post><Post><PostId>22681812</PostId><Url>http://stackoverflow.com/questions/22681812</Url><Stack><Type>SystemError</Type><Message>NULL result without error in PyObject_Call</Message><Frame><File>/usr/lib/python2.7/multiprocessing/queues.py</File><Line>266</Line><Method>_feed</Method></Frame></Stack></Post><Post><PostId>23963542</PostId><Url>http://stackoverflow.com/questions/23963542</Url><Stack><Type>SystemError</Type><Message>NULL result without error in PyObject_Call</Message><Frame><File>./svm_training.py</File><Line>185</Line><Method>module</Method></Frame><Frame><File>./svm_training.py</File><Line>63</Line><Method>main</Method></Frame><Frame><File>./svm_training.py</File><Line>85</Line><Method>gridsearch</Method></Frame><Frame><File>/usr/local/lib/python2.7/dist-packages/scikit_learn-0.14.1-py2.7-linux-    x86_64.egg/sklearn/grid_search.py</File><Line>860</Line><Method>fit</Method></Frame><Frame><File>/usr/local/lib/python2.7/dist-packages/scikit_learn-0.14.1-py2.7-linux-x86_64.egg/sklearn/grid_search.py</File><Line>493</Line><Method>_fit</Method></Frame><Frame><File>/usr/local/lib/python2.7/dist-packages/scikit_learn-0.14.1-py2.7-linux-x86_64.egg/sklearn/externals/joblib/parallel.py</File><Line>519</Line><Method>__call__</Method></Frame><Frame><File>/usr/local/lib/python2.7/dist-packages/scikit_learn-0.14.1-py2.7-linux-x86_64.egg/sklearn/externals/joblib/parallel.py</File><Line>419</Line><Method>retrieve</Method></Frame><Frame><File>/usr/lib/python2.7/multiprocessing/pool.py</File><Line>558</Line><Method>get</Method></Frame></Stack></Post><Post><PostId>24613755</PostId><Url>http://stackoverflow.com/questions/24613755</Url><Stack><Type>SystemError</Type><Message>ProgrammingError("('42S22', "[42S22] [Sybase]</Message><Frame><File>C:\Program Files\MySQL\MySQL Workbench CE 6.1.7\workbench\wizard_progress_page_widget.py</File><Line>192</Line><Method>thread_work</Method></Frame><Frame><File>C:\Program Files\MySQL\MySQL Workbench CE 6.1.7\modules\migration_schema_selection.py</File><Line>162</Line><Method>task_reveng</Method></Frame><Frame><File>C:\Program Files\MySQL\MySQL Workbench CE 6.1.7\modules\migration.py</File><Line>351</Line><Method>reverseEngineer</Method></Frame></Stack></Post><Post><PostId>24653249</PostId><Url>http://stackoverflow.com/questions/24653249</Url><Stack><Type>SystemError</Type><Message>Parent module '' not loaded, cannot perform relative import</Message><Frame><File>C:\Python34\lib\site-packages\sphinx-1.3a0dev_20140708-py3.4.egg\sphinx\ext\autodoc.py</File><Line>368</Line><Method>import_object</Method></Frame><Frame><File>Orpheus.pyx</File><Line>1</Line><Method>init Orpheus.Orpheus (Orpheus\Orpheus.c:3370)</Method></Frame><Frame><File>C:\Python34\lib\site-packages\sphinx-1.3a0dev_20140708-py3.4.egg\sphinx\ext\autodoc.py</File><Line>368</Line><Method>import_object</Method></Frame><Frame><File>Orpheus.pyx</File><Line>1</Line><Method>init Orpheus.Orpheus (Orpheus\Orpheus.c:3370)</Method></Frame></Stack></Post><Post><PostId>24653249</PostId><Url>http://stackoverflow.com/questions/24653249</Url><Stack><Type>SystemError</Type><Message>Parent module '' not loaded, cannot perform relative import</Message><Frame><File>C:\Python34\lib\site-packages\sphinx-1.3a0dev_20140708-py3.4.egg\sphinx\ext\autodoc.py</File><Line>368</Line><Method>import_object</Method></Frame><Frame><File>Orpheus.pyx</File><Line>1</Line><Method>init Orpheus.Orpheus (Orpheus\Orpheus.c:3370)</Method></Frame><Frame><File>C:\Python34\lib\site-packages\sphinx-1.3a0dev_20140708-py3.4.egg\sphinx\ext\autodoc.py</File><Line>368</Line><Method>import_object</Method></Frame><Frame><File>Orpheus.pyx</File><Line>1</Line><Method>init Orpheus.Orpheus (Orpheus\Orpheus.c:3370)</Method></Frame></Stack></Post><Post><PostId>24657190</PostId><Url>http://stackoverflow.com/questions/24657190</Url><Stack><Type>SystemError</Type><Message>None</Message><Frame><File>test.py</File><Line>36</Line><Method>module</Method></Frame><Frame><File>/usr/lib/python2.6/site-packages/py2neo/neo4j.py</File><Line>2116</Line><Method>submit</Method></Frame><Frame><File>/usr/lib/python2.6/site-packages/py2neo/neo4j.py</File><Line>2085</Line><Method>_submit</Method></Frame><Frame><File>/usr/lib/python2.6/site-packages/py2neo/rest.py</File><Line>427</Line><Method>_send</Method></Frame><Frame><File>/usr/lib/python2.6/site-packages/py2neo/rest.py</File><Line>364</Line><Method>send</Method></Frame><Frame><File>/usr/lib/python2.6/site-packages/py2neo/rest.py</File><Line>278</Line><Method>__init__</Method></Frame></Stack></Post><Post><PostId>24895087</PostId><Url>http://stackoverflow.com/questions/24895087</Url><Stack><Type>SystemError</Type><Message>MySQLError("Can't connect to MySQL server on '127.0.0.1' (10061) (code 2003)"): error calling Python module function DbMySQLFE.connect</Message><Frame><File>C:\Program Files (x86)\MySQL\MySQL Workbench 6.1     CE\workbench\wizard_progress_page_widget.py</File><Line>66</Line><Method>run</Method></Frame><Frame><File>C:\Program Files (x86)\MySQL\MySQL Workbench 6.1 CE\modules\migration_source_selection.py</File><Line>461</Line><Method>task_test_target</Method></Frame></Stack></Post><Post><PostId>25334148</PostId><Url>http://stackoverflow.com/questions/25334148</Url><Stack><Type>SystemError</Type><Message>Unsupported platform: linux</Message><Frame><File>/usr/local/bin/buildozer</File><Line>9</Line><Method>module</Method></Frame><Frame><File>/usr/local/lib/python3.4/dist-packages/buildozer/scripts/client.py</File><Line>13</Line><Method>main</Method></Frame><Frame><File>/usr/local/lib/python3.4/dist-packages/buildozer/__init__.py</File><Line>957</Line><Method>run_command</Method></Frame><Frame><File>/usr/local/lib/python3.4/dist-packages/buildozer/target.py</File><Line>85</Line><Method>run_commands</Method></Frame><Frame><File>/usr/local/lib/python3.4/dist-packages/buildozer/target.py</File><Line>95</Line><Method>cmd_debug</Method></Frame><Frame><File>/usr/local/lib/python3.4/dist-packages/buildozer/__init__.py</File><Line>157</Line><Method>prepare_for_build</Method></Frame><Frame><File>/usr/local/lib/python3.4/dist-packages/buildozer/targets/android.py</File><Line>365</Line><Method>install_platform</Method></Frame><Frame><File>/usr/local/lib/python3.4/dist-packages/buildozer/targets/android.py</File><Line>235</Line><Method>_install_android_sdk</Method></Frame></Stack></Post><Post><PostId>25418015</PostId><Url>http://stackoverflow.com/questions/25418015</Url><Stack><Type>SystemError</Type><Message>UnicodeDecodeError("'utf16' codec can't decode byte 0x2e in position 160: truncated data"): error calling Python module function DbMssqlRE.reverseEngineer</Message><Frame><File>C:\Program Files (x86)\MySQL\MySQL Workbench 6.1 CE\modules\db_mssql_grt.py</File><Line>385</Line><Method>reverseEngineer</Method></Frame><Frame><File>C:\Program Files (x86)\MySQL\MySQL Workbench 6.1 CE\modules\db_mssql_grt.py</File><Line>546</Line><Method>reverseEngineerTables</Method></Frame><Frame><File>C:\Program Files (x86)\MySQL\MySQL Workbench 6.1 CE\modules\db_mssql_grt.py</File><Line>131</Line><Method>lambda</Method></Frame><Frame><File>C:\Program Files (x86)\MySQL\MySQL Workbench 6.1 CE\Python\Lib\encodings\utf_16.py</File><Line>16</Line><Method>decode</Method></Frame><Frame><File>C:\Program Files (x86)\MySQL\MySQL Workbench 6.1 CE\workbench\wizard_progress_page_widget.py</File><Line>192</Line><Method>thread_work</Method></Frame><Frame><File>C:\Program Files (x86)\MySQL\MySQL Workbench 6.1 CE\modules\migration_schema_selection.py</File><Line>162</Line><Method>task_reveng</Method></Frame><Frame><File>C:\Program Files (x86)\MySQL\MySQL Workbench 6.1 CE\modules\migration.py</File><Line>351</Line><Method>reverseEngineer</Method></Frame></Stack></Post><Post><PostId>25418015</PostId><Url>http://stackoverflow.com/questions/25418015</Url><Stack><Type>SystemError</Type><Message>UnicodeDecodeError("'utf16' codec can't decode byte 0x2e in position 160: truncated data"): error calling Python module function DbMssqlRE.reverseEngineer</Message><Frame><File>C:\Program Files (x86)\MySQL\MySQL Workbench 6.1 CE\modules\db_mssql_grt.py</File><Line>385</Line><Method>reverseEngineer</Method></Frame><Frame><File>C:\Program Files (x86)\MySQL\MySQL Workbench 6.1 CE\modules\db_mssql_grt.py</File><Line>546</Line><Method>reverseEngineerTables</Method></Frame><Frame><File>C:\Program Files (x86)\MySQL\MySQL Workbench 6.1 CE\modules\db_mssql_grt.py</File><Line>131</Line><Method>lambda</Method></Frame><Frame><File>C:\Program Files (x86)\MySQL\MySQL Workbench 6.1 CE\Python\Lib\encodings\utf_16.py</File><Line>16</Line><Method>decode</Method></Frame><Frame><File>C:\Program Files (x86)\MySQL\MySQL Workbench 6.1 CE\workbench\wizard_progress_page_widget.py</File><Line>192</Line><Method>thread_work</Method></Frame><Frame><File>C:\Program Files (x86)\MySQL\MySQL Workbench 6.1 CE\modules\migration_schema_selection.py</File><Line>162</Line><Method>task_reveng</Method></Frame><Frame><File>C:\Program Files (x86)\MySQL\MySQL Workbench 6.1 CE\modules\migration.py</File><Line>351</Line><Method>reverseEngineer</Method></Frame></Stack></Post><Post><PostId>25440665</PostId><Url>http://stackoverflow.com/questions/25440665</Url><Stack><Type>SystemError</Type><Message>E:Opening configuration file /etc/apt/apt.conf.d/02proxy - ifstream::ifstream (13: Permission denied)</Message><Frame><File>/usr/lib/python3/dist-packages/apport_python_hook.py</File><Line>63</Line><Method>apport_excepthook</Method></Frame><Frame><File>/usr/lib/python3/dist-packages/apport/__init__.py</File><Line>5</Line><Method>module</Method></Frame><Frame><File>/usr/lib/python3/dist-packages/apport/report.py</File><Line>30</Line><Method>module</Method></Frame><Frame><File>/usr/lib/python3/dist-packages/apport/fileutils.py</File><Line>23</Line><Method>module</Method></Frame><Frame><File>/usr/lib/python3/dist-packages/apport/packaging_impl.py</File><Line>20</Line><Method>module</Method></Frame><Frame><File>/usr/lib/python3/dist-packages/apt/__init__.py</File><Line>34</Line><Method>module</Method></Frame></Stack></Post></Posts>