<?xml version="1.0" encoding="UTF-8"?><Posts><Post><PostId>845926</PostId><Url>http://stackoverflow.com/questions/845926</Url><Stack><Type>WindowsError</Type><Message>[Error 123] The filename, directory name, or</Message><Frame><File>pyshell#6</File><Line>1</Line><Method>module</Method></Frame></Stack></Post><Post><PostId>912830</PostId><Url>http://stackoverflow.com/questions/912830</Url><Stack><Type>WindowsError</Type><Message>[Error 193] %1 is not a valid Win32 application</Message><Frame><File>test_functional.py</File><Line>91</Line><Method>test_functional</Method></Frame><Frame><File>test_functional.py</File><Line>49</Line><Method>tvnamerifiy</Method></Frame><Frame><File>C:\Python26\lib\subprocess.py</File><Line>595</Line><Method>__init__</Method></Frame><Frame><File>C:\Python26\lib\subprocess.py</File><Line>804</Line><Method>_execute_child</Method></Frame></Stack></Post><Post><PostId>1845650</PostId><Url>http://stackoverflow.com/questions/1845650</Url><Stack><Type>WindowsError</Type><Message>[Error 5] Access is denied</Message><Frame><File>C:\Users\SuperUser\SwitchPy.py</File><Line>30</Line><Method>module</Method></Frame></Stack></Post><Post><PostId>2285086</PostId><Url>http://stackoverflow.com/questions/2285086</Url><Stack><Type>WindowsError</Type><Message>[Error 3] The system cannot find the path specified: 'src\\html5lib/*.*'</Message><Frame><File>C:\Users\Junior\Downloads\Python\html5lib-0.90\setup.py</File><Line>36</Line><Method>module</Method></Frame></Stack></Post><Post><PostId>2381241</PostId><Url>http://stackoverflow.com/questions/2381241</Url><Stack><Type>WindowsError</Type><Message>[Error 206] The filename or extension is too long</Message><Frame><File>dump_output_sopuids.py</File><Line>68</Line><Method>module</Method></Frame><Frame><File>dump_output_sopuids.py</File><Line>41</Line><Method>create_sopuid_to_path_dict_dcmdump</Method></Frame><Frame><File>c:\python26\lib\subprocess.py</File><Line>621</Line><Method>__init__</Method></Frame><Frame><File>c:\python26\lib\subprocess.py</File><Line>830</Line><Method>_execute_child</Method></Frame></Stack></Post><Post><PostId>2426262</PostId><Url>http://stackoverflow.com/questions/2426262</Url><Stack><Type>WindowsError</Type><Message>[Error 14001] This application has failed to start because the application configuration is incorrect. Reinstalling the application may fix this problem</Message><Frame><File>C:\Python26\Scripts\virtualenv-script.py</File><Line>8</Line><Method>load_entry_point('virtualenv==1.4.5', 'console_scripts', 'virtualenv')()</Method></Frame><Frame><File>C:\Python26\lib\site-packages\virtualenv-1.4.5-py2.6.egg\virtualenv.py</File><Line>529</Line><Method>main</Method></Frame><Frame><File>C:\Python26\lib\site-packages\virtualenv-1.4.5-py2.6.egg\virtualenv.py</File><Line>612</Line><Method>create_environment</Method></Frame><Frame><File>C:\Python26\lib\site-packages\virtualenv-1.4.5-py2.6.egg\virtualenv.py</File><Line>837</Line><Method>install_python</Method></Frame><Frame><File>C:\Python26\lib\subprocess.py</File><Line>621</Line><Method>__init__</Method></Frame><Frame><File>C:\Python26\lib\subprocess.py</File><Line>830</Line><Method>_execute_child</Method></Frame></Stack></Post><Post><PostId>2454381</PostId><Url>http://stackoverflow.com/questions/2454381</Url><Stack><Type>WindowsError</Type><Message>[Error 2] The system cannot find the file specified</Message><Frame><File>mercurial\dispatch.pyc</File><Line>47</Line><Method>_runcatch</Method></Frame><Frame><File>mercurial\dispatch.pyc</File><Line>466</Line><Method>_dispatch</Method></Frame><Frame><File>mercurial\dispatch.pyc</File><Line>336</Line><Method>runcommand</Method></Frame><Frame><File>mercurial\dispatch.pyc</File><Line>517</Line><Method>_runcommand</Method></Frame><Frame><File>mercurial\dispatch.pyc</File><Line>471</Line><Method>checkargs</Method></Frame><Frame><File>mercurial\dispatch.pyc</File><Line>465</Line><Method>lambda</Method></Frame><Frame><File>mercurial\util.pyc</File><Line>401</Line><Method>check</Method></Frame><Frame><File>mercurial\commands.pyc</File><Line>708</Line><Method>commit</Method></Frame><Frame><File>mercurial\cmdutil.pyc</File><Line>1150</Line><Method>commit</Method></Frame><Frame><File>mercurial\commands.pyc</File><Line>706</Line><Method>commitfunc</Method></Frame><Frame><File>mercurial\localrepo.pyc</File><Line>836</Line><Method>commit</Method></Frame><Frame><File>mercurial\cmdutil.pyc</File><Line>1155</Line><Method>commiteditor</Method></Frame><Frame><File>mercurial\cmdutil.pyc</File><Line>1184</Line><Method>commitforceeditor</Method></Frame><Frame><File>mercurial\ui.pyc</File><Line>361</Line><Method>edit</Method></Frame><Frame><File>mercurial\util.pyc</File><Line>383</Line><Method>system</Method></Frame><Frame><File>subprocess.pyc</File><Line>470</Line><Method>call</Method></Frame><Frame><File>subprocess.pyc</File><Line>621</Line><Method>__init__</Method></Frame><Frame><File>subprocess.pyc</File><Line>830</Line><Method>_execute_child</Method></Frame></Stack></Post><Post><PostId>2468872</PostId><Url>http://stackoverflow.com/questions/2468872</Url><Stack><Type>WindowsError</Type><Message>[Error 2] Das System kann die angegebene Datei nicht finden: ['jav</Message><Frame><File>setup.py</File><Line>332</Line><Method>module</Method></Frame><Frame><File>setup.py</File><Line>289</Line><Method>main</Method></Frame></Stack></Post><Post><PostId>2852652</PostId><Url>http://stackoverflow.com/questions/2852652</Url><Stack><Type>WindowsError</Type><Message>[Error 14001] The application has failed to start because its side-by-side configuration is incorrect. Please see the application event log or use the command-line sxstrace.exe tool for more detail</Message><Frame><File>C:\users\Public\SoundLog\Code\Código Python\SoundLog\SoundLog.py</File><Line>9</Line><Method>module</Method></Frame><Frame><File>C:\users\Public\SoundLog\Code\Código Python\SoundLog\Auxiliar\DataCollection.py</File><Line>4</Line><Method>module</Method></Frame><Frame><File>C:\users\Public\SoundLog\Code\Código Python\SoundLog\Auxiliar\SoundLogDLL.py</File><Line>4</Line><Method>module</Method></Frame><Frame><File>C:\Python26\lib\ctypes\__init__.py</File><Line>431</Line><Method>LoadLibrary</Method></Frame><Frame><File>C:\Python26\lib\ctypes\__init__.py</File><Line>353</Line><Method>__init__</Method></Frame></Stack></Post><Post><PostId>2891218</PostId><Url>http://stackoverflow.com/questions/2891218</Url><Stack><Type>WindowsError</Type><Message>exception code 0xe0434f4d</Message><Frame><File>C:\Users\Public\SoundLog\Code\Código Python\SoundLog\SoundLog.py</File><Line>821</Line><Method>OnStart</Method></Frame><Frame><File>C:\Users\Public\SoundLog\Code\Código Python\SoundLog\Auxiliar\DataCollection.py</File><Line>68</Line><Method>start</Method></Frame><Frame><File>C:\Users\Public\SoundLog\Code\Código Python\SoundLog\Auxiliar\SoundLogDLL.py</File><Line>61</Line><Method>run</Method></Frame></Stack></Post><Post><PostId>3338485</PostId><Url>http://stackoverflow.com/questions/3338485</Url><Stack><Type>WindowsError</Type><Message>[Error 5] Access is denied: '.\\OtherFiles'</Message><Frame><File>C:\Documents and Settings\nlesniewski\Desktop\downloadData.py</File><Line>281</Line><Method>module</Method></Frame><Frame><File>C:\Documents and Settings\nlesniewski\Desktop\downloadData.py</File><Line>273</Line><Method>main</Method></Frame><Frame><File>C:\Documents and Settings\nlesniewski\Desktop\extractAndParse.py</File><Line>147</Line><Method>main</Method></Frame><Frame><File>C:\Documents and Settings\nlesniewski\Desktop\extractAndParse.py</File><Line>133</Line><Method>extractGPGs</Method></Frame><Frame><File>C:\Python25\Lib\site-packages\gnupg.py</File><Line>574</Line><Method>decrypt_file</Method></Frame></Stack></Post><Post><PostId>3479385</PostId><Url>http://stackoverflow.com/questions/3479385</Url><Stack><Type>WindowsError</Type><Message>[Error 2] The system cannot find the file specified</Message><Frame><File>foo.py</File><Line>25</Line><Method>module</Method></Frame></Stack></Post><Post><PostId>3685111</PostId><Url>http://stackoverflow.com/questions/3685111</Url><Stack><Type>WindowsError</Type><Message>[Error 2] The system cannot find the file specified</Message><Frame><File>C:\Documents and Settings\Desktop\MySQL-python-1.2.3\setup.py</File><Line>15</Line><Method>module</Method></Frame><Frame><File>C:\Documents and Settings\Desktop\MySQL-python-1.2.3\setup_windows.py</File><Line>7</Line><Method>get_config</Method></Frame></Stack></Post><Post><PostId>4147438</PostId><Url>http://stackoverflow.com/questions/4147438</Url><Stack><Type>WindowsError</Type><Message>[Error 2] The system cannot find the file specified</Message><Frame><File>pyshell#10</File><Line>1</Line><Method>module</Method></Frame><Frame><File>C:\Users\B\Desktop\dTask.py</File><Line>19</Line><Method>dTask</Method></Frame></Stack></Post><Post><PostId>4609572</PostId><Url>http://stackoverflow.com/questions/4609572</Url><Stack><Type>WindowsError</Type><Message>[Error 5] Access is denied: 'prep_dat'</Message><Frame><File>run_pnoise.py</File><Line>167</Line><Method>module</Method></Frame><Frame><File>run_pnoise.py</File><Line>88</Line><Method>make_dir</Method></Frame><Frame><File>c:\Program Files (x86)\Python27\lib\os.py</File><Line>157</Line><Method>makedirs</Method></Frame></Stack></Post><Post><PostId>5011379</PostId><Url>http://stackoverflow.com/questions/5011379</Url><Stack><Type>WindowsError</Type><Message>[Error 32] The process cannot access the file because it is being</Message><Frame><File>delfoo.py</File><Line>2</Line><Method>module</Method></Frame></Stack></Post><Post><PostId>5299122</PostId><Url>http://stackoverflow.com/questions/5299122</Url><Stack><Type>WindowsError</Type><Message>[Error 2] The system cannot find the file specified</Message><Frame><File>git-p4.py</File><Line>1926</Line><Method>module</Method></Frame><Frame><File>git-p4.py</File><Line>1921</Line><Method>main</Method></Frame><Frame><File>git-p4.py</File><Line>1798</Line><Method>run</Method></Frame><Frame><File>git-p4.py</File><Line>1501</Line><Method>run</Method></Frame><Frame><File>git-p4.py</File><Line>439</Line><Method>originP4BranchesExist</Method></Frame><Frame><File>git-p4.py</File><Line>332</Line><Method>gitBranchExists</Method></Frame><Frame><File>c:\Python27\lib\subprocess.py</File><Line>672</Line><Method>__init__</Method></Frame><Frame><File>c:\Python27\lib\subprocess.py</File><Line>882</Line><Method>_execute_child</Method></Frame></Stack></Post><Post><PostId>5502619</PostId><Url>http://stackoverflow.com/questions/5502619</Url><Stack><Type>WindowsError</Type><Message>[Error 5] Access is denied: 'C:\\Windows\\System32\\build'</Message><Frame><File>C:\Python27\lib\site-packages\pip-0.8.3-py2.7.egg\pip\basecommand.py</File><Line>127</Line><Method>main</Method></Frame><Frame><File>C:\Python27\lib\site-packages\pip-0.8.3-py2.7.egg\pip\commands\install.py</File><Line>223</Line><Method>run</Method></Frame><Frame><File>C:\Python27\lib\site-packages\pip-0.8.3-py2.7.egg\pip\req.py</File><Line>936</Line><Method>prepare_files</Method></Frame><Frame><File>C:\Python27\lib\site-packages\pip-0.8.3-py2.7.egg\pip\req.py</File><Line>147</Line><Method>build_location</Method></Frame><Frame><File>C:\Python27\lib\site-packages\pip-0.8.3-py2.7.egg\pip\req.py</File><Line>1177</Line><Method>_make_build_dir</Method></Frame><Frame><File>C:\Python27\lib\os.py</File><Line>157</Line><Method>makedirs</Method></Frame></Stack></Post><Post><PostId>5678121</PostId><Url>http://stackoverflow.com/questions/5678121</Url><Stack><Type>WindowsError</Type><Message>[Error 2] The system cannot find the file specified</Message><Frame><File>setup.py</File><Line>15</Line><Method>module</Method></Frame><Frame><File>C:\Project\MySQL-python-1.2.3\setup_windows.py</File><Line>7</Line><Method>get_config</Method></Frame></Stack></Post><Post><PostId>6235282</PostId><Url>http://stackoverflow.com/questions/6235282</Url><Stack><Type>WindowsError</Type><Message>[Error 3] The system cannot find the path specified: "C:\\Users\\P</Message><Frame><File>dwload.py</File><Line>9</Line><Method>module</Method></Frame><Frame><File>Pmw\__init__.pyc</File><Line>28</Line><Method>module</Method></Frame></Stack></Post><Post><PostId>6459757</PostId><Url>http://stackoverflow.com/questions/6459757</Url><Stack><Type>WindowsError</Type><Message>[Error 183] Cannot create a file when that file already exists</Message><Frame><File>C:\SQA_log\scan.py</File><Line>20</Line><Method>module</Method></Frame><Frame><File>C:\Python27\lib\ntpath.py</File><Line>263</Line><Method>walk</Method></Frame><Frame><File>C:\Python27\lib\ntpath.py</File><Line>263</Line><Method>walk</Method></Frame><Frame><File>C:\Python27\lib\ntpath.py</File><Line>263</Line><Method>walk</Method></Frame><Frame><File>C:\Python27\lib\ntpath.py</File><Line>259</Line><Method>walk</Method></Frame><Frame><File>C:\SQA_log\scan.py</File><Line>16</Line><Method>print_tgzLogs</Method></Frame></Stack></Post><Post><PostId>7531514</PostId><Url>http://stackoverflow.com/questions/7531514</Url><Stack><Type>WindowsError</Type><Message>[Error 2] The system cannot find the file specified</Message><Frame><File>M:\cstat\ct.py</File><Line>37</Line><Method>module</Method></Frame><Frame><File>M:\cstat\ct.py</File><Line>34</Line><Method>main</Method></Frame><Frame><File>M:\cstat\ct.py</File><Line>26</Line><Method>selection</Method></Frame><Frame><File>M:\cstat\ct.py</File><Line>10</Line><Method>buildinga</Method></Frame><Frame><File>M:\cstat\ct.py</File><Line>5</Line><Method>results</Method></Frame><Frame><File>C:\Utilities\Python\lib\subprocess.py</File><Line>672</Line><Method>__init__</Method></Frame><Frame><File>C:\Utilities\Python\lib\subprocess.py</File><Line>882</Line><Method>_execute_child</Method></Frame></Stack></Post><Post><PostId>7586504</PostId><Url>http://stackoverflow.com/questions/7586504</Url><Stack><Type>WindowsError</Type><Message>[Error 126] The specified module could not be found</Message><Frame><File>pyshell#2</File><Line>1</Line><Method>module</Method></Frame><Frame><File>C:\Python26\lib\ctypes\__init__.py</File><Line>431</Line><Method>LoadLibrary</Method></Frame><Frame><File>C:\Python26\lib\ctypes\__init__.py</File><Line>353</Line><Method>__init__</Method></Frame></Stack></Post><Post><PostId>8434981</PostId><Url>http://stackoverflow.com/questions/8434981</Url><Stack><Type>WindowsError</Type><Message>[Error 2] The system cannot find the file specified</Message><Frame><File>pycheckers.py</File><Line>254</Line><Method>module</Method></Frame><Frame><File>pycheckers.py</File><Line>91</Line><Method>run</Method></Frame><Frame><File>C:\devel\Python\Python-2.7\Lib\subprocess.py</File><Line>672</Line><Method>__init__</Method></Frame><Frame><File>C:\devel\Python\Python-2.7\Lib\subprocess.py</File><Line>882</Line><Method>_execute_child</Method></Frame></Stack></Post><Post><PostId>8617720</PostId><Url>http://stackoverflow.com/questions/8617720</Url><Stack><Type>WindowsError</Type><Message>[Error 2] The system cannot find the file specified</Message><Frame><File>.\setup.py</File><Line>15</Line><Method>module</Method></Frame><Frame><File>C:\Users\samuele.mattiuzzo\Downloads\Django_python_apps\MySQL-python-1.2.3\setup_windows.py</File><Line>7</Line><Method>get_config</Method></Frame></Stack></Post><Post><PostId>9050312</PostId><Url>http://stackoverflow.com/questions/9050312</Url><Stack><Type>WindowsError</Type><Message>[Error 3] The system cannot find the path specified: '/dev/*.*'</Message><Frame><File>C:\LASERSAUR\lasersaur_Grbl\stefanix-LasaurGrbl-dac1a86\flash.py</File><Line>128</Line><Method>module</Method></Frame></Stack></Post><Post><PostId>9366362</PostId><Url>http://stackoverflow.com/questions/9366362</Url><Stack><Type>WindowsError</Type><Message>[Error 2] The system cannot find the file specified</Message><Frame><File>deploy\deploy.py</File><Line>344</Line><Method>module</Method></Frame><Frame><File>deploy\deploy.py</File><Line>287</Line><Method>main</Method></Frame><Frame><File>deploy\deploy.py</File><Line>201</Line><Method>check_deps</Method></Frame><Frame><File>C:\Documents and Settings\Sunil\workspace\khan\src\deploy\npm.py</File><Line>38</Line><Method>check_dependencies</Method></Frame><Frame><File>C:\Documents and Settings\Sunil\workspace\khan\src\deploy\npm.py</File><Line>13</Line><Method>installed</Method></Frame><Frame><File>C:\Documents and Settings\Sunil\workspace\khan\src\deploy\npm.py</File><Line>8</Line><Method>popen_results</Method></Frame><Frame><File>C:\python25\lib\subprocess.py</File><Line>594</Line><Method>__init__</Method></Frame><Frame><File>C:\python25\lib\subprocess.py</File><Line>822</Line><Method>_execute_child</Method></Frame></Stack></Post><Post><PostId>9531683</PostId><Url>http://stackoverflow.com/questions/9531683</Url><Stack><Type>WindowsError</Type><Message>[Error 2] The system cannot find the file specified</Message><Frame><File>pyshell#56</File><Line>1</Line><Method>module</Method></Frame><Frame><File>C:\Python27\lib\subprocess.py</File><Line>493</Line><Method>call</Method></Frame><Frame><File>C:\Python27\lib\subprocess.py</File><Line>679</Line><Method>__init__</Method></Frame><Frame><File>C:\Python27\lib\subprocess.py</File><Line>893</Line><Method>_execute_child</Method></Frame></Stack></Post><Post><PostId>9587454</PostId><Url>http://stackoverflow.com/questions/9587454</Url><Stack><Type>WindowsError</Type><Message>[Error 2] The system cannot find the file specified</Message><Frame><File>C:\Python27\Lib\site-packages\Pythonwin\pywin\framework\scriptutils.py</File><Line>322</Line><Method>RunScript</Method></Frame><Frame><File>C:\Python27\Lib\site-packages\Pythonwin\pywin\debugger\__init__.py</File><Line>60</Line><Method>run</Method></Frame><Frame><File>C:\Python27\Lib\site-packages\Pythonwin\pywin\debugger\debugger.py</File><Line>655</Line><Method>run</Method></Frame><Frame><File>C:\Documents and Settings\Administrator\Desktop\attachments\ocr.py</File><Line>1</Line><Method>module</Method></Frame><Frame><File>C:\Python27\lib\site-packages\PIL\Image.py</File><Line>1952</Line><Method>open</Method></Frame><Frame><File>or.py</File><Line>8</Line><Method>module</Method></Frame><Frame><File>C:\Python27\lib\pytesser.py</File><Line>31</Line><Method>image_to_string</Method></Frame><Frame><File>C:\Python27\lib\pytesser.py</File><Line>21</Line><Method>call_tesseract</Method></Frame><Frame><File>C:\Python27\lib\subprocess.py</File><Line>679</Line><Method>__init__</Method></Frame><Frame><File>C:\Python27\lib\subprocess.py</File><Line>893</Line><Method>_execute_child</Method></Frame></Stack></Post><Post><PostId>9587454</PostId><Url>http://stackoverflow.com/questions/9587454</Url><Stack><Type>WindowsError</Type><Message>[Error 2] The system cannot find the file specified</Message><Frame><File>C:\Python27\Lib\site-packages\Pythonwin\pywin\framework\scriptutils.py</File><Line>322</Line><Method>RunScript</Method></Frame><Frame><File>C:\Python27\Lib\site-packages\Pythonwin\pywin\debugger\__init__.py</File><Line>60</Line><Method>run</Method></Frame><Frame><File>C:\Python27\Lib\site-packages\Pythonwin\pywin\debugger\debugger.py</File><Line>655</Line><Method>run</Method></Frame><Frame><File>C:\Documents and Settings\Administrator\Desktop\attachments\ocr.py</File><Line>1</Line><Method>module</Method></Frame><Frame><File>C:\Python27\lib\site-packages\PIL\Image.py</File><Line>1952</Line><Method>open</Method></Frame><Frame><File>or.py</File><Line>8</Line><Method>module</Method></Frame><Frame><File>C:\Python27\lib\pytesser.py</File><Line>31</Line><Method>image_to_string</Method></Frame><Frame><File>C:\Python27\lib\pytesser.py</File><Line>21</Line><Method>call_tesseract</Method></Frame><Frame><File>C:\Python27\lib\subprocess.py</File><Line>679</Line><Method>__init__</Method></Frame><Frame><File>C:\Python27\lib\subprocess.py</File><Line>893</Line><Method>_execute_child</Method></Frame></Stack></Post><Post><PostId>9797391</PostId><Url>http://stackoverflow.com/questions/9797391</Url><Stack><Type>WindowsError</Type><Message>[Error 2] The system cannot find the file specified: '../Desktop'</Message><Frame><File>pyshell#24</File><Line>1</Line><Method>module</Method></Frame></Stack></Post><Post><PostId>10132092</PostId><Url>http://stackoverflow.com/questions/10132092</Url><Stack><Type>WindowsError</Type><Message>[Error 2] The system cannot find the file specified</Message><Frame><File>C:\testreg.py</File><Line>2</Line><Method>module</Method></Frame></Stack></Post><Post><PostId>10214105</PostId><Url>http://stackoverflow.com/questions/10214105</Url><Stack><Type>WindowsError</Type><Message>[Error 3] The system cannot find the path specified: 'D:\\docx_example\\docx_example.exe\\template'</Message><Frame><File>docx_example.py</File><Line>75</Line><Method>module</Method></Frame><Frame><File>docx.pyo</File><Line>854</Line><Method>savedocx</Method></Frame></Stack></Post><Post><PostId>10411709</PostId><Url>http://stackoverflow.com/questions/10411709</Url><Stack><Type>WindowsError</Type><Message>[Error 126] The specified module could not be found</Message><Frame><File>D:\python\Auxil\src\auxil.py</File><Line>130</Line><Method>module</Method></Frame><Frame><File>C:\Python27\lib\ctypes\__init__.py</File><Line>431</Line><Method>LoadLibrary</Method></Frame><Frame><File>C:\Python27\lib\ctypes\__init__.py</File><Line>353</Line><Method>__init__</Method></Frame></Stack></Post><Post><PostId>10549872</PostId><Url>http://stackoverflow.com/questions/10549872</Url><Stack><Type>WindowsError</Type><Message>[Error 2] The system cannot find the file specified</Message><Frame><File>.\tst.py</File><Line>2</Line><Method>module</Method></Frame><Frame><File>C:\Python27\lib\subprocess.py</File><Line>506</Line><Method>check_call</Method></Frame><Frame><File>C:\Python27\lib\subprocess.py</File><Line>493</Line><Method>call</Method></Frame><Frame><File>C:\Python27\lib\subprocess.py</File><Line>679</Line><Method>__init__</Method></Frame><Frame><File>C:\Python27\lib\subprocess.py</File><Line>896</Line><Method>_execute_child</Method></Frame></Stack></Post><Post><PostId>10634569</PostId><Url>http://stackoverflow.com/questions/10634569</Url><Stack><Type>WindowsError</Type><Message>[Error 193] %1 is not a valid Win32 application</Message><Frame><File>C:/Python27/main.py</File><Line>31</Line><Method>from svm import *</Method></Frame><Frame><File>C:/Python27\svm.py</File><Line>12</Line><Method>libsvm = CDLL(find_library('libsvm'))</Method></Frame><Frame><File>C:\Python27\lib\ctypes\__init__.py</File><Line>353</Line><Method>__init__</Method></Frame></Stack></Post><Post><PostId>10874619</PostId><Url>http://stackoverflow.com/questions/10874619</Url><Stack><Type>WindowsError</Type><Message>[Error 193] %1 is not a valid Win32 application</Message><Frame><File>pyshell#14</File><Line>1</Line><Method>module</Method></Frame><Frame><File>C:\Python27\lib\subprocess.py</File><Line>493</Line><Method>call</Method></Frame><Frame><File>C:\Python27\lib\subprocess.py</File><Line>679</Line><Method>__init__</Method></Frame><Frame><File>C:\Python27\lib\subprocess.py</File><Line>893</Line><Method>_execute_child</Method></Frame></Stack></Post><Post><PostId>10956257</PostId><Url>http://stackoverflow.com/questions/10956257</Url><Stack><Type>WindowsError</Type><Message>[Error 2] The system cannot find the file specified: 'c:\\Python27</Message><Frame><File>folder_generate.py</File><Line>21</Line><Method>module</Method></Frame></Stack></Post><Post><PostId>11062466</PostId><Url>http://stackoverflow.com/questions/11062466</Url><Stack><Type>WindowsError</Type><Message>[Error 267] The directory name is invalid: 'C:\\Users\\Bob\applications\\Program\\test\\v0.6\\dist\\library.zip/*.*'</Message><Frame><File>program.py</File><Line>427</Line><Method>module</Method></Frame><Frame><File>program.py</File><Line>242</Line><Method>__init__</Method></Frame></Stack></Post><Post><PostId>11097535</PostId><Url>http://stackoverflow.com/questions/11097535</Url><Stack><Type>WindowsError</Type><Message>[Error 2] The system cannot find the file specified</Message><Frame><File>test_scons.py</File><Line>66</Line><Method>module</Method></Frame><Frame><File>C:\Python27\lib\subprocess.py</File><Line>493</Line><Method>call</Method></Frame><Frame><File>C:\Python27\lib\subprocess.py</File><Line>679</Line><Method>__init__</Method></Frame><Frame><File>C:\Python27\lib\subprocess.py</File><Line>896</Line><Method>_execute_child</Method></Frame></Stack></Post><Post><PostId>11247420</PostId><Url>http://stackoverflow.com/questions/11247420</Url><Stack><Type>WindowsError</Type><Message>[Error 123] The filename, directory name, or volume label syntax is incorrect</Message><Frame><File>.\archive.py</File><Line>17</Line><Method>os.rename('archive.zip',newname)</Method></Frame></Stack></Post><Post><PostId>11306262</PostId><Url>http://stackoverflow.com/questions/11306262</Url><Stack><Type>WindowsError</Type><Message>[Error 123] The filename, directory name, or volume label syntax is incorrect: '\DB?1333366331.436754.048342.csv'</Message><Frame><File>file_size.py</File><Line>8</Line><Method>module</Method></Frame><Frame><File>C:\Python27\lib\genericpath.py</File><Line>49</Line><Method>getsize</Method></Frame></Stack></Post><Post><PostId>11350429</PostId><Url>http://stackoverflow.com/questions/11350429</Url><Stack><Type>WindowsError</Type><Message>[Error 126]</Message><Frame><File>pyshell#2</File><Line>1</Line><Method>module</Method></Frame><Frame><File>pyshell#3</File><Line>1</Line><Method>module</Method></Frame><Frame><File>C:\Python27\lib\ctypes\__init__.py</File><Line>431</Line><Method>LoadLibrary</Method></Frame><Frame><File>C:\Python27\lib\ctypes\__init__.py</File><Line>353</Line><Method>__init__</Method></Frame></Stack></Post><Post><PostId>11350429</PostId><Url>http://stackoverflow.com/questions/11350429</Url><Stack><Type>WindowsError</Type><Message>[Error 126]</Message><Frame><File>pyshell#2</File><Line>1</Line><Method>module</Method></Frame><Frame><File>pyshell#3</File><Line>1</Line><Method>module</Method></Frame><Frame><File>C:\Python27\lib\ctypes\__init__.py</File><Line>431</Line><Method>LoadLibrary</Method></Frame><Frame><File>C:\Python27\lib\ctypes\__init__.py</File><Line>353</Line><Method>__init__</Method></Frame></Stack></Post><Post><PostId>11470497</PostId><Url>http://stackoverflow.com/questions/11470497</Url><Stack><Type>WindowsError</Type><Message>[Error 183] Eine Datei kann nicht erstellt werden, wenn sie bereits vorhanden ist: 'development'</Message><Frame><File>C:\Users\asic\forge-tools-3.3.2\forge-tools\forge\async.py</File><Line>96</Line><Method>run</Method></Frame><Frame><File>C:\Users\asic\forge-tools-3.3.2\forge-tools\forge\main.py</File><Line>369</Line><Method>development_build</Method></Frame><Frame><File>C:\Users\asic\forge-tools-3.3.2\forge-tools\forge\lib.py</File><Line>25</Line><Method>try_a_few_times</Method></Frame><Frame><File>C:\Users\asic\forge-tools-3.3.2\forge-tools\forge\main.py</File><Line>365</Line><Method>move_files_across</Method></Frame><Frame><File>C:\Python27\lib\shutil.py</File><Line>174</Line><Method>copytree</Method></Frame><Frame><File>C:\Python27\lib\os.py</File><Line>157</Line><Method>makedirs</Method></Frame></Stack></Post><Post><PostId>11581038</PostId><Url>http://stackoverflow.com/questions/11581038</Url><Stack><Type>WindowsError</Type><Message>exception: access violation writing 0x0000087C</Message><Frame><File>test.py</File><Line>40</Line><Method>module</Method></Frame></Stack></Post><Post><PostId>11825923</PostId><Url>http://stackoverflow.com/questions/11825923</Url><Stack><Type>WindowsError</Type><Message>[Error 2] The system cannot find the file specified</Message><Frame><File>batch_file_rename_2.py</File><Line>13</Line><Method>module</Method></Frame></Stack></Post><Post><PostId>11835873</PostId><Url>http://stackoverflow.com/questions/11835873</Url><Stack><Type>WindowsError</Type><Message>[Error 5] Access is denied</Message><Frame><File>C:\path\to\my\script.py</File><Line>57</Line><Method>module</Method></Frame><Frame><File>C:\Python27\lib\subprocess.py</File><Line>493</Line><Method>call</Method></Frame><Frame><File>C:\Python27\lib\subprocess.py</File><Line>679</Line><Method>__init__</Method></Frame><Frame><File>C:\Python27\lib\subprocess.py</File><Line>893</Line><Method>_execute_child</Method></Frame></Stack></Post><Post><PostId>11873448</PostId><Url>http://stackoverflow.com/questions/11873448</Url><Stack><Type>WindowsError</Type><Message>exception: access violation reading 0x0000003C</Message><Frame><File>pyshell#56</File><Line>1</Line><Method>module</Method></Frame><Frame><File>C:/Users/schappell/Downloads/srt.py</File><Line>15</Line><Method>self_reference</Method></Frame></Stack></Post><Post><PostId>11887640</PostId><Url>http://stackoverflow.com/questions/11887640</Url><Stack><Type>WindowsError</Type><Message>[Error 5] Access is denied</Message><Frame><File>D:/Python27/fuzzer.py</File><Line>29</Line><Method>module</Method></Frame><Frame><File>D:\Python27\lib\subprocess.py</File><Line>679</Line><Method>__init__</Method></Frame><Frame><File>D:\Python27\lib\subprocess.py</File><Line>896</Line><Method>_execute_child</Method></Frame></Stack></Post><Post><PostId>11893958</PostId><Url>http://stackoverflow.com/questions/11893958</Url><Stack><Type>WindowsError</Type><Message>[Error 5] Access is denied</Message><Frame><File>pyshell#10</File><Line>1</Line><Method>module</Method></Frame></Stack></Post><Post><PostId>12179793</PostId><Url>http://stackoverflow.com/questions/12179793</Url><Stack><Type>WindowsError</Type><Message>[Error 2] The system cannot find the file specified</Message><Frame><File>C:\Python26\MySQL-python-1.2.3\setup.py</File><Line>15</Line><Method>module</Method></Frame><Frame><File>C:\Python26\MySQL-python-1.2.3\setup_windows.py</File><Line>7</Line><Method>get_config</Method></Frame></Stack></Post><Post><PostId>13073855</PostId><Url>http://stackoverflow.com/questions/13073855</Url><Stack><Type>WindowsError</Type><Message>[Error 3] The system cannot find the path</Message><Frame><File>C:/Users/Simon/Documents/import_landsat2.py</File><Line>40</Line><Method>module</Method></Frame><Frame><File>C:/Users/Simon/Documents/import_landsat2.py</File><Line>37</Line><Method>main</Method></Frame><Frame><File>C:/Users/Simon/Documents/import_landsat2.py</File><Line>17</Line><Method>import_tifs</Method></Frame></Stack></Post><Post><PostId>13832056</PostId><Url>http://stackoverflow.com/questions/13832056</Url><Stack><Type>WindowsError</Type><Message>[Error 2] The system cannot find the file specified</Message><Frame><File>Z:\desktop\Project\bhmqntm-code\HamiltonianMovie(points_reducedtsegs).py</File><Line>75</Line><Method>module</Method></Frame><Frame><File>C:\Python27\lib\site-packages\matplotlib\animation.py</File><Line>127</Line><Method>save</Method></Frame><Frame><File>C:\Python27\lib\site-packages\matplotlib\animation.py</File><Line>164</Line><Method>_make_movie</Method></Frame><Frame><File>C:\Python27\lib\subprocess.py</File><Line>679</Line><Method>__init__</Method></Frame><Frame><File>C:\Python27\lib\subprocess.py</File><Line>893</Line><Method>_execute_child</Method></Frame></Stack></Post><Post><PostId>13937812</PostId><Url>http://stackoverflow.com/questions/13937812</Url><Stack><Type>WindowsError</Type><Message>[Error 123] The filename, directory name, or volume label syntax is incorrect</Message><Frame><File>D:/Python27/Scripts/getTime.py</File><Line>17</Line><Method>module</Method></Frame></Stack></Post><Post><PostId>14519082</PostId><Url>http://stackoverflow.com/questions/14519082</Url><Stack><Type>WindowsError</Type><Message>[Error 126] The specified module could not be found</Message><Frame><File>C:\Users\PC\Desktop\Python27\MyProject\src\Main.py</File><Line>12</Line><Method>module</Method></Frame><Frame><File>C:\Users\PC\Desktop\Python27\MyProject\src\Classifier\svm.py</File><Line>14</Line><Method>module</Method></Frame><Frame><File>C:\Python27\lib\ctypes\__init__.py</File><Line>365</Line><Method>__init__</Method></Frame></Stack></Post><Post><PostId>14543419</PostId><Url>http://stackoverflow.com/questions/14543419</Url><Stack><Type>WindowsError</Type><Message>[Error 193] %1 is not a valid Win32 application</Message><Frame><File>c:\plone42\eggs\collective.documentviewer-2.2b3-py2.6.egg\collective\documentviewer\convert.py</File><Line>530</Line><Method>__call__</Method></Frame><Frame><File>c:\plone42\eggs\collective.documentviewer-2.2b3-py2.6.egg\collective\documentviewer\convert.py</File><Line>379</Line><Method>run_conversion</Method></Frame><Frame><File>c:\plone42\eggs\collective.documentviewer-2.2b3-py2.6.egg\collective\documentviewer\convert.py</File><Line>287</Line><Method>convert</Method></Frame><Frame><File>c:\plone42\eggs\collective.documentviewer-2.2b3-py2.6.egg\collective\documentviewer\convert.py</File><Line>223</Line><Method>dump_images</Method></Frame><Frame><File>c:\plone42\eggs\collective.documentviewer-2.2b3-py2.6.egg\collective\documentviewer\convert.py</File><Line>105</Line><Method>_run_command</Method></Frame><Frame><File>c:\Plone42\python\lib\subprocess.py</File><Line>623</Line><Method>__init__</Method></Frame><Frame><File>c:\Plone42\python\lib\subprocess.py</File><Line>833</Line><Method>_execute_child</Method></Frame></Stack></Post><Post><PostId>14621932</PostId><Url>http://stackoverflow.com/questions/14621932</Url><Stack><Type>WindowsError</Type><Message>[Error 193] %1 is not a valid Win32 application</Message><Frame><File>C:\Users\sbritto\Documents\Visual Studio 2008\Projects\MathFuncsDll\Debug\MathFuncs.py</File><Line>5</Line><Method>module</Method></Frame><Frame><File>C:\Python27\lib\ctypes\__init__.py</File><Line>365</Line><Method>__init__</Method></Frame></Stack></Post><Post><PostId>14677190</PostId><Url>http://stackoverflow.com/questions/14677190</Url><Stack><Type>WindowsError</Type><Message>exception: access violation writing 0x0000000C</Message><Frame><File>C:\Programming\crash.py</File><Line>9</Line><Method>func1</Method></Frame></Stack></Post><Post><PostId>15030033</PostId><Url>http://stackoverflow.com/questions/15030033</Url><Stack><Type>WindowsError</Type><Message>[Error 5] Access is denied</Message><Frame><File>pyshell#43</File><Line>1</Line><Method>module</Method></Frame><Frame><File>pyshell#47</File><Line>1</Line><Method>module</Method></Frame><Frame><File>pyshell#48</File><Line>1</Line><Method>module</Method></Frame></Stack></Post><Post><PostId>15030033</PostId><Url>http://stackoverflow.com/questions/15030033</Url><Stack><Type>WindowsError</Type><Message>[Error 5] Access is denied</Message><Frame><File>pyshell#43</File><Line>1</Line><Method>module</Method></Frame><Frame><File>pyshell#47</File><Line>1</Line><Method>module</Method></Frame><Frame><File>pyshell#48</File><Line>1</Line><Method>module</Method></Frame></Stack></Post><Post><PostId>15030033</PostId><Url>http://stackoverflow.com/questions/15030033</Url><Stack><Type>WindowsError</Type><Message>[Error 5] Access is denied</Message><Frame><File>pyshell#43</File><Line>1</Line><Method>module</Method></Frame><Frame><File>pyshell#47</File><Line>1</Line><Method>module</Method></Frame><Frame><File>pyshell#48</File><Line>1</Line><Method>module</Method></Frame></Stack></Post><Post><PostId>15049699</PostId><Url>http://stackoverflow.com/questions/15049699</Url><Stack><Type>WindowsError</Type><Message>[Error 2] The system cannot find the file specified</Message><Frame><File>C:\Python26\lib\lib-tk\Tkinter.py</File><Line>1410</Line><Method>__call__</Method></Frame><Frame><File>C:\py_pro\but1.py</File><Line>82</Line><Method>inst_proxy22</Method></Frame><Frame><File>C:\py_pro\but1.py</File><Line>79</Line><Method>set_key</Method></Frame></Stack></Post><Post><PostId>15128225</PostId><Url>http://stackoverflow.com/questions/15128225</Url><Stack><Type>WindowsError</Type><Message>[Error 5] Access is denied</Message><Frame><File>D:\PROJECT\project.py</File><Line>305</Line><Method>OnOk</Method></Frame></Stack></Post><Post><PostId>15207271</PostId><Url>http://stackoverflow.com/questions/15207271</Url><Stack><Type>WindowsError</Type><Message>[Error 2] The system cannot find the file specified</Message><Frame><File>pyshell#2</File><Line>1</Line><Method>module</Method></Frame><Frame><File>C:\Python27\lib\subprocess.py</File><Line>493</Line><Method>call</Method></Frame><Frame><File>C:\Python27\lib\subprocess.py</File><Line>679</Line><Method>__init__</Method></Frame><Frame><File>C:\Python27\lib\subprocess.py</File><Line>896</Line><Method>_execute_child</Method></Frame></Stack></Post><Post><PostId>15530866</PostId><Url>http://stackoverflow.com/questions/15530866</Url><Stack><Type>WindowsError</Type><Message>[Error 6] The handle is invalid.</Message><Frame><File>C:\Program Files\Google\google_appengine\dev_appserver.py</File><Line>194</Line><Method>_run_file(__file__, globals())</Method></Frame><Frame><File>C:\Program Files\Google\google_appengine\dev_appserver.py</File><Line>190</Line><Method>_run_file</Method></Frame><Frame><File>C:\Program Files\Google\google_appengine\google\appengine\tools\devappserver2\devappserver2.py</File><Line>545</Line><Method>main()</Method></Frame><Frame><File>C:\Program Files\Google\google_appengine\google\appengine\tools\devappserver2\devappserver2.py</File><Line>538</Line><Method>main</Method></Frame><Frame><File>C:\Program Files\Google\google_appengine\google\appengine\tools\devappserver2\devappserver2.py</File><Line>513</Line><Method>start</Method></Frame><Frame><File>C:\Program Files\Google\google_appengine\google\appengine\tools\devappserver2\dispatcher.py</File><Line>95</Line><Method>start</Method></Frame><Frame><File>C:\Program Files\Google\google_appengine\google\appengine\tools\devappserver2\server.py</File><Line>827</Line><Method>start</Method></Frame><Frame><File>C:\Program Files\Google\google_appengine\google\appengine\tools\devappserver2\win32_file_watcher.py</File><Line>74</Line><Method>start</Method></Frame></Stack></Post><Post><PostId>15822935</PostId><Url>http://stackoverflow.com/questions/15822935</Url><Stack><Type>WindowsError</Type><Message>[Error 2] The system cannot find the file specified: 'C:\\Windows\\Fonts\\OpenDyslexic-Regular.otf'</Message><Frame><File>C:\Users\Ryan\Documents\opendyslexic-installer\opendyslexic_installer.py</File><Line>109</Line><Method>module</Method></Frame><Frame><File>C:\Python27\lib\filecmp.py</File><Line>43</Line><Method>cmp</Method></Frame></Stack></Post><Post><PostId>15847253</PostId><Url>http://stackoverflow.com/questions/15847253</Url><Stack><Type>WindowsError</Type><Message>[Error 5] Access is denied</Message><Frame><File>pyshell#2</File><Line>1</Line><Method>module</Method></Frame></Stack></Post><Post><PostId>16636095</PostId><Url>http://stackoverflow.com/questions/16636095</Url><Stack><Type>WindowsError</Type><Message>[Error 5] Access is denied</Message><Frame><File>C:\Python27\lib\threading.py</File><Line>551</Line><Method>__bootstrap_inner</Method></Frame><Frame><File>VB_Extraction.py</File><Line>57</Line><Method>run</Method></Frame><Frame><File>C:\Python27\lib\subprocess.py</File><Line>1019</Line><Method>terminate</Method></Frame></Stack></Post><Post><PostId>16705216</PostId><Url>http://stackoverflow.com/questions/16705216</Url><Stack><Type>WindowsError</Type><Message>[Error 5] Access is denied</Message><Frame><File>threading.pyc</File><Line>486</Line><Method>__bootstrap_inner</Method></Frame><Frame><File>launcher\taskthread.pyc</File><Line>65</Line><Method>run</Method></Frame><Frame><File>subprocess.pyc</File><Line>594</Line><Method>__init__</Method></Frame><Frame><File>subprocess.pyc</File><Line>816</Line><Method>_execute_child</Method></Frame></Stack></Post><Post><PostId>16748148</PostId><Url>http://stackoverflow.com/questions/16748148</Url><Stack><Type>WindowsError</Type><Message>[Error 2] The system cannot find the file specified</Message><Frame><File>C:\Users\Alex\Dropbox\code stuff\solarsystem.py</File><Line>56</Line><Method>module</Method></Frame><Frame><File>C:\Python27\lib\subprocess.py</File><Line>524</Line><Method>call</Method></Frame><Frame><File>C:\Python27\lib\subprocess.py</File><Line>711</Line><Method>__init__</Method></Frame><Frame><File>C:\Python27\lib\subprocess.py</File><Line>948</Line><Method>_execute_child</Method></Frame></Stack></Post><Post><PostId>16831386</PostId><Url>http://stackoverflow.com/questions/16831386</Url><Stack><Type>WindowsError</Type><Message>[Error 5] Acceso denegado</Message><Frame><File>C:\Users\alalarcon\Python27\lib\threading.py</File><Line>810</Line><Method>__bootstrap_inner</Method></Frame><Frame><File>C:\Users\alalarcon\Python27\lib\threading.py</File><Line>763</Line><Method>run</Method></Frame><Frame><File>C:\Users\alalarcon\google_appengine\google\appengine\tools\devappserver2\server.py</File><Line>1232</Line><Method>_loop_adjusting_instances</Method></Frame><Frame><File>C:\Users\alalarcon\google_appengine\google\appengine\tools\devappserver2\server.py</File><Line>1209</Line><Method>_adjust_instances</Method></Frame><Frame><File>C:\Users\alalarcon\google_appengine\google\appengine\tools\devappserver2\server.py</File><Line>1087</Line><Method>_add_instance</Method></Frame><Frame><File>C:\Users\alalarcon\google_appengine\google\appengine\tools\devappserver2\php_runtime.py</File><Line>195</Line><Method>new_instance</Method></Frame><Frame><File>C:\Users\alalarcon\google_appengine\google\appengine\tools\devappserver2\php_runtime.py</File><Line>138</Line><Method>_check_environment</Method></Frame><Frame><File>C:\Users\alalarcon\google_appengine\google\appengine\tools\devappserver2\safe_subprocess.py</File><Line>61</Line><Method>start_process</Method></Frame><Frame><File>C:\Users\alalarcon\Python27\lib\subprocess.py</File><Line>711</Line><Method>__init__</Method></Frame><Frame><File>C:\Users\alalarcon\Python27\lib\subprocess.py</File><Line>948</Line><Method>_execute_child</Method></Frame></Stack></Post><Post><PostId>16981827</PostId><Url>http://stackoverflow.com/questions/16981827</Url><Stack><Type>WindowsError</Type><Message>[Error 2] The system cannot find the file specified</Message><Frame><File>D:\rcseng\buildout\bin\instance-script.py</File><Line>258</Line><Method>module</Method></Frame><Frame><File>d:\rcseng\buildout\eggs\plone.recipe.zope2instance-4.2.8-py2.6.egg\plone \recipe\zope2instance\ctl.py</File><Line>614</Line><Method>main</Method></Frame><Frame><File>D:\Python26\lib\cmd.py</File><Line>219</Line><Method>onecmd</Method></Frame><Frame><File>d:\rcseng\buildout\eggs\zdaemon-2.0.7-py2.6.egg\zdaemon\zdctl.py</File><Line>588</Line><Method>do_fg</Method></Frame><Frame><File>d:\rcseng\buildout\eggs\plone.recipe.zope2instance-4.2.8-py2.6.egg\plone \recipe\zope2instance\ctl.py</File><Line>550</Line><Method>do_foreground</Method></Frame><Frame><File>D:\Python26\lib\subprocess.py</File><Line>470</Line><Method>call</Method></Frame><Frame><File>D:\Python26\lib\subprocess.py</File><Line>623</Line><Method>__init__</Method></Frame><Frame><File>D:\Python26\lib\subprocess.py</File><Line>833</Line><Method>_execute_child</Method></Frame></Stack></Post><Post><PostId>17076679</PostId><Url>http://stackoverflow.com/questions/17076679</Url><Stack><Type>WindowsError</Type><Message>[Error 5] Access is denied</Message><Frame><File>.\multiprocessing_error.py</File><Line>29</Line><Method>module</Method></Frame><Frame><File>.\multiprocessing_error.py</File><Line>21</Line><Method>timeout</Method></Frame><Frame><File>C:\Python27\lib\multiprocessing\process.py</File><Line>137</Line><Method>terminate</Method></Frame><Frame><File>C:\Python27\lib\multiprocessing\forking.py</File><Line>306</Line><Method>terminate</Method></Frame></Stack></Post><Post><PostId>17168351</PostId><Url>http://stackoverflow.com/questions/17168351</Url><Stack><Type>WindowsError</Type><Message>[Error 1326] Logon failure: unknown user name or bad password</Message><Frame><File>C:\Python27\lib\site-packages\celery\task\trace.py</File><Line>228</Line><Method>trace_task</Method></Frame><Frame><File>C:\Python27\lib\site-packages\celery\task\trace.py</File><Line>415</Line><Method>__protected_call__</Method></Frame><Frame><File>Path\to\file\file.py</File><Line>96</Line><Method>movefile</Method></Frame><Frame><File>C:\Python27\lib\site-packages\win_unc\connecting.py</File><Line>163</Line><Method>mount</Method></Frame><Frame><File>C:\Python27\lib\site-packages\win_unc\connecting.py</File><Line>63</Line><Method>connect</Method></Frame><Frame><File>C:\Python27\lib\site-packages\win_unc\connecting.py</File><Line>118</Line><Method>_connect_with_creds</Method></Frame><Frame><File>C:\Python27\lib\site-packages\win_unc\internal\shell.py</File><Line>29</Line><Method>run</Method></Frame><Frame><File>C:\Python27\lib\site-packages\celery\task\trace.py</File><Line>228</Line><Method>trace_task</Method></Frame><Frame><File>C:\Python27\lib\site-packages\celery\task\trace.py</File><Line>415</Line><Method>__protected_call__</Method></Frame><Frame><File>Path\to\file\file.py</File><Line>96</Line><Method>movefile</Method></Frame><Frame><File>C:\Python27\lib\shutil.py</File><Line>117</Line><Method>copy</Method></Frame><Frame><File>C:\Python27\lib\shutil.py</File><Line>83</Line><Method>copyfile</Method></Frame><Frame><File>C:\Python27\lib\site-packages\celery\task\trace.py</File><Line>228</Line><Method>trace_task</Method></Frame><Frame><File>C:\Python27\lib\site-packages\celery\task\trace.py</File><Line>415</Line><Method>__protected_call__</Method></Frame><Frame><File>Path\to\file\file.py</File><Line>95</Line><Method>movefile</Method></Frame></Stack></Post><Post><PostId>17168351</PostId><Url>http://stackoverflow.com/questions/17168351</Url><Stack><Type>WindowsError</Type><Message>[Error 1326] Logon failure: unknown user name or bad password</Message><Frame><File>C:\Python27\lib\site-packages\celery\task\trace.py</File><Line>228</Line><Method>trace_task</Method></Frame><Frame><File>C:\Python27\lib\site-packages\celery\task\trace.py</File><Line>415</Line><Method>__protected_call__</Method></Frame><Frame><File>Path\to\file\file.py</File><Line>96</Line><Method>movefile</Method></Frame><Frame><File>C:\Python27\lib\site-packages\win_unc\connecting.py</File><Line>163</Line><Method>mount</Method></Frame><Frame><File>C:\Python27\lib\site-packages\win_unc\connecting.py</File><Line>63</Line><Method>connect</Method></Frame><Frame><File>C:\Python27\lib\site-packages\win_unc\connecting.py</File><Line>118</Line><Method>_connect_with_creds</Method></Frame><Frame><File>C:\Python27\lib\site-packages\win_unc\internal\shell.py</File><Line>29</Line><Method>run</Method></Frame><Frame><File>C:\Python27\lib\site-packages\celery\task\trace.py</File><Line>228</Line><Method>trace_task</Method></Frame><Frame><File>C:\Python27\lib\site-packages\celery\task\trace.py</File><Line>415</Line><Method>__protected_call__</Method></Frame><Frame><File>Path\to\file\file.py</File><Line>96</Line><Method>movefile</Method></Frame><Frame><File>C:\Python27\lib\shutil.py</File><Line>117</Line><Method>copy</Method></Frame><Frame><File>C:\Python27\lib\shutil.py</File><Line>83</Line><Method>copyfile</Method></Frame><Frame><File>C:\Python27\lib\site-packages\celery\task\trace.py</File><Line>228</Line><Method>trace_task</Method></Frame><Frame><File>C:\Python27\lib\site-packages\celery\task\trace.py</File><Line>415</Line><Method>__protected_call__</Method></Frame><Frame><File>Path\to\file\file.py</File><Line>95</Line><Method>movefile</Method></Frame></Stack></Post><Post><PostId>17168351</PostId><Url>http://stackoverflow.com/questions/17168351</Url><Stack><Type>WindowsError</Type><Message>[Error 1326] Logon failure: unknown user name or bad password</Message><Frame><File>C:\Python27\lib\site-packages\celery\task\trace.py</File><Line>228</Line><Method>trace_task</Method></Frame><Frame><File>C:\Python27\lib\site-packages\celery\task\trace.py</File><Line>415</Line><Method>__protected_call__</Method></Frame><Frame><File>Path\to\file\file.py</File><Line>96</Line><Method>movefile</Method></Frame><Frame><File>C:\Python27\lib\site-packages\win_unc\connecting.py</File><Line>163</Line><Method>mount</Method></Frame><Frame><File>C:\Python27\lib\site-packages\win_unc\connecting.py</File><Line>63</Line><Method>connect</Method></Frame><Frame><File>C:\Python27\lib\site-packages\win_unc\connecting.py</File><Line>118</Line><Method>_connect_with_creds</Method></Frame><Frame><File>C:\Python27\lib\site-packages\win_unc\internal\shell.py</File><Line>29</Line><Method>run</Method></Frame><Frame><File>C:\Python27\lib\site-packages\celery\task\trace.py</File><Line>228</Line><Method>trace_task</Method></Frame><Frame><File>C:\Python27\lib\site-packages\celery\task\trace.py</File><Line>415</Line><Method>__protected_call__</Method></Frame><Frame><File>Path\to\file\file.py</File><Line>96</Line><Method>movefile</Method></Frame><Frame><File>C:\Python27\lib\shutil.py</File><Line>117</Line><Method>copy</Method></Frame><Frame><File>C:\Python27\lib\shutil.py</File><Line>83</Line><Method>copyfile</Method></Frame><Frame><File>C:\Python27\lib\site-packages\celery\task\trace.py</File><Line>228</Line><Method>trace_task</Method></Frame><Frame><File>C:\Python27\lib\site-packages\celery\task\trace.py</File><Line>415</Line><Method>__protected_call__</Method></Frame><Frame><File>Path\to\file\file.py</File><Line>95</Line><Method>movefile</Method></Frame></Stack></Post><Post><PostId>17299435</PostId><Url>http://stackoverflow.com/questions/17299435</Url><Stack><Type>WindowsError</Type><Message>[Error 2] The system cannot find the file specified</Message><Frame><File>pyshell#13</File><Line>1</Line><Method>module</Method></Frame><Frame><File>C:\Python32\lib\subprocess.py</File><Line>514</Line><Method>check_output</Method></Frame><Frame><File>C:\Python32\lib\subprocess.py</File><Line>744</Line><Method>__init__</Method></Frame><Frame><File>C:\Python32\lib\subprocess.py</File><Line>977</Line><Method>_execute_child</Method></Frame></Stack></Post><Post><PostId>17326337</PostId><Url>http://stackoverflow.com/questions/17326337</Url><Stack><Type>WindowsError</Type><Message>[Error 2] The system cannot find the file specified</Message><Frame><File>C:\Users\Josh\Desktop\LapseBot 1.0\LapseBot.py</File><Line>3</Line><Method>module</Method></Frame></Stack></Post><Post><PostId>17348891</PostId><Url>http://stackoverflow.com/questions/17348891</Url><Stack><Type>WindowsError</Type><Message>[Error 193] %1 is not a valid Win32 application</Message><Frame><File>test1.py</File><Line>4</Line><Method>module</Method></Frame><Frame><File>C:\Python27\lib\subprocess.py</File><Line>679</Line><Method>__init__</Method></Frame><Frame><File>C:\Python27\lib\subprocess.py</File><Line>896</Line><Method>_execute_child</Method></Frame></Stack></Post><Post><PostId>17509088</PostId><Url>http://stackoverflow.com/questions/17509088</Url><Stack><Type>WindowsError</Type><Message>[Error 3] The system cannot find the path specified.</Message><Frame><File>Package.py</File><Line>1</Line><Method>module</Method></Frame><Frame><File>PySide\__init__.pyc</File><Line>55</Line><Method>module</Method></Frame><Frame><File>PySide\__init__.pyc</File><Line>11</Line><Method>_setupQtDirectories</Method></Frame><Frame><File>PySide\_utils.pyc</File><Line>87</Line><Method>get_pyside_dir</Method></Frame><Frame><File>PySide\_utils.pyc</File><Line>83</Line><Method>_get_win32_case_sensitive_name</Method></Frame><Frame><File>PySide\_utils.pyc</File><Line>58</Line><Method>_get_win32_short_name</Method></Frame></Stack></Post><Post><PostId>17548779</PostId><Url>http://stackoverflow.com/questions/17548779</Url><Stack><Type>WindowsError</Type><Message>[Error 127] Die angegebene Prozedur wurde nicht gefunden</Message><Frame><File>C:\Python27\Scripts\spyder-script.py</File><Line>9</Line><Method>load_entry_point('spyder==2.2.0', 'console_scripts', 'spyder')()</Method></Frame><Frame><File>C:\Python27\lib\site-packages\spyderlib\start_app.py</File><Line>72</Line><Method>main</Method></Frame><Frame><File>C:\Python27\lib\site-packages\spyderlib\spyder.py</File><Line>112</Line><Method>from spyderlib.plugins.ipythonconsole import IPythonConsole</Method></Frame><Frame><File>C:\Python27\lib\site-packages\spyderlib\plugins\ipythonconsole.py</File><Line>31</Line><Method>from IPython.frontend.qt.kernelmanager import QtKernelManager</Method></Frame><Frame><File>C:\Python27\lib\site-packages\IPython\frontend\qt\kernelmanager.py</File><Line>9</Line><Method>from IPython.zmq.kernelmanager import KernelManager, SubSocketChannel, \</Method></Frame><Frame><File>C:\Python27\lib\site-packages\IPython\zmq\__init__.py</File><Line>67</Line><Method>check_for_zmq('2.1.4')</Method></Frame><Frame><File>C:\Python27\lib\site-packages\IPython\zmq\__init__.py</File><Line>51</Line><Method>check_for_zmq</Method></Frame><Frame><File>C:\Python27\lib\site-packages\zmq\__init__.py</File><Line>35</Line><Method>_libzmq = ctypes.CDLL(bundled[0], mode=ctypes.RTLD_GLOBAL)</Method></Frame><Frame><File>C:\Python27\lib\ctypes\__init__.py</File><Line>365</Line><Method>__init__</Method></Frame></Stack></Post><Post><PostId>17612470</PostId><Url>http://stackoverflow.com/questions/17612470</Url><Stack><Type>WindowsError</Type><Message>[Error 3] The system cannot find the path specified</Message><Frame><File>B:\GitHub\ingress-apk-mod\bin\import_apk.py</File><Line>28</Line><Method>module</Method></Frame><Frame><File>B:\GitHub\ingress-apk-mod\bin\import_apk.py</File><Line>24</Line><Method>main</Method></Frame><Frame><File>C:\Python32\lib\subprocess.py</File><Line>483</Line><Method>check_call</Method></Frame><Frame><File>C:\Python32\lib\subprocess.py</File><Line>470</Line><Method>call</Method></Frame><Frame><File>C:\Python32\lib\subprocess.py</File><Line>744</Line><Method>__init__</Method></Frame><Frame><File>C:\Python32\lib\subprocess.py</File><Line>977</Line><Method>_execute_child</Method></Frame></Stack></Post><Post><PostId>17702784</PostId><Url>http://stackoverflow.com/questions/17702784</Url><Stack><Type>WindowsError</Type><Message>[Error 267] The directory name is invalid: 'C:\\Users\\JG</Message><Frame><File>CopyDir.py</File><Line>46</Line><Method>copyFiles</Method></Frame></Stack></Post><Post><PostId>17722631</PostId><Url>http://stackoverflow.com/questions/17722631</Url><Stack><Type>WindowsError</Type><Message>[Error 32] The process cannot access the file because it is being used by another process</Message><Frame><File>C:\tempstore\Filescan1</File><Line>18</Line><Method>module</Method></Frame></Stack></Post><Post><PostId>18030795</PostId><Url>http://stackoverflow.com/questions/18030795</Url><Stack><Type>WindowsError</Type><Message>[Error 5] 存取被拒。</Message><Frame><File>C:\google_appengine\google\appengine\tools\devappserver2\php_runtime.py</File><Line>212</Line><Method>new_instance</Method></Frame><Frame><File>C:\google_appengine\google\appengine\tools\devappserver2\php_runtime.py</File><Line>156</Line><Method>_check_environment</Method></Frame><Frame><File>C:\google_appengine\google\appengine\tools\devappserver2\safe_subprocess.py</File><Line>61</Line><Method>start_process</Method></Frame><Frame><File>C:\python\lib\subprocess.py</File><Line>711</Line><Method>__init__</Method></Frame><Frame><File>C:\python\lib\subprocess.py</File><Line>948</Line><Method>_execute_child</Method></Frame></Stack></Post><Post><PostId>18228162</PostId><Url>http://stackoverflow.com/questions/18228162</Url><Stack><Type>WindowsError</Type><Message>[Error 2] The system cannot find the file specified: 'D:/music/Pau</Message><Frame><File>uni.py</File><Line>9</Line><Method>module</Method></Frame><Frame><File>C:\program files\python27\lib\genericpath.py</File><Line>49</Line><Method>getsize</Method></Frame></Stack></Post><Post><PostId>18390341</PostId><Url>http://stackoverflow.com/questions/18390341</Url><Stack><Type>WindowsError</Type><Message>[Error 123] The filename, directory name, or volume label syntax is incorrect: u'\\\\?\\\\\\Uni-hq-srv6\\router\\*.*'</Message><Frame><File>pyshell#160</File><Line>1</Line><Method>module</Method></Frame></Stack></Post><Post><PostId>18529415</PostId><Url>http://stackoverflow.com/questions/18529415</Url><Stack><Type>WindowsError</Type><Message>[Error 123] The filename, directory name, or volume label syntax i</Message><Frame><File>testss.py</File><Line>19</Line><Method>module</Method></Frame><Frame><File>c:\python27\lib\fileinput.py</File><Line>253</Line><Method>next</Method></Frame><Frame><File>c:\python27\lib\fileinput.py</File><Line>322</Line><Method>readline</Method></Frame></Stack></Post><Post><PostId>18566016</PostId><Url>http://stackoverflow.com/questions/18566016</Url><Stack><Type>WindowsError</Type><Message>[Error 3] The system cannot find the path specified: 'C:\\CEF\\nod</Message><Frame><File>C:\CEF\depot_tools\depot_tools\\gclient.py</File><Line>1804</Line><Method>module</Method></Frame><Frame><File>C:\CEF\depot_tools\depot_tools\\gclient.py</File><Line>1794</Line><Method>Main</Method></Frame><Frame><File>C:\CEF\depot_tools\depot_tools\subcommand.py</File><Line>245</Line><Method>execute</Method></Frame><Frame><File>C:\CEF\depot_tools\depot_tools\\gclient.py</File><Line>1590</Line><Method>CMDsync</Method></Frame><Frame><File>C:\CEF\depot_tools\depot_tools\\gclient.py</File><Line>1152</Line><Method>RunOnDeps</Method></Frame><Frame><File>C:\CEF\depot_tools\depot_tools\gclient_utils.py</File><Line>755</Line><Method>run</Method></Frame><Frame><File>C:\CEF\depot_tools\depot_tools\\gclient.py</File><Line>627</Line><Method>run</Method></Frame><Frame><File>C:\CEF\depot_tools\depot_tools\gclient_scm.py</File><Line>151</Line><Method>RunCommand</Method></Frame><Frame><File>C:\CEF\depot_tools\depot_tools\gclient_scm.py</File><Line>357</Line><Method>update</Method></Frame><Frame><File>C:\CEF\depot_tools\depot_tools\gclient_scm.py</File><Line>879</Line><Method>_Clone</Method></Frame></Stack></Post><Post><PostId>18645520</PostId><Url>http://stackoverflow.com/questions/18645520</Url><Stack><Type>WindowsError</Type><Message>[Error 87] The parameter is incorrect</Message><Frame><File>C:/Python27/test/helloworld.py</File><Line>4</Line><Method>module</Method></Frame><Frame><File>C:\Python27\lib\site-packages\selenium-2.35.0-py2.7.egg\selenium\webdriver\firefox\webdriver.py</File><Line>60</Line><Method>__init__</Method></Frame><Frame><File>C:\Python27\lib\site-packages\selenium-2.35.0-py2.7.egg\selenium\webdriver\firefox\extension_connection.py</File><Line>47</Line><Method>__init__</Method></Frame><Frame><File>C:\Python27\lib\site-packages\selenium-2.35.0-py2.7.egg\selenium\webdriver\firefox\firefox_binary.py</File><Line>60</Line><Method>launch_browser</Method></Frame><Frame><File>C:\Python27\lib\site-packages\selenium-2.35.0-py2.7.egg\selenium\webdriver\firefox\firefox_binary.py</File><Line>83</Line><Method>_start_from_profile_path</Method></Frame><Frame><File>C:\Python27\lib\subprocess.py</File><Line>679</Line><Method>__init__</Method></Frame><Frame><File>C:\Python27\lib\subprocess.py</File><Line>893</Line><Method>_execute_child</Method></Frame></Stack></Post><Post><PostId>19039704</PostId><Url>http://stackoverflow.com/questions/19039704</Url><Stack><Type>WindowsError</Type><Message>[Error 32] The process cannot access the file because it is being used by another process: 'b.txt'</Message><Frame><File>.\file_del.py</File><Line>11</Line><Method>module</Method></Frame></Stack></Post><Post><PostId>19112944</PostId><Url>http://stackoverflow.com/questions/19112944</Url><Stack><Type>WindowsError</Type><Message>[Error 193] %1 er ikke et gyldigt Win32-program</Message><Frame><File>C:/Users/user/Desktop/Work/XlsDir.py</File><Line>16</Line><Method>module</Method></Frame><Frame><File>C:\Python27\lib\subprocess.py</File><Line>524</Line><Method>call</Method></Frame><Frame><File>C:\Python27\lib\subprocess.py</File><Line>711</Line><Method>__init__</Method></Frame><Frame><File>C:\Python27\lib\subprocess.py</File><Line>948</Line><Method>_execute_child</Method></Frame></Stack></Post><Post><PostId>19194022</PostId><Url>http://stackoverflow.com/questions/19194022</Url><Stack><Type>WindowsError</Type><Message>[Error 123] The filename, directory name, or volume label syntax is incorrect: '\\\\buildloc\\kernel\\*.patch/*.*'</Message><Frame><File>copytest.py</File><Line>47</Line><Method>module</Method></Frame><Frame><File>copytest.py</File><Line>44</Line><Method>main</Method></Frame><Frame><File>copytest.py</File><Line>18</Line><Method>copystuff</Method></Frame><Frame><File>C:\CRMApps\apps\Python262\lib\shutil.py</File><Line>140</Line><Method>copytree</Method></Frame></Stack></Post><Post><PostId>19257927</PostId><Url>http://stackoverflow.com/questions/19257927</Url><Stack><Type>WindowsError</Type><Message>[Error 2] The system cannot find the file specified</Message><Frame><File>pyshell#1</File><Line>1</Line><Method>module</Method></Frame><Frame><File>C:\Python26\lib\subprocess.py</File><Line>444</Line><Method>call</Method></Frame><Frame><File>C:\Python26\lib\subprocess.py</File><Line>595</Line><Method>__init__</Method></Frame><Frame><File>C:\Python26\lib\subprocess.py</File><Line>821</Line><Method>_execute_child</Method></Frame></Stack></Post><Post><PostId>19416456</PostId><Url>http://stackoverflow.com/questions/19416456</Url><Stack><Type>WindowsError</Type><Message>[Error 183] Cannot create a file when that file already exists</Message><Frame><File>Add_copyright.py</File><Line>69</Line><Method>module</Method></Frame><Frame><File>Add_copyright.py</File><Line>60</Line><Method>prepend_file</Method></Frame></Stack></Post><Post><PostId>19417230</PostId><Url>http://stackoverflow.com/questions/19417230</Url><Stack><Type>WindowsError</Type><Message>[Error 32] The process cannot access the file because it is being used by another process: 'C:\\Dropbox\\copyrights\\tmp18valt'</Message><Frame><File>Add_copyright.py</File><Line>69</Line><Method>module</Method></Frame><Frame><File>Add_copyright.py</File><Line>54</Line><Method>prepend_file</Method></Frame></Stack></Post><Post><PostId>19449941</PostId><Url>http://stackoverflow.com/questions/19449941</Url><Stack><Type>WindowsError</Type><Message>[Error 2] The system cannot find the file specified</Message><Frame><File>C:\Users\Test\workspace\Test\DeletePreferences.py</File><Line>9</Line><Method>module</Method></Frame></Stack></Post><Post><PostId>19458212</PostId><Url>http://stackoverflow.com/questions/19458212</Url><Stack><Type>WindowsError</Type><Message>[Error 2] Impossibile trovare il file specificato {traduction: Impossible to find specified file}</Message><Frame><File>C:\Users\Emanuele\Desktop\Project Z\Python\Imagesave\Imagesave\__init__.py</File><Line>7</Line><Method>module</Method></Frame><Frame><File>C:\Python27\lib\site-packages\pytesser.py</File><Line>44</Line><Method>image_file_to_string</Method></Frame><Frame><File>C:\Python27\lib\site-packages\pytesser.py</File><Line>21</Line><Method>call_tesseract</Method></Frame><Frame><File>C:\Python27\lib\subprocess.py</File><Line>711</Line><Method>__init__</Method></Frame><Frame><File>C:\Python27\lib\subprocess.py</File><Line>948</Line><Method>_execute_child</Method></Frame></Stack></Post><Post><PostId>19462782</PostId><Url>http://stackoverflow.com/questions/19462782</Url><Stack><Type>WindowsError</Type><Message>[Error 5] Access is denied: 'c:\\users\\ni\\appdata\\local\\temp\\</Message><Frame><File>si601lab6_sol.py</File><Line>29</Line><Method>module</Method></Frame><Frame><File>C:\Python27\lib\site-packages\mrjob\job.py</File><Line>500</Line><Method>run</Method></Frame><Frame><File>C:\Python27\lib\site-packages\mrjob\job.py</File><Line>518</Line><Method>execute</Method></Frame><Frame><File>C:\Python27\lib\site-packages\mrjob\launch.py</File><Line>146</Line><Method>execute</Method></Frame><Frame><File>C:\Python27\lib\site-packages\mrjob\launch.py</File><Line>207</Line><Method>run_job</Method></Frame><Frame><File>C:\Python27\lib\site-packages\mrjob\runner.py</File><Line>458</Line><Method>run</Method></Frame><Frame><File>C:\Python27\lib\site-packages\mrjob\sim.py</File><Line>182</Line><Method>_run</Method></Frame><Frame><File>C:\Python27\lib\site-packages\mrjob\sim.py</File><Line>269</Line><Method>_invoke_step</Method></Frame><Frame><File>C:\Python27\lib\site-packages\mrjob\inline.py</File><Line>155</Line><Method>_run_step</Method></Frame></Stack></Post><Post><PostId>19749404</PostId><Url>http://stackoverflow.com/questions/19749404</Url><Stack><Type>WindowsError</Type><Message>[Error 126] The specified module could not be found.</Message><Frame><File>C:\Users\Usuario\Desktop\rumble.py</File><Line>8</Line><Method>module</Method></Frame><Frame><File>C:\Python27\lib\ctypes\__init__.py</File><Line>435</Line><Method>__getattr__</Method></Frame><Frame><File>C:\Python27\lib\ctypes\__init__.py</File><Line>365</Line><Method>__init__</Method></Frame></Stack></Post><Post><PostId>19773953</PostId><Url>http://stackoverflow.com/questions/19773953</Url><Stack><Type>WindowsError</Type><Message>[Error 2] The system cannot find the file specified</Message><Frame><File>C:/Users/computer_4/Desktop/Scripts/crescentsaver.py</File><Line>2</Line><Method>module</Method></Frame><Frame><File>C:\Python27\lib\subprocess.py</File><Line>524</Line><Method>call</Method></Frame><Frame><File>C:\Python27\lib\subprocess.py</File><Line>711</Line><Method>__init__</Method></Frame><Frame><File>C:\Python27\lib\subprocess.py</File><Line>948</Line><Method>_execute_child</Method></Frame></Stack></Post><Post><PostId>19819417</PostId><Url>http://stackoverflow.com/questions/19819417</Url><Stack><Type>WindowsError</Type><Message>[Error 2] The system cannot find the file specified</Message><Frame><File>C:\Python27\MyPython\MyCode.py</File><Line>7</Line><Method>module</Method></Frame><Frame><File>C:\Python27\MyPython\MyCode.py</File><Line>4</Line><Method>runcmd</Method></Frame><Frame><File>C:\Python27\lib\subprocess.py</File><Line>679</Line><Method>__init__</Method></Frame><Frame><File>C:\Python27\lib\subprocess.py</File><Line>893</Line><Method>_execute_child</Method></Frame></Stack></Post><Post><PostId>19849077</PostId><Url>http://stackoverflow.com/questions/19849077</Url><Stack><Type>WindowsError</Type><Message>[Error 193] %1 is not a valid Win32 application</Message><Frame><File>test.py</File><Line>4</Line><Method>module</Method></Frame><Frame><File>C:\Python27\lib\ctypes\__init__.py</File><Line>365</Line><Method>__init__</Method></Frame></Stack></Post><Post><PostId>19900986</PostId><Url>http://stackoverflow.com/questions/19900986</Url><Stack><Type>WindowsError</Type><Message>[Error 2] The system cannot find the file specified</Message><Frame><File>setup.py</File><Line>37</Line><Method>module</Method></Frame><Frame><File>D:\Python27\lib\subprocess.py</File><Line>711</Line><Method>__init__</Method></Frame><Frame><File>D:\Python27\lib\subprocess.py</File><Line>948</Line><Method>_execute_child</Method></Frame></Stack></Post><Post><PostId>20061246</PostId><Url>http://stackoverflow.com/questions/20061246</Url><Stack><Type>WindowsError</Type><Message>[Error 2] The system cannot find the file specified</Message><Frame><File>C:\Users\name\Desktop\browser-extensions.git\python-env\Scripts\forge- extension-script.py</File><Line>10</Line><Method>module</Method></Frame><Frame><File>c:\users\name\desktop\browser-extensions.git\generate\build_tools\main .py</File><Line>227</Line><Method>main</Method></Frame><Frame><File>c:\users\name\desktop\browser-extensions.git\generate\build_tools\main .py</File><Line>94</Line><Method>command_build</Method></Frame><Frame><File>c:\users\name\desktop\browser-extensions.git\generate\generate\main.py</File><Line>237</Line><Method>main</Method></Frame><Frame><File>c:\users\name\desktop\browser-extensions.git\generate\generate\main.py</File><Line>107</Line><Method>run</Method></Frame><Frame><File>c:\users\name\desktop\browser-extensions.git\generate\generate\build.p y</File><Line>308</Line><Method>run</Method></Frame><Frame><File>c:\users\name\desktop\browser-extensions.git\generate\generate\build.p y</File><Line>267</Line><Method>_call_with_params</Method></Frame><Frame><File>c:\users\name\desktop\browser-extensions.git\generate\generate\server_ tasks.py</File><Line>115</Line><Method>minify_in_place</Method></Frame><Frame><File>c:\users\name\desktop\browser-extensions.git\generate\generate\minify. py</File><Line>32</Line><Method>minify_in_place</Method></Frame><Frame><File>C:\Python27\Lib\subprocess.py</File><Line>711</Line><Method>__init__</Method></Frame><Frame><File>C:\Python27\Lib\subprocess.py</File><Line>948</Line><Method>_execute_child</Method></Frame></Stack></Post><Post><PostId>20104139</PostId><Url>http://stackoverflow.com/questions/20104139</Url><Stack><Type>WindowsError</Type><Message>[Error -529697949] Windows Error 0xE06D7363</Message><Frame><File>D:\Tools\Python_Scripts\point_info.py</File><Line>46</Line><Method>module</Method></Frame><Frame><File>C:\Python27\ArcGIS10.1\lib\site-packages\liblas\point.py</File><Line>560</Line><Method>get_data</Method></Frame><Frame><File>C:\Python27\ArcGIS10.1\lib\site-packages\liblas\point.py</File><Line>546</Line><Method>get_header</Method></Frame></Stack></Post><Post><PostId>20283879</PostId><Url>http://stackoverflow.com/questions/20283879</Url><Stack><Type>WindowsError</Type><Message>[Error 2]</Message><Frame><File>E:\jenkins_tmp\my_utils\temp2.py</File><Line>8</Line><Method>module</Method></Frame><Frame><File>C:\Program Files (x86)\Python27\lib\subprocess.py</File><Line>679</Line><Method>__init__</Method></Frame><Frame><File>C:\Program Files (x86)\Python27\lib\subprocess.py</File><Line>893</Line><Method>_execute_child</Method></Frame></Stack></Post><Post><PostId>20293995</PostId><Url>http://stackoverflow.com/questions/20293995</Url><Stack><Type>WindowsError</Type><Message>[Error 87] The parameter is incorrect</Message><Frame><File>C:/Users/Kaushik/Desktop/IMC DEVELOPER TEST/Sample.py</File><Line>4</Line><Method>module</Method></Frame><Frame><File>C:\Python27\lib\site-packages\selenium-2.37.2-py2.7.egg\selenium\webdriver\firefox\webdriver.py</File><Line>59</Line><Method>__init__</Method></Frame><Frame><File>C:\Python27\lib\site-packages\selenium-2.37.2-py2.7.egg\selenium\webdriver\firefox\extension_connection.py</File><Line>47</Line><Method>__init__</Method></Frame><Frame><File>C:\Python27\lib\site-packages\selenium-2.37.2-py2.7.egg\selenium\webdriver\firefox\firefox_binary.py</File><Line>60</Line><Method>launch_browser</Method></Frame><Frame><File>C:\Python27\lib\site-packages\selenium-2.37.2-py2.7.egg\selenium\webdriver\firefox\firefox_binary.py</File><Line>83</Line><Method>_start_from_profile_path</Method></Frame><Frame><File>C:\Python27\lib\subprocess.py</File><Line>709</Line><Method>__init__</Method></Frame><Frame><File>C:\Python27\lib\subprocess.py</File><Line>957</Line><Method>_execute_child</Method></Frame></Stack></Post><Post><PostId>20330385</PostId><Url>http://stackoverflow.com/questions/20330385</Url><Stack><Type>WindowsError</Type><Message>[Error 2] The system cannot find the file specified</Message><Frame><File>test.py</File><Line>2</Line><Method>module</Method></Frame><Frame><File>C:\Python27\lib\subprocess.py</File><Line>522</Line><Method>call</Method></Frame><Frame><File>C:\Python27\lib\subprocess.py</File><Line>709</Line><Method>__init__</Method></Frame><Frame><File>C:\Python27\lib\subprocess.py</File><Line>957</Line><Method>_execute_child</Method></Frame><Frame><File>test.py</File><Line>4</Line><Method>module</Method></Frame><Frame><File>C:\Python27\lib\subprocess.py</File><Line>522</Line><Method>call</Method></Frame><Frame><File>C:\Python27\lib\subprocess.py</File><Line>709</Line><Method>__init__</Method></Frame><Frame><File>C:\Python27\lib\subprocess.py</File><Line>957</Line><Method>_execute_child</Method></Frame></Stack></Post><Post><PostId>20330385</PostId><Url>http://stackoverflow.com/questions/20330385</Url><Stack><Type>WindowsError</Type><Message>[Error 2] The system cannot find the file specified</Message><Frame><File>test.py</File><Line>2</Line><Method>module</Method></Frame><Frame><File>C:\Python27\lib\subprocess.py</File><Line>522</Line><Method>call</Method></Frame><Frame><File>C:\Python27\lib\subprocess.py</File><Line>709</Line><Method>__init__</Method></Frame><Frame><File>C:\Python27\lib\subprocess.py</File><Line>957</Line><Method>_execute_child</Method></Frame><Frame><File>test.py</File><Line>4</Line><Method>module</Method></Frame><Frame><File>C:\Python27\lib\subprocess.py</File><Line>522</Line><Method>call</Method></Frame><Frame><File>C:\Python27\lib\subprocess.py</File><Line>709</Line><Method>__init__</Method></Frame><Frame><File>C:\Python27\lib\subprocess.py</File><Line>957</Line><Method>_execute_child</Method></Frame></Stack></Post><Post><PostId>20335220</PostId><Url>http://stackoverflow.com/questions/20335220</Url><Stack><Type>WindowsError</Type><Message>[Error 2] The system cannot find the file specified</Message><Frame><File>C:\test\rename_jpg\rename_jpg.py</File><Line>4</Line><Method>module</Method></Frame></Stack></Post><Post><PostId>20658834</PostId><Url>http://stackoverflow.com/questions/20658834</Url><Stack><Type>WindowsError</Type><Message>[Error 32] The process cannot access the file because it is being used by another process: 'c:\\users\\michal~1\\appdata\\local\\temp\\harness-stdout-l8remz'</Message><Frame><File>C:\Users\michal smoczyk\Downloads\addon-sdk-1.14\bin\cfx</File><Line>33</Line><Method>module</Method></Frame><Frame><File>C:\Users\michal smoczyk\Downloads\addon-sdk-1.14\python-lib\cuddlefish\__init__.py</File><Line>928</Line><Method>run</Method></Frame><Frame><File>C:\Users\michal smoczyk\Downloads\addon-sdk-1.14\python-lib\cuddlefish\runner.py</File><Line>706</Line><Method>run_app</Method></Frame><Frame><File>C:\Users\michal smoczyk\Downloads\addon-sdk-1.14\python-lib\mozrunner\__init__.py</File><Line>529</Line><Method>start</Method></Frame><Frame><File>C:\Users\michal smoczyk\Downloads\addon-sdk-1.14\python-lib\mozrunner\__init__.py</File><Line>59</Line><Method>run_command</Method></Frame><Frame><File>C:\Python27\lib\subprocess.py</File><Line>709</Line><Method>__init__</Method></Frame><Frame><File>C:\Python27\lib\atexit.py</File><Line>24</Line><Method>_run_exitfuncs</Method></Frame><Frame><File>C:\Users\michal smoczyk\Downloads\addon-sdk-1.14\python-lib\cuddlefish\runner.py</File><Line>534</Line><Method>maybe_remove_outfile</Method></Frame><Frame><File>C:\Python27\lib\atexit.py</File><Line>24</Line><Method>_run_exitfuncs</Method></Frame><Frame><File>C:\Users\michal smoczyk\Downloads\addon-sdk-1.14\python-lib\cuddlefish\runner.py</File><Line>534</Line><Method>maybe_remove_outfile</Method></Frame></Stack></Post><Post><PostId>20658834</PostId><Url>http://stackoverflow.com/questions/20658834</Url><Stack><Type>WindowsError</Type><Message>[Error 32] The process cannot access the file because it is being used by another process: 'c:\\users\\michal~1\\appdata\\local\\temp\\harness-stdout-l8remz'</Message><Frame><File>C:\Users\michal smoczyk\Downloads\addon-sdk-1.14\bin\cfx</File><Line>33</Line><Method>module</Method></Frame><Frame><File>C:\Users\michal smoczyk\Downloads\addon-sdk-1.14\python-lib\cuddlefish\__init__.py</File><Line>928</Line><Method>run</Method></Frame><Frame><File>C:\Users\michal smoczyk\Downloads\addon-sdk-1.14\python-lib\cuddlefish\runner.py</File><Line>706</Line><Method>run_app</Method></Frame><Frame><File>C:\Users\michal smoczyk\Downloads\addon-sdk-1.14\python-lib\mozrunner\__init__.py</File><Line>529</Line><Method>start</Method></Frame><Frame><File>C:\Users\michal smoczyk\Downloads\addon-sdk-1.14\python-lib\mozrunner\__init__.py</File><Line>59</Line><Method>run_command</Method></Frame><Frame><File>C:\Python27\lib\subprocess.py</File><Line>709</Line><Method>__init__</Method></Frame><Frame><File>C:\Python27\lib\atexit.py</File><Line>24</Line><Method>_run_exitfuncs</Method></Frame><Frame><File>C:\Users\michal smoczyk\Downloads\addon-sdk-1.14\python-lib\cuddlefish\runner.py</File><Line>534</Line><Method>maybe_remove_outfile</Method></Frame><Frame><File>C:\Python27\lib\atexit.py</File><Line>24</Line><Method>_run_exitfuncs</Method></Frame><Frame><File>C:\Users\michal smoczyk\Downloads\addon-sdk-1.14\python-lib\cuddlefish\runner.py</File><Line>534</Line><Method>maybe_remove_outfile</Method></Frame></Stack></Post><Post><PostId>20658834</PostId><Url>http://stackoverflow.com/questions/20658834</Url><Stack><Type>WindowsError</Type><Message>[Error 32] The process cannot access the file because it is being used by another process: 'c:\\users\\michal~1\\appdata\\local\\temp\\harness-stdout-l8remz'</Message><Frame><File>C:\Users\michal smoczyk\Downloads\addon-sdk-1.14\bin\cfx</File><Line>33</Line><Method>module</Method></Frame><Frame><File>C:\Users\michal smoczyk\Downloads\addon-sdk-1.14\python-lib\cuddlefish\__init__.py</File><Line>928</Line><Method>run</Method></Frame><Frame><File>C:\Users\michal smoczyk\Downloads\addon-sdk-1.14\python-lib\cuddlefish\runner.py</File><Line>706</Line><Method>run_app</Method></Frame><Frame><File>C:\Users\michal smoczyk\Downloads\addon-sdk-1.14\python-lib\mozrunner\__init__.py</File><Line>529</Line><Method>start</Method></Frame><Frame><File>C:\Users\michal smoczyk\Downloads\addon-sdk-1.14\python-lib\mozrunner\__init__.py</File><Line>59</Line><Method>run_command</Method></Frame><Frame><File>C:\Python27\lib\subprocess.py</File><Line>709</Line><Method>__init__</Method></Frame><Frame><File>C:\Python27\lib\atexit.py</File><Line>24</Line><Method>_run_exitfuncs</Method></Frame><Frame><File>C:\Users\michal smoczyk\Downloads\addon-sdk-1.14\python-lib\cuddlefish\runner.py</File><Line>534</Line><Method>maybe_remove_outfile</Method></Frame><Frame><File>C:\Python27\lib\atexit.py</File><Line>24</Line><Method>_run_exitfuncs</Method></Frame><Frame><File>C:\Users\michal smoczyk\Downloads\addon-sdk-1.14\python-lib\cuddlefish\runner.py</File><Line>534</Line><Method>maybe_remove_outfile</Method></Frame></Stack></Post><Post><PostId>20796355</PostId><Url>http://stackoverflow.com/questions/20796355</Url><Stack><Type>WindowsError</Type><Message>[Error 3] The system cannot find the path specified:   '../headfirstpython/chapter3'</Message><Frame><File>pyshell#2</File><Line>1</Line><Method>module</Method></Frame><Frame><File>pyshell#3</File><Line>1</Line><Method>module</Method></Frame></Stack></Post><Post><PostId>20796355</PostId><Url>http://stackoverflow.com/questions/20796355</Url><Stack><Type>WindowsError</Type><Message>[Error 3] The system cannot find the path specified:   '../headfirstpython/chapter3'</Message><Frame><File>pyshell#2</File><Line>1</Line><Method>module</Method></Frame><Frame><File>pyshell#3</File><Line>1</Line><Method>module</Method></Frame></Stack></Post><Post><PostId>20830444</PostId><Url>http://stackoverflow.com/questions/20830444</Url><Stack><Type>WindowsError</Type><Message>exception: access violation reading 0x00000028</Message><Frame><File>string</File><Line>1</Line><Method>module</Method></Frame><Frame><File>string</File><Line>16</Line><Method>MessageBox</Method></Frame></Stack></Post><Post><PostId>21088370</PostId><Url>http://stackoverflow.com/questions/21088370</Url><Stack><Type>WindowsError</Type><Message>[Error 2] El sistema no puede hallar el archivo especificado</Message><Frame><File>C:\Documents and Settings\Administrador\workspace\Interfaz\bashpython.py</File><Line>3</Line><Method>module</Method></Frame><Frame><File>C:\Python27\lib\subprocess.py</File><Line>486</Line><Method>call</Method></Frame><Frame><File>C:\Python27\lib\subprocess.py</File><Line>672</Line><Method>__init__</Method></Frame><Frame><File>C:\Python27\lib\subprocess.py</File><Line>882</Line><Method>_execute_child</Method></Frame></Stack></Post><Post><PostId>21100626</PostId><Url>http://stackoverflow.com/questions/21100626</Url><Stack><Type>WindowsError</Type><Message>[Error 126] The specified module could not be found</Message><Frame><File>b.py</File><Line>8</Line><Method>module</Method></Frame><Frame><File>c:\Python27\lib\ctypes\__init__.py</File><Line>443</Line><Method>LoadLibrary</Method></Frame><Frame><File>c:\Python27\lib\ctypes\__init__.py</File><Line>365</Line><Method>__init__</Method></Frame></Stack></Post><Post><PostId>21268706</PostId><Url>http://stackoverflow.com/questions/21268706</Url><Stack><Type>WindowsError</Type><Message>[Error 2] The system cannot find the file specified</Message><Frame><File>setup.py</File><Line>47</Line><Method>module</Method></Frame><Frame><File>setup.py</File><Line>32</Line><Method>pkgconfig</Method></Frame><Frame><File>C:\Python27\lib\subprocess.py</File><Line>537</Line><Method>check_output</Method></Frame><Frame><File>C:\Python27\lib\subprocess.py</File><Line>679</Line><Method>__init__</Method></Frame><Frame><File>C:\Python27\lib\subprocess.py</File><Line>893</Line><Method>_execute_child</Method></Frame></Stack></Post><Post><PostId>21323257</PostId><Url>http://stackoverflow.com/questions/21323257</Url><Stack><Type>WindowsError</Type><Message>[Error 87] The parameter is incorrect</Message><Frame><File>C:\Python27\lib\threading.py</File><Line>810</Line><Method>__bootstrap_innerself.run()</Method></Frame><Frame><File>C:\Python27\lib\threading.py</File><Line>763</Line><Method>runself.__target(*self.__args, **self.__kwargs)</Method></Frame><Frame><File>C:\Users\Tyler\Desktop\GoPMABD\go_appengine\google\appengine\tools\devappserver2\module.py</File><Line>1265</Line><Method>_loop_adjusting_instances</Method></Frame><Frame><File>C:\Users\Tyler\Desktop\GoPMABD\go_appengine\google\appengine\tools\devappserver2\module.py</File><Line>1242</Line><Method>_adjust_instances</Method></Frame><Frame><File>C:\Users\Tyler\Desktop\GoPMABD\go_appengine\google\appengine\tools\devappserver2\module.py</File><Line>1120</Line><Method>_add_instance</Method></Frame><Frame><File>C:\Users\Tyler\Desktop\GoPMABD\go_appengine\google\appengine\tools\devappserver2\go_runtime.py</File><Line>165</Line><Method>new_instance</Method></Frame><Frame><File>C:\Users\Tyler\Desktop\GoPMABD\go_appengine\google\appengine\tools\devappserver2\go_application.py</File><Line>259</Line><Method>maybe_build</Method></Frame><Frame><File>C:\Users\Tyler\Desktop\GoPMABD\go_appengine\google\appengine\tools\devappserver2\go_application.py</File><Line>192</Line><Method>_get_extras_hash</Method></Frame><Frame><File>C:\Users\Tyler\Desktop\GoPMABD\go_appengine\google\appengine\tools\devappserver2\safe_subprocess.py</File><Line>74</Line><Method>start_process</Method></Frame><Frame><File>C:\Python27\lib\subprocess.py</File><Line>709</Line><Method>__init__</Method></Frame><Frame><File>C:\Python27\lib\subprocess.py</File><Line>957</Line><Method>_execute_child</Method></Frame></Stack></Post><Post><PostId>21334328</PostId><Url>http://stackoverflow.com/questions/21334328</Url><Stack><Type>WindowsError</Type><Message>[Error 2] The system can not find the file specified: '%(name)s'</Message><Frame><File>C:/Users/Fatt-DELL-3/ser.py</File><Line>10</Line><Method>module</Method></Frame><Frame><File>C:\Program Files\IBM\SPSS\Statistics\22\Python\lib\zipfile.py</File><Line>1031</Line><Method>write</Method></Frame></Stack></Post><Post><PostId>21420787</PostId><Url>http://stackoverflow.com/questions/21420787</Url><Stack><Type>WindowsError</Type><Message>[Error 2]</Message><Frame><File>E:\Code\Eclipse\IE411HW1\problem1.py</File><Line>11</Line><Method>module</Method></Frame><Frame><File>E:\learning software\Python\lib\site-packages\coinor.gimpy-1.1.0-py2.7.egg\coinor\gimpy\graph.py</File><Line>1625</Line><Method>display</Method></Frame><Frame><File>E:\learning software\Python\lib\site-packages\coinor.gimpy-1.1.0-py2.7.egg\coinor\gimpy\graph.py</File><Line>1559</Line><Method>create</Method></Frame><Frame><File>E:\learning software\Python\lib\subprocess.py</File><Line>711</Line><Method>__init__</Method></Frame><Frame><File>E:\learning software\Python\lib\subprocess.py</File><Line>948</Line><Method>_execute_child</Method></Frame></Stack></Post><Post><PostId>21501721</PostId><Url>http://stackoverflow.com/questions/21501721</Url><Stack><Type>WindowsError</Type><Message>[Error 32] The process cannot access the file because it is being used by       another process</Message><Frame><File>rastertool3.py</File><Line>266</Line><Method>module</Method></Frame><Frame><File>rastertool3.py</File><Line>183</Line><Method>sel2rast</Method></Frame><Frame><File>rastertool3.py</File><Line>146</Line><Method>backupOrigRenNew</Method></Frame></Stack></Post><Post><PostId>21503558</PostId><Url>http://stackoverflow.com/questions/21503558</Url><Stack><Type>WindowsError</Type><Message>[Error 6] The handle is invalid.</Message><Frame><File>C:\Python27\lib\site-packages\cherrypy\process\servers.py</File><Line>188</Line><Method>_start_http_thread</Method></Frame><Frame><File>C:\Python27\lib\site-packages\cherrypy\wsgiserver\wsgiserver2.py</File><Line>1836</Line><Method>start</Method></Frame><Frame><File>C:\Python27\lib\site-packages\cherrypy\wsgiserver\wsgiserver2.py</File><Line>1883</Line><Method>bind</Method></Frame><Frame><File>C:\Python27\lib\site-packages\cherrypy\wsgiserver\wsgiserver2.py</File><Line>1599</Line><Method>prevent_socket_inheritance</Method></Frame></Stack></Post><Post><PostId>21590012</PostId><Url>http://stackoverflow.com/questions/21590012</Url><Stack><Type>WindowsError</Type><Message>[Error 2] The system cannot find the file specified</Message><Frame><File>v2_PEP8.py</File><Line>286</Line><Method>module</Method></Frame><Frame><File>v2_PEP8.py</File><Line>226</Line><Method>p4</Method></Frame><Frame><File>C:\Programs\python\App\lib\subprocess.py</File><Line>711</Line><Method>__init__</Method></Frame><Frame><File>C:\Programs\python\App\lib\subprocess.py</File><Line>948</Line><Method>_execute_child</Method></Frame></Stack></Post><Post><PostId>21839298</PostId><Url>http://stackoverflow.com/questions/21839298</Url><Stack><Type>WindowsError</Type><Message>[Error 2] Le fichier spÚcifiÚ est introuvable</Message><Frame><File>script/oic_flow_tests.py</File><Line>232</Line><Method>module</Method></Frame><Frame><File>C:\python27\lib\subprocess.py</File><Line>709</Line><Method>__init__</Method></Frame><Frame><File>C:\python27\lib\subprocess.py</File><Line>957</Line><Method>_execute_child</Method></Frame></Stack></Post><Post><PostId>22015901</PostId><Url>http://stackoverflow.com/questions/22015901</Url><Stack><Type>WindowsError</Type><Message>[Error 3] The system cannot find the path specified: 'C:\\</Message><Frame><File>ftpdownload2.py</File><Line>44</Line><Method>module</Method></Frame><Frame><File>ftpdownload2.py</File><Line>38</Line><Method>downloadFiles</Method></Frame></Stack></Post><Post><PostId>22026453</PostId><Url>http://stackoverflow.com/questions/22026453</Url><Stack><Type>WindowsError</Type><Message>[Error 5] Access is denied</Message><Frame><File>testing12.py</File><Line>20</Line><Method>module</Method></Frame><Frame><File>c:\Python27\lib\subprocess.py</File><Line>522</Line><Method>call</Method></Frame><Frame><File>c:\Python27\lib\subprocess.py</File><Line>709</Line><Method>__init__</Method></Frame><Frame><File>c:\Python27\lib\subprocess.py</File><Line>957</Line><Method>_execute_child</Method></Frame></Stack></Post><Post><PostId>22063869</PostId><Url>http://stackoverflow.com/questions/22063869</Url><Stack><Type>WindowsError</Type><Message>[Error 32] The process cannot access the file because it is being used by another process</Message><Frame><File>pyshell#4</File><Line>2</Line><Method>module</Method></Frame></Stack></Post><Post><PostId>22282385</PostId><Url>http://stackoverflow.com/questions/22282385</Url><Stack><Type>WindowsError</Type><Message>exception: access violation reading 0x00000028</Message><Frame><File>script.py</File><Line>14</Line><Method>module</Method></Frame></Stack></Post><Post><PostId>22408489</PostId><Url>http://stackoverflow.com/questions/22408489</Url><Stack><Type>WindowsError</Type><Message>[Error 32] The process cannot access the file because it is being</Message><Frame><File>insert_n_blank_rows.py</File><Line>93</Line><Method>module</Method></Frame><Frame><File>insert_n_blank_rows.py</File><Line>89</Line><Method>main</Method></Frame><Frame><File>insert_n_blank_rows.py</File><Line>80</Line><Method>insert_n_blank_rows</Method></Frame></Stack></Post><Post><PostId>22461767</PostId><Url>http://stackoverflow.com/questions/22461767</Url><Stack><Type>WindowsError</Type><Message>[Error 2] The system cannot find the file specified: '\n\t\tC:\\Users\\Jens\\Documents\\V\xe5r 2014\\TMA4245 Statistikk\\Probability</Message><Frame><File>session.py</File><Line>19</Line><Method>module</Method></Frame></Stack></Post><Post><PostId>22621978</PostId><Url>http://stackoverflow.com/questions/22621978</Url><Stack><Type>WindowsError</Type><Message>[Error 2] The system cannot find the file specified</Message><Frame><File>C:\NDEPGIS\Scripts\baqp_permits_aris_daily</File><Line>28</Line><Method>module</Method></Frame></Stack></Post><Post><PostId>22631202</PostId><Url>http://stackoverflow.com/questions/22631202</Url><Stack><Type>WindowsError</Type><Message>exception: access violation reading 0x03F3B000</Message><Frame><File>test.py</File><Line>15</Line><Method>module</Method></Frame><Frame><File>C:\Python27\lib\site-packages\sdl2\ext\sprite.py</File><Line>643</Line><Method>render</Method></Frame></Stack></Post><Post><PostId>22793650</PostId><Url>http://stackoverflow.com/questions/22793650</Url><Stack><Type>WindowsError</Type><Message>[Error 5] Access is denied</Message><Frame><File>c:\python27\scripts\virtualenv-script.py</File><Line>9</Line><Method>module</Method></Frame><Frame><File>C:\Python27\lib\site-packages\virtualenv.py</File><Line>779</Line><Method>main</Method></Frame><Frame><File>C:\Python27\lib\subprocess.py</File><Line>709</Line><Method>__init__</Method></Frame><Frame><File>C:\Python27\lib\subprocess.py</File><Line>957</Line><Method>_execute_child</Method></Frame></Stack></Post><Post><PostId>22917011</PostId><Url>http://stackoverflow.com/questions/22917011</Url><Stack><Type>WindowsError</Type><Message>[Error 32] The process cannot access the file because it is being used by another process</Message><Frame><File>C:\Apps\UtilitiesByMarc\bates_stamp_pdf_files_using_veryPDF_and_regex_match_groups_and_verbose_.py</File><Line>56</Line><Method>module</Method></Frame><Frame><File>C:\Python27\lib\subprocess.py</File><Line>493</Line><Method>call</Method></Frame><Frame><File>C:\Python27\lib\subprocess.py</File><Line>679</Line><Method>__init__</Method></Frame><Frame><File>C:\Python27\lib\subprocess.py</File><Line>896</Line><Method>_execute_child</Method></Frame></Stack></Post><Post><PostId>22990083</PostId><Url>http://stackoverflow.com/questions/22990083</Url><Stack><Type>WindowsError</Type><Message>[Error 126] The specified module could not be found</Message><Frame><File>c:/Users/ben/Desktop/Meld/meld/bin/meld</File><Line>98</Line><Method>module</Method></Frame><Frame><File>c:\Python27\lib\ctypes\__init__.py</File><Line>435</Line><Method>__getattr__</Method></Frame><Frame><File>c:\Python27\lib\ctypes\__init__.py</File><Line>365</Line><Method>__init__</Method></Frame></Stack></Post><Post><PostId>23005080</PostId><Url>http://stackoverflow.com/questions/23005080</Url><Stack><Type>WindowsError</Type><Message>[Error 6] The handle is invalid.</Message><Frame><File>C:\Python32\lib\site-packages\cherrypy\wsgiserver\wsgiserver3.py</File><Line>1563</Line><Method>start</Method></Frame><Frame><File>C:\Python32\lib\site-packages\cherrypy\wsgiserver\wsgiserver3.py</File><Line>1618</Line><Method>tick</Method></Frame><Frame><File>C:\Python32\lib\site-packages\cherrypy\wsgiserver\wsgiserver3.py</File><Line>1324</Line><Method>prevent_socket_inheritance</Method></Frame><Frame><File>C:\Python32\lib\site-packages\cherrypy\wsgiserver\wsgiserver3.py</File><Line>1563</Line><Method>start</Method></Frame><Frame><File>C:\Python32\lib\site-packages\cherrypy\wsgiserver\wsgiserver3.py</File><Line>1618</Line><Method>tick</Method></Frame><Frame><File>C:\Python32\lib\site-packages\cherrypy\wsgiserver\wsgiserver3.py</File><Line>1324</Line><Method>prevent_socket_inheritance</Method></Frame></Stack></Post><Post><PostId>23005080</PostId><Url>http://stackoverflow.com/questions/23005080</Url><Stack><Type>WindowsError</Type><Message>[Error 6] The handle is invalid.</Message><Frame><File>C:\Python32\lib\site-packages\cherrypy\wsgiserver\wsgiserver3.py</File><Line>1563</Line><Method>start</Method></Frame><Frame><File>C:\Python32\lib\site-packages\cherrypy\wsgiserver\wsgiserver3.py</File><Line>1618</Line><Method>tick</Method></Frame><Frame><File>C:\Python32\lib\site-packages\cherrypy\wsgiserver\wsgiserver3.py</File><Line>1324</Line><Method>prevent_socket_inheritance</Method></Frame><Frame><File>C:\Python32\lib\site-packages\cherrypy\wsgiserver\wsgiserver3.py</File><Line>1563</Line><Method>start</Method></Frame><Frame><File>C:\Python32\lib\site-packages\cherrypy\wsgiserver\wsgiserver3.py</File><Line>1618</Line><Method>tick</Method></Frame><Frame><File>C:\Python32\lib\site-packages\cherrypy\wsgiserver\wsgiserver3.py</File><Line>1324</Line><Method>prevent_socket_inheritance</Method></Frame></Stack></Post><Post><PostId>23079628</PostId><Url>http://stackoverflow.com/questions/23079628</Url><Stack><Type>WindowsError</Type><Message>[Error 2] The system cannot find the file specified`</Message><Frame><File>C:\Users\user\Desktop\test.py</File><Line>5</Line><Method>module</Method></Frame><Frame><File>C:\Python27\lib\site-packages\zopyx\convert2\convert.py</File><Line>33</Line><Method>convert</Method></Frame><Frame><File>C:\Python27\lib\site-packages\zopyx\convert2\xfc.py</File><Line>70</Line><Method>convert</Method></Frame><Frame><File>C:\Python27\lib\site-packages\zopyx\convert2\xfc.py</File><Line>48</Line><Method>fo2xfc</Method></Frame><Frame><File>C:\Python27\lib\site-packages\zopyx\convert2\util.py</File><Line>29</Line><Method>runcmd</Method></Frame><Frame><File>C:\Python27\lib\subprocess.py</File><Line>709</Line><Method>__init__</Method></Frame><Frame><File>C:\Python27\lib\subprocess.py</File><Line>957</Line><Method>_execute_child</Method></Frame></Stack></Post><Post><PostId>23395728</PostId><Url>http://stackoverflow.com/questions/23395728</Url><Stack><Type>WindowsError</Type><Message>[Error 123] 檔案名稱、目錄名稱或磁碟區標籤語法錯誤。: 'C:\\Users\\Heinz\\Desktop\tc_500'</Message><Frame><File>C:\Users\Heinz\Desktop\python_test\any_test.py</File><Line>13</Line><Method>module</Method></Frame></Stack></Post><Post><PostId>23410558</PostId><Url>http://stackoverflow.com/questions/23410558</Url><Stack><Type>WindowsError</Type><Message>[Error 5] Zugriff verweigert</Message><Frame><File>C:\Users\user\Documents\scripts\test\test\test.py</File><Line>1</Line><Method>module</Method></Frame><Frame><File>C:\Programme\Anaconda\lib\site-packages\pylab.py</File><Line>1</Line><Method>module</Method></Frame><Frame><File>C:\Programme\Anaconda\lib\site-packages\matplotlib\pylab.py</File><Line>269</Line><Method>module</Method></Frame><Frame><File>C:\Programme\Anaconda\lib\site-packages\matplotlib\pyplot.py</File><Line>98</Line><Method>module</Method></Frame><Frame><File>C:\Programme\Anaconda\lib\site-packages\matplotlib\backends\__init__.py</File><Line>28</Line><Method>pylab_setup</Method></Frame><Frame><File>C:\Programme\Anaconda\lib\site-packages\matplotlib\backends\backend_qt4agg.py</File><Line>13</Line><Method>module</Method></Frame><Frame><File>C:\Programme\Anaconda\lib\site-packages\matplotlib\backends\backend_qt4.py</File><Line>21</Line><Method>module</Method></Frame><Frame><File>C:\Programme\Anaconda\lib\site-packages\matplotlib\backends\qt4_editor\figureoptions.py</File><Line>13</Line><Method>module</Method></Frame><Frame><File>C:\Programme\Anaconda\lib\site-packages\matplotlib\backends\qt4_editor\formlayout.py</File><Line>51</Line><Method>module</Method></Frame><Frame><File>C:\Programme\Anaconda\lib\site-packages\matplotlib\backends\qt4_compat.py</File><Line>80</Line><Method>module</Method></Frame><Frame><File>C:\Programme\Anaconda\lib\site-packages\PySide\__init__.py</File><Line>41</Line><Method>module</Method></Frame><Frame><File>C:\Programme\Anaconda\lib\site-packages\PySide\__init__.py</File><Line>11</Line><Method>_setupQtDirectories</Method></Frame><Frame><File>C:\Programme\Anaconda\lib\site-packages\PySide\_utils.py</File><Line>93</Line><Method>get_pyside_dir</Method></Frame><Frame><File>C:\Programme\Anaconda\lib\site-packages\PySide\_utils.py</File><Line>84</Line><Method>_get_win32_case_sensitive_name</Method></Frame><Frame><File>C:\Programme\Anaconda\lib\site-packages\PySide\_utils.py</File><Line>74</Line><Method>_get_win32_long_name</Method></Frame></Stack></Post><Post><PostId>23625053</PostId><Url>http://stackoverflow.com/questions/23625053</Url><Stack><Type>WindowsError</Type><Message>exception: access violation reading 0x00000005</Message><Frame><File>D:\py\test.py</File><Line>5</Line><Method>module</Method></Frame></Stack></Post><Post><PostId>23676830</PostId><Url>http://stackoverflow.com/questions/23676830</Url><Stack><Type>WindowsError</Type><Message>[Error 2] The system cannot find the file specified</Message><Frame><File>systrace.py</File><Line>286</Line><Method>module</Method></Frame><Frame><File>systrace.py</File><Line>60</Line><Method>main</Method></Frame><Frame><File>systrace.py</File><Line>44</Line><Method>get_device_sdk_version</Method></Frame><Frame><File>C:\Reuben\Softwares\Python 2.7.6\Lib\subprocess.py</File><Line>709</Line><Method>__init__</Method></Frame><Frame><File>C:\Reuben\Softwares\Python 2.7.6\Lib\subprocess.py</File><Line>957</Line><Method>_execute_child</Method></Frame></Stack></Post><Post><PostId>23838953</PostId><Url>http://stackoverflow.com/questions/23838953</Url><Stack><Type>WindowsError</Type><Message>[Error 2] The system cannot find the file specified</Message><Frame><File>C:\Temp\temp.py</File><Line>13</Line><Method>module</Method></Frame><Frame><File>C:\Python27\lib\subprocess.py</File><Line>709</Line><Method>__init__</Method></Frame><Frame><File>C:\Python27\lib\subprocess.py</File><Line>957</Line><Method>_execute_child</Method></Frame></Stack></Post><Post><PostId>23910150</PostId><Url>http://stackoverflow.com/questions/23910150</Url><Stack><Type>WindowsError</Type><Message>[Error 2] The system cannot find the file specified</Message><Frame><File>C:\Python27\lib\lib-tk\Tkinter.py</File><Line>1470</Line><Method>__call__</Method></Frame><Frame><File>C:\Users\NAME\Desktop\test.py</File><Line>17</Line><Method>lambda</Method></Frame><Frame><File>C:\Python27\lib\subprocess.py</File><Line>522</Line><Method>call</Method></Frame><Frame><File>C:\Python27\lib\subprocess.py</File><Line>709</Line><Method>__init__</Method></Frame><Frame><File>C:\Python27\lib\subprocess.py</File><Line>957</Line><Method>_execute_child</Method></Frame></Stack></Post><Post><PostId>24067158</PostId><Url>http://stackoverflow.com/questions/24067158</Url><Stack><Type>WindowsError</Type><Message>[Error 32] The process cannot access the file because it is being used by another process</Message><Frame><File>C:\Python27\Lib\logging\handlers.py</File><Line>72</Line><Method>emit</Method></Frame><Frame><File>C:\Python27\Lib\logging\handlers.py</File><Line>174</Line><Method>doRollover</Method></Frame><Frame><File>C:\Python27\Lib\logging\handlers.py</File><Line>113</Line><Method>rotate</Method></Frame></Stack></Post><Post><PostId>24126133</PostId><Url>http://stackoverflow.com/questions/24126133</Url><Stack><Type>WindowsError</Type><Message>[Error 6] The handle is invalid</Message><Frame><File>.\sublime_plugin.py</File><Line>356</Line><Method>run_</Method></Frame><Frame><File>.\text_transfer.py</File><Line>123</Line><Method>run</Method></Frame><Frame><File>.\sublimerepl.py</File><Line>437</Line><Method>find_repl</Method></Frame><Frame><File>.\repls\subprocess_repl.py</File><Line>185</Line><Method>is_alive</Method></Frame><Frame><File>.\subprocess.py</File><Line>705</Line><Method>poll</Method></Frame><Frame><File>.\subprocess.py</File><Line>874</Line><Method>_internal_poll</Method></Frame></Stack></Post><Post><PostId>24217419</PostId><Url>http://stackoverflow.com/questions/24217419</Url><Stack><Type>WindowsError</Type><Message>[Error 123] The filename, directory name, or volume label syntax is     incorrect`</Message><Frame><File>C:\Python27\lib\site-packages\celery\worker\__init__.py</File><Line>206</Line><Method>start</Method></Frame><Frame><File>C:\Python27\lib\site-packages\celery\bootsteps.py</File><Line>123</Line><Method>start</Method></Frame><Frame><File>C:\Python27\lib\site-packages\celery\bootsteps.py</File><Line>373</Line><Method>start</Method></Frame><Frame><File>C:\Python27\lib\site-packages\celery\concurrency\base.py</File><Line>131</Line><Method>start</Method></Frame><Frame><File>C:\Python27\lib\site-packages\celery\concurrency\prefork.py</File><Line>117</Line><Method>on_start</Method></Frame><Frame><File>C:\Python27\lib\site-packages\billiard\pool.py</File><Line>925</Line><Method>__init__</Method></Frame><Frame><File>C:\Python27\lib\site-packages\billiard\pool.py</File><Line>1267</Line><Method>_setup_queues</Method></Frame><Frame><File>C:\Python27\lib\site-packages\billiard\queues.py</File><Line>369</Line><Method>__init__</Method></Frame><Frame><File>C:\Python27\lib\site-packages\billiard\__init__.py</File><Line>97</Line><Method>Pipe</Method></Frame><Frame><File>C:\Python27\lib\site-packages\billiard\py2\connection.py</File><Line>233</Line><Method>Pipe</Method></Frame></Stack></Post><Post><PostId>24315053</PostId><Url>http://stackoverflow.com/questions/24315053</Url><Stack><Type>WindowsError</Type><Message>exception: access violation writing 0x00000050</Message><Frame><File>D:\ISI\tmp\NN DLL\Test DLL.py</File><Line>98</Line><Method>module</Method></Frame></Stack></Post><Post><PostId>24335854</PostId><Url>http://stackoverflow.com/questions/24335854</Url><Stack><Type>WindowsError</Type><Message>[Error 2] The system cannot find the file specified</Message><Frame><File>C:\Anaconda\Scripts\conda-pipbuild-script.py</File><Line>4</Line><Method>module</Method></Frame><Frame><File>C:\Anaconda\lib\site-packages\conda_build\main_pipbuild.py</File><Line>76</Line><Method>main</Method></Frame><Frame><File>C:\Anaconda\lib\site-packages\conda_build\main_pipbuild.py</File><Line>347</Line><Method>execute</Method></Frame><Frame><File>C:\Anaconda\lib\site-packages\conda_build\main_pipbuild.py</File><Line>300</Line><Method>build_package</Method></Frame><Frame><File>C:\Anaconda\lib\site-packages\conda_build\main_pipbuild.py</File><Line>244</Line><Method>make_recipe</Method></Frame><Frame><File>C:\Anaconda\lib\site-packages\conda_build\main_pipbuild.py</File><Line>214</Line><Method>get_all_dependencies</Method></Frame><Frame><File>C:\Anaconda\lib\subprocess.py</File><Line>710</Line><Method>__init__</Method></Frame><Frame><File>C:\Anaconda\lib\subprocess.py</File><Line>958</Line><Method>_execute_child</Method></Frame></Stack></Post><Post><PostId>24361882</PostId><Url>http://stackoverflow.com/questions/24361882</Url><Stack><Type>WindowsError</Type><Message>exception: access violation writing 0x0C000068</Message><Frame><File>Msi_test.py</File><Line>100</Line><Method>module</Method></Frame></Stack></Post><Post><PostId>24690170</PostId><Url>http://stackoverflow.com/questions/24690170</Url><Stack><Type>WindowsError</Type><Message>[Error 2] The system cannot find the file specified</Message><Frame><File>copy.py</File><Line>2</Line><Method>module</Method></Frame><Frame><File>C:\Python27\lib\subprocess.py</File><Line>493</Line><Method>call</Method></Frame><Frame><File>C:\Python27\lib\subprocess.py</File><Line>679</Line><Method>__init__</Method></Frame><Frame><File>C:\Python27\lib\subprocess.py</File><Line>896</Line><Method>_execute_child</Method></Frame></Stack></Post><Post><PostId>24946061</PostId><Url>http://stackoverflow.com/questions/24946061</Url><Stack><Type>WindowsError</Type><Message>[Error 2] The system cannot find the file specified</Message><Frame><File>test_grunt_fail.py</File><Line>3</Line><Method>module</Method></Frame><Frame><File>C:\Python27\lib\subprocess.py</File><Line>710</Line><Method>__init__</Method></Frame><Frame><File>C:\Python27\lib\subprocess.py</File><Line>958</Line><Method>_execute_child</Method></Frame></Stack></Post><Post><PostId>24954202</PostId><Url>http://stackoverflow.com/questions/24954202</Url><Stack><Type>WindowsError</Type><Message>[Error 5] Access is denied: 'E:'</Message><Frame><File>C:\Users\DC\Desktop\Prototype\Prototype</File><Line>9</Line><Method>module</Method></Frame><Frame><File>C:\Python27\lib\shutil.py</File><Line>300</Line><Method>move</Method></Frame><Frame><File>C:\Python27\lib\shutil.py</File><Line>256</Line><Method>rmtree</Method></Frame><Frame><File>C:\Python27\lib\shutil.py</File><Line>254</Line><Method>rmtree</Method></Frame></Stack></Post><Post><PostId>25090981</PostId><Url>http://stackoverflow.com/questions/25090981</Url><Stack><Type>WindowsError</Type><Message>[Error 2] The system cannot find the file specified</Message><Frame><File>pyshell#2</File><Line>1</Line><Method>module</Method></Frame><Frame><File>D:\Python27\lib\subprocess.py</File><Line>522</Line><Method>call</Method></Frame><Frame><File>D:\Python27\lib\subprocess.py</File><Line>710</Line><Method>__init__</Method></Frame><Frame><File>D:\Python27\lib\subprocess.py</File><Line>958</Line><Method>_execute_child</Method></Frame></Stack></Post><Post><PostId>25203955</PostId><Url>http://stackoverflow.com/questions/25203955</Url><Stack><Type>WindowsError</Type><Message>[Error 6] The handle is invalid</Message><Frame><File>bin\runw.py</File><Line>215</Line><Method>process_instance</Method></Frame><Frame><File>bin\mixin.py</File><Line>181</Line><Method>setup</Method></Frame><Frame><File>bin\mixin.py</File><Line>166</Line><Method>get_firefox_browser</Method></Frame><Frame><File>C:\myvirtualenv\lib\site-packages\selenium\webdriver\firefox\webdriver.py</File><Line>59</Line><Method>__init__</Method></Frame><Frame><File>C:\myvirtualenv\lib\site-packages\selenium\webdriver\firefox\extension_connection.py</File><Line>47</Line><Method>__init__</Method></Frame><Frame><File>C:\myvirtualenv\lib\site-packages\selenium\webdriver\firefox\firefox_binary.py</File><Line>60</Line><Method>launch_browser</Method></Frame><Frame><File>C:\myvirtualenv\lib\site-packages\selenium\webdriver\firefox\firefox_binary.py</File><Line>83</Line><Method>_start_from_profile_path</Method></Frame><Frame><File>C:\Python27\Lib\subprocess.py</File><Line>702</Line><Method>__init__</Method></Frame><Frame><File>C:\Python27\Lib\subprocess.py</File><Line>833</Line><Method>_get_handles</Method></Frame><Frame><File>C:\Python27\Lib\subprocess.py</File><Line>884</Line><Method>_make_inheritable</Method></Frame></Stack></Post><Post><PostId>25317989</PostId><Url>http://stackoverflow.com/questions/25317989</Url><Stack><Type>WindowsError</Type><Message>[Error 2] The system cannot find the file specified</Message><Frame><File>[PATH]\bands.py</File><Line>36</Line><Method>module</Method></Frame><Frame><File>C:\Python27\ArcGIS10.2\lib\subprocess.py</File><Line>711</Line><Method>_init_</Method></Frame><Frame><File>C:\Python27\ArcGIS10.2\lib\subprocess.py</File><Line>948</Line><Method>_execute_child</Method></Frame></Stack></Post><Post><PostId>25568068</PostId><Url>http://stackoverflow.com/questions/25568068</Url><Stack><Type>WindowsError</Type><Message>[Error 2] The system cannot find the file specified: '1Clickfolder</Message><Frame><File>cleaner.py</File><Line>35</Line><Method>module</Method></Frame><Frame><File>cleaner.py</File><Line>32</Line><Method>do_stuff</Method></Frame><Frame><File>cleaner.py</File><Line>31</Line><Method>genexpr</Method></Frame><Frame><File>C:\Python27\lib\genericpath.py</File><Line>49</Line><Method>getsize</Method></Frame></Stack></Post></Posts>